Workbook

Sheet Spares
A1: ID | B1: Pace | C1: Number | D1: Type | E1: Alias | F1: Version | G1: Useful
A2: 1 | B2: Business Math | C2: 3 | D2: PACE
A3: 2 | B3: Business Math | C3: 4 | D3: PACE
A4: 3 | B4: Business Math | C4: 6 | D4: PACE
A5: 4 | B5: Business Math | C5: 7 | D5: PACE
A6: 5 | B6: Business Math | C6: 8 | D6: PACE
A7: 6 | B7: Health | C7: 1 | D7: PACE
A8: 7 | B8: Basic Intro to Physical Science | C8: 10 | D8: PACE | E8: College Physical Science
A9: 8 | B9: Basic History of Civilization | C9: 11 | D9: PACE
A10: 9 | B10: OT Survey | C10: 109 | D10: PACE | E10: Biblical Studies II
A11: 10 | B11: Biology Activity Pac | C11: 1 | D11: PACE
A12: 11 | B12: Biology Activity Pac | C12: 2 | D12: PACE
A13: 12 | B13: Biology Activity Pac | C13: 3 | D13: PACE
A14: 13 | B14: Biology Activity Pac | C14: 4 | D14: PACE
A15: 14 | B15: Biology Activity Pac | C15: 5 | D15: PACE
A16: 15 | B16: Biology Activity Pac | C16: 6 | D16: PACE
A17: 16 | B17: Social Studies — US Civics | C17: 4 | D17: PACE
A18: 17 | B18: Successful Living | C18: 1 | D18: PACE
A19: 18 | B19: Successful Living | C19: 2 | D19: PACE
A20: 19 | B20: Successful Living | C20: 3 | D20: PACE
A21: 20 | B21: Successful Living | C21: 5 | D21: PACE
A22: 21 | B22: Apologetics | C22: 1097 | D22: PACE
A23: 22 | B23: Apologetics | C23: 1098-p | D23: PACE
A24: 23 | B24: Apologetics | C24: 1099-p | D24: PACE
A25: 24 | B25: Apologetics | C25: 1100-p | D25: PACE
A26: 25 | B26: Missions | C26: 1 | D26: PACE
A27: 26 | B27: Basic Intro to Christian Counseling | C27: 6 | D27: PACE
A28: 27 | B28: Basic Greek | C28: 122 | D28: PACE
A29: 28 | B29: Basic Greek | C29: 123 | D29: PACE
A30: 29 | B30: Basic Greek | C30: 125 | D30: PACE
A31: 30 | B31: Basic Greek | C31: 126 | D31: PACE
A32: 31 | B32: Spanish I | C32: 2 | D32: PACE
A33: 32 | B33: Speech | C33: 1 | D33: PACE
A34: 33 | B34: Basic Beginning Art | C34: 77 | D34: PACE
A35: 34 | B35: Basic Beginning Art | C35: 78 | D35: PACE
A36: 35 | B36: Nutrition Science | C36: 1 | D36: PACE
A37: 36 | B37: Nutrition Science | C37: 2 | D37: PACE
... A55: 54 | B55: Algebra-II-8 | C55: 128 | D55: PACE
A56: 55 | B56: English | C56: 83 | D56: PACE | F56: Old | G56: 1
A57: 56 | B57: English I-2 | C57: 98 | D57: PACE
...

Sheet Progress
A1: ID | B1: Student | C1: Course | D1: PACE | E1: Added | F1: Date
A2: 1 | B2: Nathanaël | C2: Maths | D2: 79 | F2: 45245
A3: 2 | B3: Nathanaël | C3: English | D3: 83 | F3: 45245
A4: 3 | B4: Nathanaël | C4: Word Building | D4: 84 | F4: 45245
A5: 4 | B5: Nathanaël | C5: Literature | D5: 78 | F5: 45245
A6: 5 | B6: Nathanaël | C6: Science | D6: 83 | F6: 45245
A7: 6 | B7: Nathanaël | C7: Social Studies | F7: 45245
A8: 8 | B8: Nathanaël | C8: Apologetics | F8: 45245
A9: 9 | B9: Nathanaël | C9: Staatsinrichting | D9: 3 | F9: 45245
A10: 10 | B10: Aron | C10: Algebra 1 | D10: 105 | F10: 45245
A11: 11 | B11: Aron | C11: English 1 | D11: 105 | F11: 45245
A12: 12 | B12: Aron | C12: Etymology | D12: 106 | F12: 45245
A13: 13 | B13: Aron | C13: Literature | D13: 108 | F13: 45245
A14: 14 | B14: Aron | C14: Biology | D14: 105 | F14: 45245
A15: 15 | B15: Aron | C15: World Geography | D15: 105 | F15: 45245
A16: 16 | B16: Aron | C16: Successful Living | D16: 11 | F16: 45245
A17: 17 | B17: Aron | C17: Apologetics | D17: 11 | F17: 45245
A18: 18 | B18: Aron | C18: Music | D18: 5 | F18: 45245
A19: 19 | B19: Dani | C19: Maths | D19: 75 | E19: 81 | F19: 45245
A20: 20 | B20: Dani | C20: English | D20: 80 | F20: 45245
A21: 21 | B21: Dani | C21: Word Building | D21: 82 | E21: 88 | F21: 45245
A22: 22 | B22: Dani | C22: Literature | D22: 74 | F22: 45245
A23: 23 | B23: Dani | C23: Science | D23: 82 | F23: 45245
A24: 24 | B24: Dani | C24: Staatsinrichting | D24: 3 | F24: 45245
A25: 25 | B25: Stijn | C25: Algebra 1 | D25: 103 | F25: 45245
A26: 26 | B26: Stijn | C26: English 1 | D26: 104 | F26: 45245
A27: 27 | B27: Stijn | C27: Etymology | D27: 103 | F27: 45245
A28: 28 | B28: Stijn | C28: Literature | D28: 104 | F28: 45245
A29: 29 | B29: Stijn | C29: Biology | D29: 102 | F29: 45245
A30: 30 | B30: Stijn | C30: World Geography | D30: 103 | F30: 45245
A31: 31 | B31: Stijn | C31: Successful Living | D31: 8 | E31: 9 | F31: 45245
A32: 32 | B32: Stijn | C32: Apologetics | D32: 97 | F32: 45245
A33: 33 | B33: Sam | C33: Geometry | D33: 109 | F33: 45245
A34: 34 | B34: Sam | C34: English II | D34: 108 | F34: 45245
A35: 35 | B35: Sam | C35: Biology | D35: 108 | F35: 45245
A36: 36 | B36: Sam | C36: Physical Science | D36: 108 | E36: 112, 113, 114 | F36: 45245
A37: 37 | B37: Sam | C37: World Geography | D37: 108 | F37: 45245
A38: 38 | B38: Sam | C38: History of Civilization 1 | D38: 0 | E38: 9 | F38: 45245
A39: 39 | B39: Sam | C39: Greek 1 | D39: 121 | E39: 125, 126 | F39: 45245
A40: 40 | B40: Sam | C40: NT Christ History | D40: 121 | F40: 45245
...

Sheet State
A1: ID | B1: State | C1: Reason
A2: 1 | B2: Enrolled
A3: 2 | B3: Unenrolled | C3: Moved to other location
A4: 3 | B4: Unenrolled | C4: Disagreement
A5: 4 | B5: Unenrolled | C5: Graduated
A6: 0 | B6: Not Applicable

Sheet Person
A1: ID | B1: Surname | C1: SurnamePrefix | D1: FirstNames | E1: CallName | F1: Email | G1: DateOfBirth | H1: AddressID | I1: Status | J1: ClassID | K1: FirstLanguageID | L1: SecondLanguageID | M1: StateID | N1: Baptized__ | O1: Denomination
A2: 1 | B2: Adeleke | D2: Deborah | E2: Deborah | G2: 39083 | H2: 1 | I2: Student | J2: 4 | K2: 2 | L2: 1 | M2: 1 | N2: No | O2: 5
A3: 2 | B3: Adeleke | D3: Oluwatobi Samuel | E3: Oluwatobi | G3: =G2+3*RANDBETWEEN(-365, 365) -> 39089 | H3: 1 | I3: Student | J3: 4 | K3: 2 | L3: 1 | M3: 1 | N3: No | O3: 5
A4: 3 | B4: Adeleke | D4: Dorcas Mayowa Oluwatofarati Temitope Esther | E4: Dorcas | G4: =G3+3*RANDBETWEEN(-365, 365) -> 38408 | H4: 1 | I4: Student | J4: 4 | K4: 2 | L4: 1 | M4: 1 | N4: No | O4: 5
A5: 4 | B5: Benschop | D5: Jannetje Hendrika | E5: Hannah | G5: =G4+3*RANDBETWEEN(-365, 365) -> 38309 | H5: 2 | I5: Student | J5: 4 | K5: 1 | L5: 2 | M5: 4 | N5: No | O5: 0
A6: 5 | B6: Boulahdaraj | D6: Zakariya | E6: Zakariya | G6: =G5+3*RANDBETWEEN(-365, 365) -> 38942 | H6: 3 | I6: Student | J6: 4 | K6: 1 | L6: 5 | M6: 1 | N6: No | O6: 0
A7: 6 | B7: Brand | C7: van den | D7: Ezra | E7: Ezra | G7: =G6+3*RANDBETWEEN(-365, 365) -> 38024 | H7: 4 | I7: Student | J7: 4 | K7: 1 | L7: 2 | M7: 1 | N7: No | O7: 0
A8: 7 | B8: Brand | C8: van den | D8: Lois-Daan | E8: Lois-Daan | G8: =G7+3*RANDBETWEEN(-365, 365) -> 38309 | H8: 4 | I8: Student | J8: 4 | K8: 1 | L8: 2 | M8: 1 | N8: No | O8: 0
A9: 8 | B9: Bruijne | C9: de | D9: Matthias | E9: Matthias | G9: =G8+3*RANDBETWEEN(-365, 365) -> 38504 | H9: 5 | I9: Student | J9: 4 | K9: 1 | L9: 2 | M9: 1 | N9: No | O9: 0
A10: 9 | B10: Choi | D10: Byeol | E10: Byeol | G10: =G9+3*RANDBETWEEN(-365, 365) -> 39320 | H10: 6 | I10: Student | J10: 4 | K10: 1 | L10: 2 | M10: 2 | N10: No | O10: 6
A11: 10 | B11: Gonzalez Rodriguez | D11: Eleazar Leonardo | E11: Eleazar | G11: =G10+3*RANDBETWEEN(-365, 365) -> 38414 | H11: 7 | I11: Student | J11: 4 | K11: 1 | L11: 3 | M11: 1 | N11: No | O11: 3
A12: 11 | B12: Gunnink | D12: Johannes David Bernardus | E12: Daan | G12: =G11+3*RANDBETWEEN(-365, 365) -> 37895 | H12: 8 | I12: Student | J12: 4 | K12: 1 | L12: 2 | M12: 4 | N12: Yes, immersion | O12: 4
A13: 12 | B13: Harkes | D13: Marinus Dirk Martijn | E13: Stijn | G13: =G12+3*RANDBETWEEN(-365, 365) -> 37019 | H13: 9 | I13: Student | J13: 4 | K13: 1 | L13: 2 | M13: 1 | N13: No | O13: 1
A14: 13 | B14: Harkes | D14: Jonathan Anne Theodoor | E14: Jona | G14: =G13+3*RANDBETWEEN(-365, 365) -> 37928 | H14: 9 | I14: Student | J14: 4 | K14: 1 | L14: 2 | M14: 1 | N14: No | O14: 1
A15: 14 | B15: Houweling | C15: van | D15: Benjamin Ezra | E15: Ben | G15: =G14+3*RANDBETWEEN(-365, 365) -> 36953 | H15: 10 | I15: Student | J15: 4 | K15: 1 | L15: 2 | M15: 1 | N15: No | O15: 0
A16: 15 | B16: Houweling | C16: van | D16: Noah Christian | E16: Noah | G16: =G15+3*RANDBETWEEN(-365, 365) -> 37295 | H16: 10 | I16: Student | J16: 4 | K16: 1 | L16: 2 | M16: 1 | N16: No | O16: 0
A17: 16 | B17: Houweling | C17: van | D17: Emma Rhodé | E17: Aimée | G17: =G16+3*RANDBETWEEN(-365, 365) -> 37838 | H17: 10 | I17: Student | J17: 4 | K17: 1 | L17: 2 | M17: 1 | N17: No | O17: 0
A18: 17 | B18: Kleef | C18: van | D18: Loïs Eunice | E18: Loïs | G18: =G17+3*RANDBETWEEN(-365, 365) -> 38390 | H18: 11 | I18: Student | J18: 4 | K18: 1 | L18: 2 | M18: 3 | N18: No | O18: 0
A19: 18 | B19: Kleef | C19: van | D19: Jonathan | E19: Jonathan | G19: =G18+3*RANDBETWEEN(-365, 365) -> 38288 | H19: 11 | I19: Student | J19: 4 | K19: 1 | L19: 2 | M19: 3 | N19: No | O19: 0
A20: 19 | B20: Lee | D20: Kang Kevin | E20: Kevin | G20: =G19+3*RANDBETWEEN(-365, 365) -> 37994 | H20: 12 | I20: Student | J20: 4 | K20: 6 | L20: 2 | M20: 1 | N20: No | O20: 0
A21: 20 | B21: Lee | D21: Myung | E21: Matthew | G21: =G20+3*RANDBETWEEN(-365, 365) -> 36908 | H21: 12 | I21: Student | J21: 4 | K21: 6 | L21: 2 | M21: 1 | N21: No | O21: 0
A22: 21 | B22: Littel | D22: Beline Elizabeth | E22: Lina | G22: =G21+3*RANDBETWEEN(-365, 365) -> 36299 | H22: 13 | I22: Student | J22: 4 | K22: 1 | L22: 2 | M22: 1 | N22: No | O22: 4
A23: 22 | B23: Littel | D23: Simon Johannes | E23: Sam | G23: =G22+3*RANDBETWEEN(-365, 365) -> 36671 | H23: 13 | I23: Student | J23: 4 | K23: 1 | L23: 2 | M23: 1 | N23: Yes, immersion | O23: 4
A24: 23 | B24: Littel | D24: Catharina Johanna | E24: Noa | G24: =G23+3*RANDBETWEEN(-365, 365) -> 37313 | H24: 13 | I24: Student | J24: 4 | K24: 1 | L24: 2 | M24: 1 | N24: Yes, immersion | O24: 4
A25: 24 | B25: Trimp | D25: Elbert Daniël | E25: Dani | G25: =G24+3*RANDBETWEEN(-365, 365) -> 38108 | H25: 14 | I25: Student | J25: 4 | K25: 1 | L25: 3 | M25: 1 | N25: No | O25: 4
A26: 25 | B26: Trimp | D26: Aron Pieter | E26: Aron | G26: =G25+3*RANDBETWEEN(-365, 365) -> 37043 | H26: 14 | I26: Student | J26: 4 | K26: 1 | L26: 3 | M26: 1 | N26: No | O26: 4
A27: 26 | B27: Verwoerd | D27: Cornelia Elisabeth | E27: Isolde | G27: =G26+3*RANDBETWEEN(-365, 365) -> 37928 | H27: 15 | I27: Student | J27: 4 | K27: 1 | L27: 2 | M27: 4 | N27: No | O27: 0
A28: 27 | B28: Verwoerd | D28: Martinus Gerardus | E28: Magnus | G28: =G27+3*RANDBETWEEN(-365, 365) -> 37208 | H28: 15 | I28: Student | J28: 4 | K28: 1 | L28: 2 | M28: 4 | N28: No | O28: 0
A29: 28 | B29: Visser | D29: Loïs | E29: Loïs | G29: =G28+3*RANDBETWEEN(-365, 365) -> 37478 | H29: 16 | I29: Student | J29: 4 | K29: 1 | L29: 2 | M29: 4 | N29: No | O29: 0
A30: 29 | B30: Yong | D30: Joseph Nathan Andrew Jun-Yin | E30: Nathan | G30: 40453 | H30: 17 | I30: Student | J30: 4 | K30: 1 | L30: 4 | M30: 1 | N30: No | O30: 4
A31: 30 | B31: Yong | D31: Andrew | E31: Andrew | F31: a.yong@ceder.nl | G31: 30584 | H31: 17 | I31: Monitor | J31: 0 | K31: 1 | L31: 2 | M31: 0 | N31: Yes, affusion | O31: 4
A32: 31 | B32: Bezemer | D32: Simon | E32: Simon | F32: s.bezemer@ceder.nl | G32: =G31+3*RANDBETWEEN(-365, 365) -> 30803 | H32: 20 | I32: Supervisor | J32: 0 | K32: 1 | L32: 2 | M32: 0 | N32: Unknown | O32: 0
A33: 32 | B33: Visser | D33: Hanna | E33: Hanna | F33: h.visser@ceder.nl | G33: =G32+3*RANDBETWEEN(-365, 365) -> 30362 | H33: 16 | I33: Supervisor | J33: 3 | K33: 1 | L33: 2 | M33: 0 | N33: Unknown | O33: 0
A34: 33 | B34: Trimp | D34: Annelies | E34: Annelies | F34: a.trimp@ceder.nl | G34: =G33+3*RANDBETWEEN(-365, 365) -> 30845 | H34: 14 | I34: Supervisor | J34: 1 | K34: 1 | L34: 2 | M34: 0 | N34: Unknown | O34: 0
A35: 34 | B35: Westerhof | D35: Petra | E35: Petra | G35: =G34+3*RANDBETWEEN(-365, 365) -> 31247 | H35: 20 | I35: Monitor | J35: 0 | K35: 1 | L35: 2 | M35: 0 | N35: Unknown | O35: 0
A36: 35 | B36: Kleef | C36: van | D36: Johanna | E36: Johanna | G36: =G35+3*RANDBETWEEN(-365, 365) -> 31850 | H36: 20 | I36: Supervisor | J36: 2 | K36: 1 | L36: 2 | M36: 0 | N36: Unknown | O36: 0
A37: 36 | B37: Bruin | C37: de | D37: Ada | E37: Ada | G37: =G36+3*RANDBETWEEN(-365, 365) -> 32501 | H37: 21 | I37: Supervisor | J37: 0 | K37: 1 | L37: 2 | M37: 0 | N37: Unknown | O37: 0
A38: 37 | B38: Lee | D38: Irene | E38: Irene | F38: irene7416@naver.com | G38: =G37+3*RANDBETWEEN(-365, 365) -> 33341 | H38: 12 | I38: Monitor | J38: 0 | K38: 6 | L38: 2 | M38: 0 | N38: Unknown | O38: 0
A39: 38 | B39: Steenbeek | D39: Lukas | E39: Lukas | G39: =G38+3*RANDBETWEEN(-365, 365) -> 34271 | H39: 18 | I39: Student | J39: 4 | K39: 1 | L39: 2 | M39: 0 | N39: Unknown | O39: 0
A40: 39 | B40: Steenbeek | D40: Nathanaël | E40: Nathanaël | G40: =G39+3*RANDBETWEEN(-365, 365) -> 34016 | H40: 18 | I40: Student | J40: 4 | K40: 1 | L40: 2 | M40: 0 | N40: Unknown | O40: 0
...

Sheet Transaction
A1: ID | B1: StudentID | C1: Date | D1: Type | E1: Graduation Type | F1: Remarks | G1: Count
A2: 1 | B2: 57 | C2: 45159 | D2: Registration new student | E2: To ABCs | G2: 1
A3: 2 | B3: 56 | C3: 45159 | D3: Registration new student | E3: To ABCs | G3: 1
A4: 3 | B4: 9 | C4: 45108 | D4: Left school without graduation | F4: Moved to Switzerland | G4: -1
A5: 4 | B5: 58 | C5: 45108 | D5: Left school without graduation | F5: Moved to Switzerland | G5: -1
A6: 5 | B6: 28 | C6: 45108 | D6: Graduation General Certificate | G6: -1
A7: 6 | B7: 1 | C7: 45108 | D7: Graduation Advanced Certificate | G7: -1
A8: 7 | B8: 29 | C8: 45159 | D8: To new class | E8: To Seniors | G8: 0
A9: 8 | B9: 39 | C9: 45159 | D9: To new class | E9: To Seniors | G9: 0
A10: 9 | B10: 24 | C10: 45159 | D10: To new class | E10: To Seniors | G10: 0
A11: 10 | B11: 5 | C11: 45159 | D11: To new class | E11: To Seniors | G11: 0
A12: 11 | B12: 59 | C12: 45159 | D12: To new class | E12: To Juniors | G12: 0
A13: 12 | B13: 6 | C13: 45108 | D13: Left school without graduation | F13: Moved to South-Korea | G13: -1
A14: 13 | B14: 7 | C14: 45108 | D14: Left school without graduation | F14: Moved to South-Korea | G14: -1

Sheet Denomination
A1: ID | B1: CurrentDenomination | C1: Remark
A2: 0 | B2: Unknown
A3: 1 | B3: Dutch Reformed without certainty of salvation | C3: Such as Gereformeerde Gemeente
A4: 2 | B4: Dutch Reformed with certainty of salvation
A5: 3 | B5: Evangelical
A6: 4 | B6: Non-denominational
A7: 5 | B7: Pentecostal
A8: 6 | B8: Reformed | C8: Other

Sheet Language
A1: ID | B1: Language | C1: Remark
A2: 1 | B2: Dutch
A3: 2 | B3: English
A4: 3 | B4: Spanish
A5: 4 | B5: Mandarin Chinese
A6: 5 | B6: Moroccan Tamazight | C6: Berbers
A7: 6
A8: 7

Sheet Address
A1: ID | B1: Surname+ | C1: Address | D1: HouseNumber | E1: Postal Code | F1: City | G1: TransactionDate
A2: 1 | B2: Adeleke | C2: Adres 1 | D2: 95 | E2: 3459QA | F2: Amsterdam | G2: 44951
A3: 2 | B3: Benschop | C3: Adres 2 | D3: 41 | E3: 4463MM | F3: Rotterdam | G3: 44951
A4: 3 | B4: Boulahdaraj | C4: Adres 3 | D4: 46 | E4: 3654LR | F4: Alphen a/d Rijn | G4: 44951
A5: 4 | B5: Brand | C5: Adres 4 | D5: 10 | E5: 3767DT | F5: Capelle aan den IJssel | G5: 44951
A6: 5 | B6: Bruijne | C6: Adres 5 | D6: 85 | E6: 4915YR | F6: Boskoop | G6: 44951
A7: 6 | B7: Choi | C7: Adres 6 | D7: 73 | E7: 3477XR | F7: Boskoop | G7: 44951
A8: 7 | B8: Gonzalez Rodriguez | C8: Adres 7 | D8: 96 | E8: 4456XW | F8: Gouda | G8: 44951
A9: 8 | B9: Gunnink | C9: Adres 8 | D9: 11 | E9: 3901QI | F9: Woerden | G9: 44951
A10: 9 | B10: Harkes | C10: Adres 9 | D10: 45 | E10: 4750LG | F10: Rotterdam | G10: 44951
A11: 10 | B11: Houweling | C11: Adres 10 | D11: 59 | E11: 3278UE | F11: Den Haag | G11: 44951
A12: 11 | B12: Kleef | C12: Adres 11 | D12: 73 | E12: 4283RT | F12: Leiderdorp | G12: 44951
A13: 12 | B13: Lee | C13: Adres 12 | D13: 50 | E13: 4953GR | F13: Leiderdorp | G13: 44951
... A20: 19 | B20: Hoogendoorn | C20: Adres 18 | D20: 29 | E20: 3067KA | F20: Rotterdam | G20: 44951
A21: 20 | B21: Bezemer | C21: Adres 19

Sheet Date
A1: ID | B1: Date | C1: Weekend | D1: Holiday | E1: DayOff | F1: WeekDay | G1: Remark | H1: Term | I1: TermWeek | J1: Week
A2: 1 | B2: 44792 | C2: =IF(OR(WEEKDAY(B2) = 7, WEEKDAY(B2) = 1), 1, 0) -> 0 | D2: 1 | E2: =IF((C2+D2)>0, 1, 0) -> 1 | F2: =TEXT(B2, "dddd") -> Friday | G2: Zomervakantie | H2: 5 | I2: 5 | J2: =_xlfn.ISOWEEKNUM(B2) -> 33
A3: 2 | B3: 44793 | C3: =IF(OR(WEEKDAY(B3) = 7, WEEKDAY(B3) = 1), 1, 0) -> 1 | D3: 1 | E3: =IF((C3+D3)>0, 1, 0) -> 1 | F3: =TEXT(B3, "dddd") -> Saturday | G3: Zomervakantie | H3: 5 | I3: 5 | J3: =_xlfn.ISOWEEKNUM(B3) -> 33
A4: 3 | B4: 44794 | C4: =IF(OR(WEEKDAY(B4) = 7, WEEKDAY(B4) = 1), 1, 0) -> 1 | D4: 1 | E4: =IF((C4+D4)>0, 1, 0) -> 1 | F4: =TEXT(B4, "dddd") -> Sunday | G4: Zomervakantie | H4: 5 | I4: 5 | J4: =_xlfn.ISOWEEKNUM(B4) -> 33
A5: 4 | B5: 44795 | C5: =IF(OR(WEEKDAY(B5) = 7, WEEKDAY(B5) = 1), 1, 0) -> 0 | D5: 0 | E5: =IF((C5+D5)>0, 1, 0) -> 0 | F5: =TEXT(B5, "dddd") -> Monday | H5: 1 | I5: =IF(J5>J4, IF(H5<>H4,1, I4+1),I4) -> 1 | J5: =_xlfn.ISOWEEKNUM(B5) -> 34
A6: 5 | B6: 44796 | C6: =IF(OR(WEEKDAY(B6) = 7, WEEKDAY(B6) = 1), 1, 0) -> 0 | D6: 0 | E6: =IF((C6+D6)>0, 1, 0) -> 0 | F6: =TEXT(B6, "dddd") -> Tuesday | H6: 1 | I6: =IF(J6>J5, IF(H6<>H5,1, I5+1),I5) -> 1 | J6: =_xlfn.ISOWEEKNUM(B6) -> 34
A7: 6 | B7: 44797 | C7: =IF(OR(WEEKDAY(B7) = 7, WEEKDAY(B7) = 1), 1, 0) -> 0 | D7: 0 | E7: =IF((C7+D7)>0, 1, 0) -> 0 | F7: =TEXT(B7, "dddd") -> Wednesday | H7: 1 | I7: =IF(J7>J6, IF(H7<>H6,1, I6+1),I6) -> 1 | J7: =_xlfn.ISOWEEKNUM(B7) -> 34
A8: 7 | B8: 44798 | C8: =IF(OR(WEEKDAY(B8) = 7, WEEKDAY(B8) = 1), 1, 0) -> 0 | D8: 0 | E8: =IF((C8+D8)>0, 1, 0) -> 0 | F8: =TEXT(B8, "dddd") -> Thursday | H8: 1 | I8: =IF(J8>J7, IF(H8<>H7,1, I7+1),I7) -> 1 | J8: =_xlfn.ISOWEEKNUM(B8) -> 34
A9: 8 | B9: 44799 | C9: =IF(OR(WEEKDAY(B9) = 7, WEEKDAY(B9) = 1), 1, 0) -> 0 | D9: 0 | E9: =IF((C9+D9)>0, 1, 0) -> 0 | F9: =TEXT(B9, "dddd") -> Friday | H9: 1 | I9: =IF(J9>J8, IF(H9<>H8,1, I8+1),I8) -> 1 | J9: =_xlfn.ISOWEEKNUM(B9) -> 34
A10: 9 | B10: 44800 | C10: =IF(OR(WEEKDAY(B10) = 7, WEEKDAY(B10) = 1), 1, 0) -> 1 | D10: 0 | E10: =IF((C10+D10)>0, 1, 0) -> 1 | F10: =TEXT(B10, "dddd") -> Saturday | H10: 1 | I10: =IF(J10>J9, IF(H10<>H9,1, I9+1),I9) -> 1 | J10: =_xlfn.ISOWEEKNUM(B10) -> 34
A11: 10 | B11: 44801 | C11: =IF(OR(WEEKDAY(B11) = 7, WEEKDAY(B11) = 1), 1, 0) -> 1 | D11: 0 | E11: =IF((C11+D11)>0, 1, 0) -> 1 | F11: =TEXT(B11, "dddd") -> Sunday | H11: 1 | I11: =IF(J11>J10, IF(H11<>H10,1, I10+1),I10) -> 1 | J11: =_xlfn.ISOWEEKNUM(B11) -> 34
A12: 11 | B12: 44802 | C12: =IF(OR(WEEKDAY(B12) = 7, WEEKDAY(B12) = 1), 1, 0) -> 0 | D12: 0 | E12: =IF((C12+D12)>0, 1, 0) -> 0 | F12: =TEXT(B12, "dddd") -> Monday | H12: 1 | I12: =IF(J12>J11, IF(H12<>H11,1, I11+1),I11) -> 2 | J12: =_xlfn.ISOWEEKNUM(B12) -> 35
A13: 12 | B13: 44803 | C13: =IF(OR(WEEKDAY(B13) = 7, WEEKDAY(B13) = 1), 1, 0) -> 0 | D13: 0 | E13: =IF((C13+D13)>0, 1, 0) -> 0 | F13: =TEXT(B13, "dddd") -> Tuesday | H13: 1 | I13: =IF(J13>J12, IF(H13<>H12,1, I12+1),I12) -> 2 | J13: =_xlfn.ISOWEEKNUM(B13) -> 35
A14: 13 | B14: 44804 | C14: =IF(OR(WEEKDAY(B14) = 7, WEEKDAY(B14) = 1), 1, 0) -> 0 | D14: 0 | E14: =IF((C14+D14)>0, 1, 0) -> 0 | F14: =TEXT(B14, "dddd") -> Wednesday | H14: 1 | I14: =IF(J14>J13, IF(H14<>H13,1, I13+1),I13) -> 2 | J14: =_xlfn.ISOWEEKNUM(B14) -> 35
A15: 14 | B15: 44805 | C15: =IF(OR(WEEKDAY(B15) = 7, WEEKDAY(B15) = 1), 1, 0) -> 0 | D15: 0 | E15: =IF((C15+D15)>0, 1, 0) -> 0 | F15: =TEXT(B15, "dddd") -> Thursday | H15: 1 | I15: =IF(J15>J14, IF(H15<>H14,1, I14+1),I14) -> 2 | J15: =_xlfn.ISOWEEKNUM(B15) -> 35
A16: 15 | B16: 44806 | C16: =IF(OR(WEEKDAY(B16) = 7, WEEKDAY(B16) = 1), 1, 0) -> 0 | D16: 0 | E16: =IF((C16+D16)>0, 1, 0) -> 0 | F16: =TEXT(B16, "dddd") -> Friday | H16: 1 | I16: =IF(J16>J15, IF(H16<>H15,1, I15+1),I15) -> 2 | J16: =_xlfn.ISOWEEKNUM(B16) -> 35
... A67: 66 | B67: 44857 | C67: =IF(OR(WEEKDAY(B67) = 7, WEEKDAY(B67) = 1), 1, 0) -> 1 | D67: 0 | E67: =IF((C67+D67)>0, 1, 0) -> 1 | F67: =TEXT(B67, "dddd") -> Sunday | H67: 1 | I67: =IF(J67>J66, IF(H67<>H66,1, I66+1),I66) -> 9 | J67: =_xlfn.ISOWEEKNUM(B67) -> 42
A68: 67 | B68: 44858 | C68: =IF(OR(WEEKDAY(B68) = 7, WEEKDAY(B68) = 1), 1, 0) -> 0 | D68: 1 | E68: =IF((C68+D68)>0, 1, 0) -> 1 | F68: =TEXT(B68, "dddd") -> Monday | G68: Najaarsvakantie | H68: 1 | I68: =IF(J68>J67, IF(H68<>H67,1, I67+1),I67) -> 10 | J68: =_xlfn.ISOWEEKNUM(B68) -> 43
A69: 68 | B69: 44859 | C69: =IF(OR(WEEKDAY(B69) = 7, WEEKDAY(B69) = 1), 1, 0) -> 0 | D69: 1 | E69: =IF((C69+D69)>0, 1, 0) -> 1 | F69: =TEXT(B69, "dddd") -> Tuesday | G69: Najaarsvakantie | H69: 1 | I69: =IF(J69>J68, IF(H69<>H68,1, I68+1),I68) -> 10 | J69: =_xlfn.ISOWEEKNUM(B69) -> 43
A70: 69 | B70: 44860 | C70: =IF(OR(WEEKDAY(B70) = 7, WEEKDAY(B70) = 1), 1, 0) -> 0 | D70: 1 | E70: =IF((C70+D70)>0, 1, 0) -> 1 | F70: =TEXT(B70, "dddd") -> Wednesday | G70: Najaarsvakantie | H70: 1 | I70: =IF(J70>J69, IF(H70<>H69,1, I69+1),I69) -> 10 | J70: =_xlfn.ISOWEEKNUM(B70) -> 43
A71: 70 | B71: 44861 | C71: =IF(OR(WEEKDAY(B71) = 7, WEEKDAY(B71) = 1), 1, 0) -> 0 | D71: 1 | E71: =IF((C71+D71)>0, 1, 0) -> 1 | F71: =TEXT(B71, "dddd") -> Thursday | G71: Najaarsvakantie | H71: 1 | I71: =IF(J71>J70, IF(H71<>H70,1, I70+1),I70) -> 10 | J71: =_xlfn.ISOWEEKNUM(B71) -> 43
A72: 71 | B72: 44862 | C72: =IF(OR(WEEKDAY(B72) = 7, WEEKDAY(B72) = 1), 1, 0) -> 0 | D72: 1 | E72: =IF((C72+D72)>0, 1, 0) -> 1 | F72: =TEXT(B72, "dddd") -> Friday | G72: Najaarsvakantie | H72: 1 | I72: =IF(J72>J71, IF(H72<>H71,1, I71+1),I71) -> 10 | J72: =_xlfn.ISOWEEKNUM(B72) -> 43
A73: 72 | B73: 44863 | C73: =IF(OR(WEEKDAY(B73) = 7, WEEKDAY(B73) = 1), 1, 0) -> 1 | D73: 1 | E73: =IF((C73+D73)>0, 1, 0) -> 1 | F73: =TEXT(B73, "dddd") -> Saturday | G73: Najaarsvakantie | H73: 1 | I73: =IF(J73>J72, IF(H73<>H72,1, I72+1),I72) -> 10 | J73: =_xlfn.ISOWEEKNUM(B73) -> 43
A74: 73 | B74: 44864 | C74: =IF(OR(WEEKDAY(B74) = 7, WEEKDAY(B74) = 1), 1, 0) -> 1 | D74: 1 | E74: =IF((C74+D74)>0, 1, 0) -> 1 | F74: =TEXT(B74, "dddd") -> Sunday | G74: Najaarsvakantie | H74: 1 | I74: =IF(J74>J73, IF(H74<>H73,1, I73+1),I73) -> 10 | J74: =_xlfn.ISOWEEKNUM(B74) -> 43
A75: 74 | B75: 44865 | C75: =IF(OR(WEEKDAY(B75) = 7, WEEKDAY(B75) = 1), 1, 0) -> 0 | D75: 1 | E75: =IF((C75+D75)>0, 1, 0) -> 1 | F75: =TEXT(B75, "dddd") -> Monday | G75: Studiedag | H75: 2 | I75: =IF(J75>J74, IF(H75<>H74,1, I74+1),I74) -> 1 | J75: =_xlfn.ISOWEEKNUM(B75) -> 44
A76: 75 | B76: 44866 | C76: =IF(OR(WEEKDAY(B76) = 7, WEEKDAY(B76) = 1), 1, 0) -> 0 | D76: 0 | E76: =IF((C76+D76)>0, 1, 0) -> 0 | F76: =TEXT(B76, "dddd") -> Tuesday | H76: 2 | I76: =IF(J76>J75, IF(H76<>H75,1, I75+1),I75) -> 1 | J76: =_xlfn.ISOWEEKNUM(B76) -> 44
A77: 76 | B77: 44867 | C77: =IF(OR(WEEKDAY(B77) = 7, WEEKDAY(B77) = 1), 1, 0) -> 0 | D77: 0 | E77: =IF((C77+D77)>0, 1, 0) -> 0 | F77: =TEXT(B77, "dddd") -> Wednesday | H77: 2 | I77: =IF(J77>J76, IF(H77<>H76,1, I76+1),I76) -> 1 | J77: =_xlfn.ISOWEEKNUM(B77) -> 44
A78: 77 | B78: 44868 | C78: =IF(OR(WEEKDAY(B78) = 7, WEEKDAY(B78) = 1), 1, 0) -> 0 | D78: 0 | E78: =IF((C78+D78)>0, 1, 0) -> 0 | F78: =TEXT(B78, "dddd") -> Thursday | H78: 2 | I78: =IF(J78>J77, IF(H78<>H77,1, I77+1),I77) -> 1 | J78: =_xlfn.ISOWEEKNUM(B78) -> 44
A79: 78 | B79: 44869 | C79: =IF(OR(WEEKDAY(B79) = 7, WEEKDAY(B79) = 1), 1, 0) -> 0 | D79: 0 | E79: =IF((C79+D79)>0, 1, 0) -> 0 | F79: =TEXT(B79, "dddd") -> Friday | H79: 2 | I79: =IF(J79>J78, IF(H79<>H78,1, I78+1),I78) -> 1 | J79: =_xlfn.ISOWEEKNUM(B79) -> 44
A80: 79 | B80: 44870 | C80: =IF(OR(WEEKDAY(B80) = 7, WEEKDAY(B80) = 1), 1, 0) -> 1 | D80: 0 | E80: =IF((C80+D80)>0, 1, 0) -> 1 | F80: =TEXT(B80, "dddd") -> Saturday | H80: 2 | I80: =IF(J80>J79, IF(H80<>H79,1, I79+1),I79) -> 1 | J80: =_xlfn.ISOWEEKNUM(B80) -> 44
A81: 80 | B81: 44871 | C81: =IF(OR(WEEKDAY(B81) = 7, WEEKDAY(B81) = 1), 1, 0) -> 1 | D81: 0 | E81: =IF((C81+D81)>0, 1, 0) -> 1 | F81: =TEXT(B81, "dddd") -> Sunday | H81: 2 | I81: =IF(J81>J80, IF(H81<>H80,1, I80+1),I80) -> 1 | J81: =_xlfn.ISOWEEKNUM(B81) -> 44
A82: 81 | B82: 44872 | C82: =IF(OR(WEEKDAY(B82) = 7, WEEKDAY(B82) = 1), 1, 0) -> 0 | D82: 0 | E82: =IF((C82+D82)>0, 1, 0) -> 0 | F82: =TEXT(B82, "dddd") -> Monday | H82: 2 | I82: =IF(J82>J81, IF(H82<>H81,1, I81+1),I81) -> 2 | J82: =_xlfn.ISOWEEKNUM(B82) -> 45
A83: 82 | B83: 44873 | C83: =IF(OR(WEEKDAY(B83) = 7, WEEKDAY(B83) = 1), 1, 0) -> 0 | D83: 0 | E83: =IF((C83+D83)>0, 1, 0) -> 0 | F83: =TEXT(B83, "dddd") -> Tuesday | H83: 2 | I83: =IF(J83>J82, IF(H83<>H82,1, I82+1),I82) -> 2 | J83: =_xlfn.ISOWEEKNUM(B83) -> 45
A84: 83 | B84: 44874 | C84: =IF(OR(WEEKDAY(B84) = 7, WEEKDAY(B84) = 1), 1, 0) -> 0 | D84: 0 | E84: =IF((C84+D84)>0, 1, 0) -> 0 | F84: =TEXT(B84, "dddd") -> Wednesday | H84: 2 | I84: =IF(J84>J83, IF(H84<>H83,1, I83+1),I83) -> 2 | J84: =_xlfn.ISOWEEKNUM(B84) -> 45
A85: 84 | B85: 44875 | C85: =IF(OR(WEEKDAY(B85) = 7, WEEKDAY(B85) = 1), 1, 0) -> 0 | D85: 0 | E85: =IF((C85+D85)>0, 1, 0) -> 0 | F85: =TEXT(B85, "dddd") -> Thursday | H85: 2 | I85: =IF(J85>J84, IF(H85<>H84,1, I84+1),I84) -> 2 | J85: =_xlfn.ISOWEEKNUM(B85) -> 45
A86: 85 | B86: 44876 | C86: =IF(OR(WEEKDAY(B86) = 7, WEEKDAY(B86) = 1), 1, 0) -> 0 | D86: 0 | E86: =IF((C86+D86)>0, 1, 0) -> 0 | F86: =TEXT(B86, "dddd") -> Friday | H86: 2 | I86: =IF(J86>J85, IF(H86<>H85,1, I85+1),I85) -> 2 | J86: =_xlfn.ISOWEEKNUM(B86) -> 45
A87: 86 | B87: 44877 | C87: =IF(OR(WEEKDAY(B87) = 7, WEEKDAY(B87) = 1), 1, 0) -> 1 | D87: 0 | E87: =IF((C87+D87)>0, 1, 0) -> 1 | F87: =TEXT(B87, "dddd") -> Saturday | H87: 2 | I87: =IF(J87>J86, IF(H87<>H86,1, I86+1),I86) -> 2 | J87: =_xlfn.ISOWEEKNUM(B87) -> 45
... A129: 128 | B129: 44919 | C129: =IF(OR(WEEKDAY(B129) = 7, WEEKDAY(B129) = 1), 1, 0) -> 1 | D129: 0 | E129: =IF((C129+D129)>0, 1, 0) -> 1 | F129: =TEXT(B129, "dddd") -> Saturday | H129: 2 | I129: =IF(J129>J128, IF(H129<>H128,1, I128+1),I128) -> 8 | J129: =_xlfn.ISOWEEKNUM(B129) -> 51
A130: 129 | B130: 44920 | C130: =IF(OR(WEEKDAY(B130) = 7, WEEKDAY(B130) = 1), 1, 0) -> 1 | D130: 1 | E130: =IF((C130+D130)>0, 1, 0) -> 1 | F130: =TEXT(B130, "dddd") -> Sunday | G130: Kerstvakantie | H130: 2 | I130: =IF(J130>J129, IF(H130<>H129,1, I129+1),I129) -> 8 | J130: =_xlfn.ISOWEEKNUM(B130) -> 51
A131: 130 | B131: 44921 | C131: =IF(OR(WEEKDAY(B131) = 7, WEEKDAY(B131) = 1), 1, 0) -> 0 | D131: 1 | E131: =IF((C131+D131)>0, 1, 0) -> 1 | F131: =TEXT(B131, "dddd") -> Monday | G131: Kerstvakantie | H131: 2 | I131: =IF(J131>J130, IF(H131<>H130,1, I130+1),I130) -> 9 | J131: =_xlfn.ISOWEEKNUM(B131) -> 52
...

Sheet Grade
A1: ID | B1: StudentID | C1: Date | D1: PaceCourseID | E1: Course | F1: CourseName__ | G1: PACE_ID | H1: Type | I1: Grade | J1: Remarks | K1: Test__
A2: 1 | B2: 2 | C2: 44936 | E2: 117 | F2: Physics | G2: 145 | H2: PACE | I2: 0.819 | K2: 1
A3: 2 | B3: 2 | C3: =C2+1 -> 44937 | E3: 117 | F3: Physics | G3: 146 | H3: PACE | I3: 0.854 | K3: 1
A4: 3 | B4: 2 | C4: =C3+1 -> 44938 | E4: 125 | F4: Life of Christ II | G4: 1212 | H4: PACE | I4: 0.896 | K4: 1
A5: 4 | B5: 2 | C5: =C4+1 -> 44939 | E5: 117 | F5: Physics | G5: 147 | H5: PACE | I5: 0.803 | K5: 1
A6: 5 | B6: 2 | C6: =C5+1 -> 44940 | E6: 117 | F6: Physics | G6: 148 | H6: PACE | I6: 0.851 | K6: 1
A7: 6 | B7: 2 | C7: =C6+1 -> 44941 | E7: 117 | F7: Physics | G7: 149 | H7: PACE | I7: 0.926 | K7: 1
A8: 7 | B8: 2 | C8: =C7+1 -> 44942 | E8: 125 | F8: Life of Christ II | G8: 1213 | H8: PACE | I8: 0.872 | K8: 1
A9: 8 | B9: 2 | C9: =C8+1 -> 44943 | E9: 117 | F9: Physics | G9: 150 | H9: PACE | I9: 0.955 | K9: 1
A10: 9 | B10: 2 | C10: =C9+1 -> 44944 | E10: 117 | F10: Physics | G10: 151 | H10: PACE | I10: 0.918 | K10: 1
A11: 10 | B11: 2 | C11: =C10+1 -> 44945 | E11: 125 | F11: Life of Christ II | G11: 1214 | H11: PACE | I11: 0.921 | K11: 1
A12: 11 | B12: 2 | C12: =C11+1 -> 44946 | E12: 117 | F12: Physics | G12: 152 | H12: PACE | I12: 0.957 | K12: 1
A13: 12 | B13: 2 | C13: =C12+1 -> 44947 | E13: 125 | F13: Life of Christ II | G13: 1215 | H13: PACE | I13: 0.97 | K13: 1
A14: 13 | B14: 2 | C14: =C13+1 -> 44948 | E14: 125 | F14: Life of Christ II | G14: 1216 | H14: PACE | I14: 0.915 | K14: 1
... A50: 49 | B50: 2 | C50: =C49+1 -> 44984 | E50: 111 | F50: Trigonometry | G50: 1097 | H50: PACE | I50: 0.975 | K50: 1
A51: 50 | B51: 29 | C51: 45030 | E51: 38 | F51: English | G51: 451 | H51: PACE | I51: 0.92 | K51: 1
A52: 51 | B52: 29 | C52: 45030 | E52: 39 | F52: Word Building | G52: 463 | H52: PACE | I52: 0.98 | K52: 1
A53: 52 | B53: 29 | C53: 44981 | E53: 38 | F53: English | G53: 283 | H53: PACE | I53: 0.995 | K53: 1
A54: 53 | B54: 29 | C54: 45028 | E54: 41 | F54: Science Level 6 | G54: 487 | H54: PACE | I54: 0.995 | K54: 1
A55: 54 | B55: 29 | C55: 45028 | E55: 42 | F55: Social Studies Level 6 | G55: 499 | H55: PACE | I55: 0.995 | K55: 1
A56: 55 | B56: 29 | C56: 45028 | E56: ? | F56: Grammar | G56: 499 | H56: PACE | I56: 0.995 | K56: 1

Sheet Class
A1: ID | B1: Class
A2: 0 | B2: Not Applicable
A3: 1 | B3: Kindergarten
A4: 2 | B4: ABCs
A5: 3 | B5: Juniors
A6: 4 | B6: Seniors

Sheet SubjectGroup
A1: ID | B1: Name | C1: order
A2: 1 | B2: Christian Studies | C2: 1
A3: 2 | B3: Core Academic Studies | C3: 2
A4: 3 | B4: Core Expanded Studies | C4: 3
A5: 4 | B5: Applied Studies | C5: 4
A6: 5 | B6: Dutch Language | C6: 5
A7: 6 | B7: Supplementary Activities | C7: 6
A8: 7 | B8: Coursework | C8: 7
A9: 8 | B9: Miscellaneous | C9: 8

Sheet Subject
A1: ID | B1: Name | C1: Colour | D1: SubjectLabel | E1: Abbreviation
A2: 1 | B2: Maths | C2: Yellow | D2: Academic | E2: MA
A3: 2 | B3: Language | C3: Red | D3: Academic | E3: LA
A4: 3 | B4: Word Building | C4: Purple | D4: Academic | E4: WB
A5: 4 | B5: Literature | C5: DarkRed | D5: Academic | E5: LI
A6: 5 | B6: Science | C6: Blue | D6: Academic | E6: SC
A7: 6 | B7: Social Studies | C7: Green | D7: Academic | E7: SS
A8: 7 | B8: Biblical Studies | C8: SandOrange | D8: Christian | E8: BS
A9: 8 | B9: Electives | C9: Grey | D9: Elective | E9: EL
A10: 9 | B10: Dutch Language | C10: Orange | D10: Academic | E10: NL
A11: 10 | B11: Supplementary | C11: White | D11: Elective | E11: SU

Sheet ICCE_Certificate
A1: ID | B1: Certificate
A2: 1 | B2: Vocational Level 7
A3: 2 | B3: General Level 9
A4: 3 | B4: Intermediate
A5: 4 | B5: Advanced
A6: 5 | B6: Advanced Higher
A7: 6 | B7: Advanced Maths Bias
A8: 7 | B8: Advanced Social Studies Bias
A9: 8 | B9: Advanced Science Bias
A10: 9 | B10: General Level 8
A11: 10 | B11: Level 2
A12: 11 | B12: Level 3
A13: 12 | B13: Level 4
... A15: 14 | B15: Level 6

Sheet Enrollment
A1: ID | B1: Certificate | C1: CertificateID | D1: CourseName | E1: needChoice | F1: Type | G1: SubjectGroup | H1: SubjectGroupID | I1: StarValue | J1: Note | K1: Order
A2: 1 | B2: =VLOOKUP(C2,ICCE_Certificate!$A$2:$B$10,2, FALSE) -> Advanced | C2: 4 | D2: NT Church History / Life of Christ | E2: T | F2: Biblical Studies | G2: =VLOOKUP(H2, SubjectGroup!$A$2:$B$9, 2, FALSE) -> Christian Studies | H2: 1 | I2: 12
A3: 2 | B3: =VLOOKUP(C3,ICCE_Certificate!$A$2:$B$10,2, FALSE) -> Advanced | C3: 4 | D3: Apologetics III | E3: T | G3: =VLOOKUP(H3, SubjectGroup!$A$2:$B$9, 2, FALSE) -> Christian Studies | H3: 1 | I3: 6
A4: 3 | B4: =VLOOKUP(C4,ICCE_Certificate!$A$2:$B$10,2, FALSE) -> Advanced | C4: 4 | D4: Algebra II | E4: F | G4: =VLOOKUP(H4, SubjectGroup!$A$2:$B$9, 2, FALSE) -> Core Academic Studies | H4: 2 | I4: 12
A5: 4 | B5: =VLOOKUP(C5,ICCE_Certificate!$A$2:$B$10,2, FALSE) -> Advanced | C5: 4 | D5: English III / English IV | E5: T | F5: English | G5: =VLOOKUP(H5, SubjectGroup!$A$2:$B$9, 2, FALSE) -> Core Academic Studies | H5: 2 | I5: 12
A6: 5 | B6: =VLOOKUP(C6,ICCE_Certificate!$A$2:$B$10,2, FALSE) -> Advanced | C6: 4 | D6: Chemistry / Physics | E6: T | F6: Chemistry | G6: =VLOOKUP(H6, SubjectGroup!$A$2:$B$9, 2, FALSE) -> Core Academic Studies | H6: 2 | I6: 12
A7: 6 | B7: =VLOOKUP(C7,ICCE_Certificate!$A$2:$B$10,2, FALSE) -> Advanced | C7: 4 | D7: History of Civilisation II | E7: F | G7: =VLOOKUP(H7, SubjectGroup!$A$2:$B$9, 2, FALSE) -> Core Academic Studies | H7: 2 | I7: 12
A8: 7 | B8: =VLOOKUP(C8,ICCE_Certificate!$A$2:$B$10,2, FALSE) -> Advanced | C8: 4 | D8: Further Credit Option | E8: F | F8: Further Credit Option | G8: =VLOOKUP(H8, SubjectGroup!$A$2:$B$9, 2, FALSE) -> Miscellaneous | H8: 8 | I8: 12
A9: 8 | B9: =VLOOKUP(C9,ICCE_Certificate!$A$2:$B$10,2, FALSE) -> Advanced | C9: 4 | D9: Coursework 1 | E9: T | F9: Coursework | G9: =VLOOKUP(H9, SubjectGroup!$A$2:$B$9, 2, FALSE) -> Coursework | H9: 7 | I9: 2
A10: 9 | B10: =VLOOKUP(C10,ICCE_Certificate!$A$2:$B$10,2, FALSE) -> Advanced | C10: 4 | D10: Coursework 2 | E10: T | F10: Coursework | G10: =VLOOKUP(H10, SubjectGroup!$A$2:$B$9, 2, FALSE) -> Coursework | H10: 7 | I10: 2
A11: 10 | B11: =VLOOKUP(C11,ICCE_Certificate!$A$2:$B$10,2, FALSE) -> Advanced | C11: 4 | D11: Coursework 3 | E11: T | F11: Coursework | G11: =VLOOKUP(H11, SubjectGroup!$A$2:$B$9, 2, FALSE) -> Coursework | H11: 7 | I11: 2
A12: 11 | B12: =VLOOKUP(C12,ICCE_Certificate!$A$2:$B$10,2, FALSE) -> Advanced Maths Bias | C12: 6 | D12: NT Church History / Life of Christ | E12: T | F12: Biblical Studies | G12: =VLOOKUP(H12, SubjectGroup!$A$2:$B$9, 2, FALSE) -> Christian Studies | H12: 1 | I12: 12 | K12: 10
A13: 12 | B13: =VLOOKUP(C13,ICCE_Certificate!$A$2:$B$10,2, FALSE) -> Advanced Maths Bias | C13: 6 | D13: Apologetics III | E13: T | F13: Biblical Studies | G13: =VLOOKUP(H13, SubjectGroup!$A$2:$B$9, 2, FALSE) -> Christian Studies | H13: 1 | I13: 6 | K13: 11
A14: 13 | B14: =VLOOKUP(C14,ICCE_Certificate!$A$2:$B$10,2, FALSE) -> Advanced Maths Bias | C14: 6 | D14: Algebra II | E14: F | G14: =VLOOKUP(H14, SubjectGroup!$A$2:$B$9, 2, FALSE) -> Core Academic Studies | H14: 2 | I14: 12 | K14: 1
A15: 14 | B15: =VLOOKUP(C15,ICCE_Certificate!$A$2:$B$10,2, FALSE) -> Advanced Maths Bias | C15: 6 | D15: Trigonometry | E15: F | G15: =VLOOKUP(H15, SubjectGroup!$A$2:$B$9, 2, FALSE) -> Core Academic Studies | H15: 2 | I15: 6 | K15: =K14+1 -> 2
A16: 15 | B16: =VLOOKUP(C16,ICCE_Certificate!$A$2:$B$10,2, FALSE) -> Advanced Maths Bias | C16: 6 | D16: Higher Maths | E16: F | G16: =VLOOKUP(H16, SubjectGroup!$A$2:$B$9, 2, FALSE) -> Core Academic Studies | H16: 2 | I16: 6 | K16: =K15+1 -> 3
A17: 16 | B17: =VLOOKUP(C17,ICCE_Certificate!$A$2:$B$10,2, FALSE) -> Advanced Maths Bias | C17: 6 | D17: College Maths I | E17: F | G17: =VLOOKUP(H17, SubjectGroup!$A$2:$B$9, 2, FALSE) -> Core Academic Studies | H17: 2 | I17: 12 | K17: =K16+1 -> 4
A18: 17 | B18: =VLOOKUP(C18,ICCE_Certificate!$A$2:$B$10,2, FALSE) -> Advanced Maths Bias | C18: 6 | D18: College Maths II | E18: F | G18: =VLOOKUP(H18, SubjectGroup!$A$2:$B$9, 2, FALSE) -> Core Academic Studies | H18: 2 | I18: 12 | K18: =K17+1 -> 5
A19: 18 | B19: =VLOOKUP(C19,ICCE_Certificate!$A$2:$B$10,2, FALSE) -> Advanced Maths Bias | C19: 6 | D19: Physics | E19: F | G19: =VLOOKUP(H19, SubjectGroup!$A$2:$B$9, 2, FALSE) -> Core Academic Studies | H19: 2 | I19: 12 | K19: 7
A20: 19 | B20: =VLOOKUP(C20,ICCE_Certificate!$A$2:$B$10,2, FALSE) -> Advanced Maths Bias | C20: 6 | D20: ICT Course | E20: T | F20: ICT Course | G20: =VLOOKUP(H20, SubjectGroup!$A$2:$B$9, 2, FALSE) -> Core Expanded Studies | H20: 3 | I20: 12 | K20: 12
A21: 20 | B21: =VLOOKUP(C21,ICCE_Certificate!$A$2:$B$10,2, FALSE) -> Advanced Maths Bias | C21: 6 | D21: Further Credit Option | E21: T | F21: Further Credit Option | G21: =VLOOKUP(H21, SubjectGroup!$A$2:$B$9, 2, FALSE) -> Core Academic Studies | H21: 2 | I21: 12 | K21: =K20+1 -> 13
A22: 21 | B22: =VLOOKUP(C22,ICCE_Certificate!$A$2:$B$10,2, FALSE) -> Advanced Maths Bias | C22: 6 | D22: Coursework 1 | E22: T | F22: Coursework | G22: =VLOOKUP(H22, SubjectGroup!$A$2:$B$9, 2, FALSE) -> Coursework | H22: 7 | I22: 2 | K22: 6
A23: 22 | B23: =VLOOKUP(C23,ICCE_Certificate!$A$2:$B$10,2, FALSE) -> Advanced Maths Bias | C23: 6 | D23: Coursework 2 | E23: T | F23: Coursework | G23: =VLOOKUP(H23, SubjectGroup!$A$2:$B$9, 2, FALSE) -> Coursework | H23: 7 | I23: 2 | K23: 8
A24: 23 | B24: =VLOOKUP(C24,ICCE_Certificate!$A$2:$B$10,2, FALSE) -> Advanced Maths Bias | C24: 6 | D24: Coursework 3 | E24: T | F24: Coursework | G24: =VLOOKUP(H24, SubjectGroup!$A$2:$B$9, 2, FALSE) -> Coursework | H24: 7 | I24: 2 | K24: 9
A25: 24 | B25: =VLOOKUP(C25,ICCE_Certificate!$A$2:$B$10,2, FALSE) -> Advanced Social Studies Bias | C25: 7 | D25: NT Church History / Life of Christ | E25: T | F25: Biblical Studies | G25: =VLOOKUP(H25, SubjectGroup!$A$2:$B$9, 2, FALSE) -> Christian Studies | H25: 1 | I25: 12
A26: 25 | B26: =VLOOKUP(C26,ICCE_Certificate!$A$2:$B$10,2, FALSE) -> Advanced Social Studies Bias | C26: 7 | D26: Apologetics III | E26: F | G26: =VLOOKUP(H26, SubjectGroup!$A$2:$B$9, 2, FALSE) -> Christian Studies | H26: 1 | I26: 6
A27: 26 | B27: =VLOOKUP(C27,ICCE_Certificate!$A$2:$B$10,2, FALSE) -> Advanced Social Studies Bias | C27: 7 | D27: English III | E27: F | G27: =VLOOKUP(H27, SubjectGroup!$A$2:$B$9, 2, FALSE) -> Core Academic Studies | H27: 2 | I27: 12
A28: 27 | B28: =VLOOKUP(C28,ICCE_Certificate!$A$2:$B$10,2, FALSE) -> Advanced Social Studies Bias | C28: 7 | D28: English Composition II | E28: F | G28: =VLOOKUP(H28, SubjectGroup!$A$2:$B$9, 2, FALSE) -> Core Academic Studies | H28: 2 | I28: 12 | J28: Andere nummers in PACE
A29: 28 | B29: =VLOOKUP(C29,ICCE_Certificate!$A$2:$B$10,2, FALSE) -> Advanced Social Studies Bias | C29: 7 | D29: History of Civilisation II | E29: F | G29: =VLOOKUP(H29, SubjectGroup!$A$2:$B$9, 2, FALSE) -> Core Academic Studies | H29: 2 | I29: 12
A30: 29 | B30: =VLOOKUP(C30,ICCE_Certificate!$A$2:$B$10,2, FALSE) -> Advanced Social Studies Bias | C30: 7 | D30: Economics and Civics | E30: F | G30: =VLOOKUP(H30, SubjectGroup!$A$2:$B$9, 2, FALSE) -> Core Academic Studies | H30: 2 | I30: 12 | J30: Andere naam dan in FCO
A31: 30 | B31: =VLOOKUP(C31,ICCE_Certificate!$A$2:$B$10,2, FALSE) -> Advanced Social Studies Bias | C31: 7 | D31: Further Credit Option | E31: T | F31: Further Credit Option | G31: =VLOOKUP(H31, SubjectGroup!$A$2:$B$9, 2, FALSE) -> Miscellaneous | H31: 8 | I31: 12
A32: 31 | B32: =VLOOKUP(C32,ICCE_Certificate!$A$2:$B$10,2, FALSE) -> Advanced Social Studies Bias | C32: 7 | D32: Coursework 1 | E32: T | F32: Coursework | G32: =VLOOKUP(H32, SubjectGroup!$A$2:$B$9, 2, FALSE) -> Coursework | H32: 7 | I32: 2
A33: 32 | B33: =VLOOKUP(C33,ICCE_Certificate!$A$2:$B$10,2, FALSE) -> Advanced Social Studies Bias | C33: 7 | D33: Coursework 2 | E33: T | F33: Coursework | G33: =VLOOKUP(H33, SubjectGroup!$A$2:$B$9, 2, FALSE) -> Coursework | H33: 7 | I33: 2
A34: 33 | B34: =VLOOKUP(C34,ICCE_Certificate!$A$2:$B$10,2, FALSE) -> Advanced Social Studies Bias | C34: 7 | D34: Coursework 3 | E34: T | F34: Coursework | G34: =VLOOKUP(H34, SubjectGroup!$A$2:$B$9, 2, FALSE) -> Coursework | H34: 7 | I34: 2
A35: 34 | B35: =VLOOKUP(C35,ICCE_Certificate!$A$2:$B$10,2, FALSE) -> Advanced Science Bias | C35: 8 | D35: NT Church History / Life of Christ | E35: T | G35: =VLOOKUP(H35, SubjectGroup!$A$2:$B$9, 2, FALSE) -> Christian Studies | H35: 1 | I35: 12
A36: 35 | B36: =VLOOKUP(C36,ICCE_Certificate!$A$2:$B$10,2, FALSE) -> Advanced Science Bias | C36: 8 | D36: Apologetics III | E36: F | G36: =VLOOKUP(H36, SubjectGroup!$A$2:$B$9, 2, FALSE) -> Christian Studies | H36: 1 | I36: 6
A37: 36 | B37: =VLOOKUP(C37,ICCE_Certificate!$A$2:$B$10,2, FALSE) -> Advanced Science Bias | C37: 8 | D37: Algebra II | E37: F | G37: =VLOOKUP(H37, SubjectGroup!$A$2:$B$9, 2, FALSE) -> Core Academic Studies | H37: 2 | I37: 12
A38: 37 | B38: =VLOOKUP(C38,ICCE_Certificate!$A$2:$B$10,2, FALSE) -> Advanced Science Bias | C38: 8 | D38: Trigonometry | E38: F | G38: =VLOOKUP(H38, SubjectGroup!$A$2:$B$9, 2, FALSE) -> Core Academic Studies | H38: 2 | I38: 6
A39: 38 | B39: =VLOOKUP(C39,ICCE_Certificate!$A$2:$B$10,2, FALSE) -> Advanced Science Bias | C39: 8 | D39: Higher Maths | E39: F | G39: =VLOOKUP(H39, SubjectGroup!$A$2:$B$9, 2, FALSE) -> Core Academic Studies | H39: 2 | I39: 6
A40: 39 | B40: =VLOOKUP(C40,ICCE_Certificate!$A$2:$B$10,2, FALSE) -> Advanced Science Bias | C40: 8 | D40: Chemistry | E40: F | G40: =VLOOKUP(H40, SubjectGroup!$A$2:$B$9, 2, FALSE) -> Core Academic Studies | H40: 2 | I40: 12
...

Sheet Course
A1: ID | C1: Alias | D1: ICCE-Alias | E1: Level | F1: PaceNrStart | G1: PaceNrEnd | H1: PaceCount__ | I1: StarValue | J1: SubjectID | K1: Subject_temp | L1: SubjectAbb | M1: Remarks | N1: Specification | O1: SubjectGroupID | P1: SubjectGroup | Q1: CourseType | R1: Course | S1: PassThreshold
A2: 1 | C2: Maths Reading Readiness | E2: 0 | F2: 1 | G2: 12 | H2: =G2-F2+1 -> 12 | I2: 12 | J2: 1 | K2: =VLOOKUP(J2, Subject!$A$2:$B$15, 2, FALSE) -> Maths | L2: =VLOOKUP(J2, Subject!$A$2:$E$11, 5, FALSE) -> MA | N2: RR | O2: 2 | P2: =VLOOKUP(O2, SubjectGroup!$A$2:$B$8, 2, FALSE) -> Core Academic Studies | Q2: Core | R2: =C2 -> Maths Reading Readiness | S2: 0.8
A3: 2 | C3: Maths Level 1 | E3: 1 | F3: 1 | G3: 12 | H3: =G3-F3+1 -> 12 | I3: 12 | J3: 1 | K3: =VLOOKUP(J3, Subject!$A$2:$B$15, 2, FALSE) -> Maths | L3: =VLOOKUP(J3, Subject!$A$2:$E$11, 5, FALSE) -> MA | N3: MA | O3: 2 | P3: =VLOOKUP(O3, SubjectGroup!$A$2:$B$8, 2, FALSE) -> Core Academic Studies | Q3: Core | R3: =C3 -> Maths Level 1 | S3: 0.8
A4: 3 | C4: English Level 1 | E4: 1 | F4: 1 | G4: 12 | H4: =G4-F4+1 -> 12 | I4: 12 | J4: 2 | K4: =VLOOKUP(J4, Subject!$A$2:$B$15, 2, FALSE) -> Language | L4: =VLOOKUP(J4, Subject!$A$2:$E$11, 5, FALSE) -> LA | N4: EN | O4: 2 | P4: =VLOOKUP(O4, SubjectGroup!$A$2:$B$8, 2, FALSE) -> Core Academic Studies | Q4: Core | R4: =C4 -> English Level 1 | S4: 0.8
A5: 4 | C5: Word Building Level 1 | E5: 1 | F5: 1 | G5: 12 | H5: =G5-F5+1 -> 12 | I5: 12 | J5: 3 | K5: =VLOOKUP(J5, Subject!$A$2:$B$15, 2, FALSE) -> Word Building | L5: =VLOOKUP(J5, Subject!$A$2:$E$11, 5, FALSE) -> WB | N5: WB | O5: 2 | P5: =VLOOKUP(O5, SubjectGroup!$A$2:$B$8, 2, FALSE) -> Core Academic Studies | Q5: Core | R5: =C5 -> Word Building Level 1 | S5: 0.9
A6: 5 | C6: Literature and Creative Writing Level 1 | E6: 1 | F6: 1 | G6: 12 | H6: =G6-F6+1 -> 12 | I6: 12 | J6: 4 | K6: =VLOOKUP(J6, Subject!$A$2:$B$15, 2, FALSE) -> Literature | L6: =VLOOKUP(J6, Subject!$A$2:$E$11, 5, FALSE) -> LI | N6: LC | O6: 2 | P6: =VLOOKUP(O6, SubjectGroup!$A$2:$B$8, 2, FALSE) -> Core Academic Studies | Q6: Core | R6: =C6 -> Literature and Creative Writing Level 1 | S6: 0.8
A7: 6 | C7: Science Level 1 | E7: 1 | F7: 1 | G7: 12 | H7: =G7-F7+1 -> 12 | I7: 12 | J7: 5 | K7: =VLOOKUP(J7, Subject!$A$2:$B$15, 2, FALSE) -> Science | L7: =VLOOKUP(J7, Subject!$A$2:$E$11, 5, FALSE) -> SC | N7: SC | O7: 2 | P7: =VLOOKUP(O7, SubjectGroup!$A$2:$B$8, 2, FALSE) -> Core Academic Studies | Q7: Core | R7: =C7 -> Science Level 1 | S7: 0.8
A8: 7 | C8: Social Studies Level 1 | E8: 1 | F8: 1 | G8: 12 | H8: =G8-F8+1 -> 12 | I8: 12 | J8: 6 | K8: =VLOOKUP(J8, Subject!$A$2:$B$15, 2, FALSE) -> Social Studies | L8: =VLOOKUP(J8, Subject!$A$2:$E$11, 5, FALSE) -> SS | N8: SS | O8: 2 | P8: =VLOOKUP(O8, SubjectGroup!$A$2:$B$8, 2, FALSE) -> Core Academic Studies | Q8: Core | R8: =C8 -> Social Studies Level 1 | S8: 0.8
A9: 8 | C9: Bible Reading Level 1 | E9: 1 | F9: 1 | G9: 12 | H9: =G9-F9+1 -> 12 | I9: 12 | J9: 7 | K9: =VLOOKUP(J9, Subject!$A$2:$B$15, 2, FALSE) -> Biblical Studies | L9: =VLOOKUP(J9, Subject!$A$2:$E$11, 5, FALSE) -> BS | N9: BR | O9: 1 | P9: =VLOOKUP(O9, SubjectGroup!$A$2:$B$8, 2, FALSE) -> Christian Studies | Q9: Core | R9: =C9 -> Bible Reading Level 1 | S9: 0.8
A10: 9 | C10: Maths Level 2 | E10: 2 | F10: 13 | G10: 24 | H10: =G10-F10+1 -> 12 | I10: 12 | J10: 1 | K10: =VLOOKUP(J10, Subject!$A$2:$B$15, 2, FALSE) -> Maths | L10: =VLOOKUP(J10, Subject!$A$2:$E$11, 5, FALSE) -> MA | N10: MA | O10: 2 | P10: =VLOOKUP(O10, SubjectGroup!$A$2:$B$8, 2, FALSE) -> Core Academic Studies | Q10: Core | R10: =C10 -> Maths Level 2 | S10: 0.8
A11: 10 | C11: English Level 2 | E11: 2 | F11: 13 | G11: 24 | H11: =G11-F11+1 -> 12 | I11: 12 | J11: 2 | K11: =VLOOKUP(J11, Subject!$A$2:$B$15, 2, FALSE) -> Language | L11: =VLOOKUP(J11, Subject!$A$2:$E$11, 5, FALSE) -> LA | N11: EN | O11: 2 | P11: =VLOOKUP(O11, SubjectGroup!$A$2:$B$8, 2, FALSE) -> Core Academic Studies | Q11: Core | R11: =C11 -> English Level 2 | S11: 0.8
A12: 11 | C12: Word Building Level 2 | E12: 2 | F12: 13 | G12: 24 | H12: =G12-F12+1 -> 12 | I12: 12 | J12: 3 | K12: =VLOOKUP(J12, Subject!$A$2:$B$15, 2, FALSE) -> Word Building | L12: =VLOOKUP(J12, Subject!$A$2:$E$11, 5, FALSE) -> WB | N12: WB | O12: 2 | P12: =VLOOKUP(O12, SubjectGroup!$A$2:$B$8, 2, FALSE) -> Core Academic Studies | Q12: Core | R12: =C12 -> Word Building Level 2 | S12: 0.9
A13: 12 | C13: Literature and Creative Writing Level 2 | E13: 2 | F13: 13 | G13: 24 | H13: =G13-F13+1 -> 12 | I13: 12 | J13: 4 | K13: =VLOOKUP(J13, Subject!$A$2:$B$15, 2, FALSE) -> Literature | L13: =VLOOKUP(J13, Subject!$A$2:$E$11, 5, FALSE) -> LI | N13: LC | O13: 2 | P13: =VLOOKUP(O13, SubjectGroup!$A$2:$B$8, 2, FALSE) -> Core Academic Studies | Q13: Core | R13: =C13 -> Literature and Creative Writing Level 2 | S13: 0.8
... A48: 47 | C48: Word Building Level 7 | E48: 7 | F48: 73 | G48: 84 | H48: =G48-F48+1 -> 12 | I48: 12 | J48: 3 | K48: =VLOOKUP(J48, Subject!$A$2:$B$15, 2, FALSE) -> Word Building | L48: =VLOOKUP(J48, Subject!$A$2:$E$11, 5, FALSE) -> WB | N48: WB | O48: 2 | P48: =VLOOKUP(O48, SubjectGroup!$A$2:$B$8, 2, FALSE) -> Core Academic Studies | Q48: Core | R48: =C48 -> Word Building Level 7 | S48: 0.9
A49: 48 | C49: Literature Level 7 | E49: 7 | F49: 73 | G49: 84 | H49: =G49-F49+1 -> 12 | J49: 4 | K49: =VLOOKUP(J49, Subject!$A$2:$B$15, 2, FALSE) -> Literature | L49: =VLOOKUP(J49, Subject!$A$2:$E$11, 5, FALSE) -> LI | M49: Alleen even getallen hebben PACE beschikbaar | N49: LC | O49: 2 | P49: =VLOOKUP(O49, SubjectGroup!$A$2:$B$8, 2, FALSE) -> Core Academic Studies | Q49: Core | R49: =C49 -> Literature Level 7 | S49: 0.8
A50: 49 | C50: Science Level 7 | E50: 7 | F50: 73 | G50: 84 | H50: =G50-F50+1 -> 12 | I50: 12 | J50: 5 | K50: =VLOOKUP(J50, Subject!$A$2:$B$15, 2, FALSE) -> Science | L50: =VLOOKUP(J50, Subject!$A$2:$E$11, 5, FALSE) -> SC | N50: SC | O50: 2 | P50: =VLOOKUP(O50, SubjectGroup!$A$2:$B$8, 2, FALSE) -> Core Academic Studies | Q50: Core | R50: =C50 -> Science Level 7 | S50: 0.8
A51: 50 | C51: Social Studies Level 7 | E51: 7 | F51: 73 | G51: 78 | H51: =G51-F51+1 -> 6 | J51: 6 | K51: =VLOOKUP(J51, Subject!$A$2:$B$15, 2, FALSE) -> Social Studies | L51: =VLOOKUP(J51, Subject!$A$2:$E$11, 5, FALSE) -> SS | N51: SS | O51: 2 | P51: =VLOOKUP(O51, SubjectGroup!$A$2:$B$8, 2, FALSE) -> Core Academic Studies | Q51: Core | R51: =C51 -> Social Studies Level 7 | S51: 0.8
A52: 51 | C52: Staatsinrichting | E52: 7 | F52: 1 | G52: 3 | H52: =G52-F52+1 -> 3 | I52: 3 | J52: 6 | K52: =VLOOKUP(J52, Subject!$A$2:$B$15, 2, FALSE) -> Social Studies | L52: =VLOOKUP(J52, Subject!$A$2:$E$11, 5, FALSE) -> SS | N52: SI | O52: 2 | P52: =VLOOKUP(O52, SubjectGroup!$A$2:$B$8, 2, FALSE) -> Core Academic Studies | Q52: Core | R52: =C52 -> Staatsinrichting | S52: 0.8
A53: 52 | C53: Bible Reading Level 7 | E53: 7 | F53: 73 | G53: 84 | H53: =G53-F53+1 -> 12 | I53: 12 | J53: 7 | K53: =VLOOKUP(J53, Subject!$A$2:$B$15, 2, FALSE) -> Biblical Studies | L53: =VLOOKUP(J53, Subject!$A$2:$E$11, 5, FALSE) -> BS | M53: Dit bestaat nog niet. Misschien komt er later nog materiaal beschikbaar voor dit niveau. | N53: BR | O53: 2 | P53: =VLOOKUP(O53, SubjectGroup!$A$2:$B$8, 2, FALSE) -> Core Academic Studies | Q53: Core | R53: =C53 -> Bible Reading Level 7 | S53: 0.8
A54: 53 | C54: General Maths | E54: 8 | F54: 85 | G54: 96 | H54: =G54-F54+1 -> 12 | I54: 12 | J54: 1 | K54: =VLOOKUP(J54, Subject!$A$2:$B$15, 2, FALSE) -> Maths | L54: =VLOOKUP(J54, Subject!$A$2:$E$11, 5, FALSE) -> MA | N54: GM | O54: 2 | P54: =VLOOKUP(O54, SubjectGroup!$A$2:$B$8, 2, FALSE) -> Core Academic Studies | Q54: Core | R54: =C54 -> General Maths | S54: 0.8
A55: 54 | C55: General English | E55: 8 | F55: 85 | G55: 96 | H55: =G55-F55+1 -> 12 | I55: 12 | J55: 2 | K55: =VLOOKUP(J55, Subject!$A$2:$B$15, 2, FALSE) -> Language | L55: =VLOOKUP(J55, Subject!$A$2:$E$11, 5, FALSE) -> LA | N55: EN | O55: 1 | P55: =VLOOKUP(O55, SubjectGroup!$A$2:$B$8, 2, FALSE) -> Christian Studies | Q55: Core | R55: =C55 -> General English | S55: 0.8
A56: 55 | C56: Word Building Level 8 | E56: 8 | F56: 85 | G56: 96 | H56: =G56-F56+1 -> 12 | I56: 12 | J56: 3 | K56: =VLOOKUP(J56, Subject!$A$2:$B$15, 2, FALSE) -> Word Building | L56: =VLOOKUP(J56, Subject!$A$2:$E$11, 5, FALSE) -> WB | N56: WB | O56: 1 | P56: =VLOOKUP(O56, SubjectGroup!$A$2:$B$8, 2, FALSE) -> Christian Studies | Q56: Core | R56: =C56 -> Word Building Level 8 | S56: 0.9
A57: 56 | C57: Literature Level 8 | E57: 8 | F57: 86 | G57: 96 | H57: =G57-F57+1 -> 11 | J57: 4 | K57: =VLOOKUP(J57, Subject!$A$2:$B$15, 2, FALSE) -> Literature | L57: =VLOOKUP(J57, Subject!$A$2:$E$11, 5, FALSE) -> LI | M57: Alleen even getallen hebben PACE beschikbaar | N57: LC | O57: 1 | P57: =VLOOKUP(O57, SubjectGroup!$A$2:$B$8, 2, FALSE) -> Christian Studies | Q57: Core | R57: =C57 -> Literature Level 8 | S57: 0.8
A58: 57 | C58: Earth Science | E58: 8 | F58: 85 | G58: 96 | H58: =G58-F58+1 -> 12 | I58: 12 | J58: 5 | K58: =VLOOKUP(J58, Subject!$A$2:$B$15, 2, FALSE) -> Science | L58: =VLOOKUP(J58, Subject!$A$2:$E$11, 5, FALSE) -> SC | N58: ES | O58: 2 | P58: =VLOOKUP(O58, SubjectGroup!$A$2:$B$8, 2, FALSE) -> Core Academic Studies | Q58: Core | R58: Science Level 8 | S58: 0.8
A59: 58 | C59: British and European History | E59: 8 | F59: 97 | G59: 108 | H59: =G59-F59+1 -> 12 | I59: 12 | J59: 6 | K59: =VLOOKUP(J59, Subject!$A$2:$B$15, 2, FALSE) -> Social Studies | L59: =VLOOKUP(J59, Subject!$A$2:$E$11, 5, FALSE) -> SS | N59: UK | O59: 1 | P59: =VLOOKUP(O59, SubjectGroup!$A$2:$B$8, 2, FALSE) -> Christian Studies | Q59: Further Credit Option | R59: Social Studies Level 8 British and European History | S59: 0.8
A60: 59 | C60: World History | E60: 8 | F60: 97 | G60: 108 | H60: =G60-F60+1 -> 12 | I60: 12 | J60: 6 | K60: =VLOOKUP(J60, Subject!$A$2:$B$15, 2, FALSE) -> Social Studies | L60: =VLOOKUP(J60, Subject!$A$2:$E$11, 5, FALSE) -> SS | M60: Dit is tot 1/1/2024 een keuzevak voor het Enrollment-Course "British and European History / World History" binnen General, en alleen de 3rd Edition mag dan gebruikt worden. Daarna mag dit vak alleen nog gekozen worden binnen Intermediate en alleen met de 4th Editions | N60: WH | O60: 1 | P60: =VLOOKUP(O60, SubjectGroup!$A$2:$B$8, 2, FALSE) -> Christian Studies | Q60: Further Credit Option | R60: Social Studies Level 9 World History | S60: 0.8
A61: 60 | B61: Biblical Studies I | C61: New Testament Survey | E61: 8 | F61: 97 | G61: 102 | H61: =G61-F61+1 -> 6 | J61: 7 | K61: =VLOOKUP(J61, Subject!$A$2:$B$15, 2, FALSE) -> Biblical Studies | L61: =VLOOKUP(J61, Subject!$A$2:$E$11, 5, FALSE) -> BS | N61: NT | O61: 1 | P61: =VLOOKUP(O61, SubjectGroup!$A$2:$B$8, 2, FALSE) -> Christian Studies | Q61: Core | R61: =C61 -> New Testament Survey | S61: 0.8
A62: 61 | C62: Algebra I | E62: 9 | F62: 97 | G62: 108 | H62: =G62-F62+1 -> 12 | I62: 12 | J62: 1 | K62: =VLOOKUP(J62, Subject!$A$2:$B$15, 2, FALSE) -> Maths | L62: =VLOOKUP(J62, Subject!$A$2:$E$11, 5, FALSE) -> MA | N62: AL | O62: 1 | P62: =VLOOKUP(O62, SubjectGroup!$A$2:$B$8, 2, FALSE) -> Christian Studies | Q62: Core | R62: =C62 -> Algebra I | S62: 0.8
A63: 62 | C63: English I | E63: 9 | F63: 97 | G63: 108 | H63: =G63-F63+1 -> 12 | I63: 12 | J63: 2 | K63: =VLOOKUP(J63, Subject!$A$2:$B$15, 2, FALSE) -> Language | L63: =VLOOKUP(J63, Subject!$A$2:$E$11, 5, FALSE) -> LA | N63: EN | O63: 1 | P63: =VLOOKUP(O63, SubjectGroup!$A$2:$B$8, 2, FALSE) -> Christian Studies | Q63: Core | R63: =C63 -> English I | S63: 0.8
A64: 63 | C64: French I | E64: 9 | F64: 97 | G64: 108 | H64: =G64-F64+1 -> 12 | I64: 12 | J64: 2 | K64: =VLOOKUP(J64, Subject!$A$2:$B$15, 2, FALSE) -> Language | L64: =VLOOKUP(J64, Subject!$A$2:$E$11, 5, FALSE) -> LA | N64: FR | O64: 1 | P64: =VLOOKUP(O64, SubjectGroup!$A$2:$B$8, 2, FALSE) -> Christian Studies | Q64: Further Credit Option | R64: =C64 -> French I | S64: 0.8
A65: 64 | C65: Rosetta Stone Level 9 | E65: 9 | F65: 1 | G65: 2 | H65: =G65-F65+1 -> 2 | J65: 2 | K65: =VLOOKUP(J65, Subject!$A$2:$B$15, 2, FALSE) -> Language | L65: =VLOOKUP(J65, Subject!$A$2:$E$11, 5, FALSE) -> LA | M65: Extended Levels only | N65: RS | O65: 1 | P65: =VLOOKUP(O65, SubjectGroup!$A$2:$B$8, 2, FALSE) -> Christian Studies | Q65: Further Credit Option | R65: =C65 -> Rosetta Stone Level 9 | S65: 0.8
A66: 65 | C66: Spanish I | E66: 9 | F66: 1 | G66: 12 | H66: =G66-F66+1 -> 12 | I66: 12 | J66: 2 | K66: =VLOOKUP(J66, Subject!$A$2:$B$15, 2, FALSE) -> Language | L66: =VLOOKUP(J66, Subject!$A$2:$E$11, 5, FALSE) -> LA | N66: ES | O66: 1 | P66: =VLOOKUP(O66, SubjectGroup!$A$2:$B$8, 2, FALSE) -> Christian Studies | Q66: Further Credit Option | R66: =C66 -> Spanish I | S66: 0.8
A67: 66 | C67: Advanced Art | E67: 9 | F67: 97 | G67: 108 | H67: =G67-F67+1 -> 12 | I67: 12 | J67: 10 | K67: =VLOOKUP(J67, Subject!$A$2:$B$15, 2, FALSE) -> Supplementary | L67: =VLOOKUP(J67, Subject!$A$2:$E$11, 5, FALSE) -> SU | N67: AA | O67: 2 | P67: =VLOOKUP(O67, SubjectGroup!$A$2:$B$8, 2, FALSE) -> Core Academic Studies | Q67: Further Credit Option | R67: =C67 -> Advanced Art | S67: 0.8
A68: 67 | C68: Complete Art | E68: 9 | F68: 1 | G68: 10 | H68: =G68-F68+1 -> 10 | J68: 10 | K68: =VLOOKUP(J68, Subject!$A$2:$B$15, 2, FALSE) -> Supplementary | L68: =VLOOKUP(J68, Subject!$A$2:$E$11, 5, FALSE) -> SU | N68: CA | O68: 2 | P68: =VLOOKUP(O68, SubjectGroup!$A$2:$B$8, 2, FALSE) -> Core Academic Studies | Q68: Further Credit Option | R68: =C68 -> Complete Art | S68: 0.8
A69: 68 | C69: Etymology | E69: 9 | F69: 97 | G69: 108 | H69: =G69-F69+1 -> 12 | I69: 12 | J69: 3 | K69: =VLOOKUP(J69, Subject!$A$2:$B$15, 2, FALSE) -> Word Building | L69: =VLOOKUP(J69, Subject!$A$2:$E$11, 5, FALSE) -> WB | N69: ET | O69: 1 | P69: =VLOOKUP(O69, SubjectGroup!$A$2:$B$8, 2, FALSE) -> Christian Studies | Q69: Core | R69: Word Building Level 9 | S69: 0.9
A70: 69 | C70: Music | E70: 9 | F70: 1 | G70: 6 | H70: =G70-F70+1 -> 6 | J70: 10 | K70: =VLOOKUP(J70, Subject!$A$2:$B$15, 2, FALSE) -> Supplementary | L70: =VLOOKUP(J70, Subject!$A$2:$E$11, 5, FALSE) -> SU | N70: MU | O70: 3 | P70: =VLOOKUP(O70, SubjectGroup!$A$2:$B$8, 2, FALSE) -> Core Expanded Studies | Q70: Further Credit Option | R70: =C70 -> Music | S70: 0.8
A71: 70 | C71: Music Theory/Performance Grade 5 | E71: 9 | F71: 5 | G71: 6 | H71: =G71-F71+1 -> 2 | I71: 12 | J71: 10 | K71: =VLOOKUP(J71, Subject!$A$2:$B$15, 2, FALSE) -> Supplementary | L71: =VLOOKUP(J71, Subject!$A$2:$E$11, 5, FALSE) -> SU | N71: MT | O71: 3 | P71: =VLOOKUP(O71, SubjectGroup!$A$2:$B$8, 2, FALSE) -> Core Expanded Studies | Q71: Further Credit Option | R71: =C71 -> Music Theory/Performance Grade 5 | S71: 0.8
A72: 71 | C72: Music Theory/Performance | E72: 9 | F72: 5 | G72: 6 | H72: =G72-F72+1 -> 2 | I72: 12 | J72: 10 | K72: =VLOOKUP(J72, Subject!$A$2:$B$15, 2, FALSE) -> Supplementary | L72: =VLOOKUP(J72, Subject!$A$2:$E$11, 5, FALSE) -> SU | M72: Is duplicate of 70? Or perhaps the other one is theory and this one is performance | N72: MT | O72: 3 | P72: =VLOOKUP(O72, SubjectGroup!$A$2:$B$8, 2, FALSE) -> Core Expanded Studies | Q72: Further Credit Option | R72: =C72 -> Music Theory/Performance | S72: 0.8
A73: 72 | C73: Speech | E73: 9 | F73: 1 | G73: 6 | H73: =G73-F73+1 -> 6 | J73: 3 | K73: =VLOOKUP(J73, Subject!$A$2:$B$15, 2, FALSE) -> Word Building | L73: =VLOOKUP(J73, Subject!$A$2:$E$11, 5, FALSE) -> WB | N73: SP | O73: 3 | P73: =VLOOKUP(O73, SubjectGroup!$A$2:$B$8, 2, FALSE) -> Core Expanded Studies | Q73: Core | R73: =C73 -> Speech | S73: 0.8
A74: 73 | C74: ICCE Literature Level 9 | E74: 9 | F74: 1 | G74: 4 | H74: =G74-F74+1 -> 4 | I74: 6 | J74: 4 | K74: =VLOOKUP(J74, Subject!$A$2:$B$15, 2, FALSE) -> Literature | L74: =VLOOKUP(J74, Subject!$A$2:$E$11, 5, FALSE) -> LI | N74: I9 | O74: 2 | P74: =VLOOKUP(O74, SubjectGroup!$A$2:$B$8, 2, FALSE) -> Core Academic Studies | Q74: Core | R74: =C74 -> ICCE Literature Level 9 | S74: 0.8
...

Sheet PaceCourse
A1: ID | B1: PaceID | C1: CourseID | D1: Alias__ | E1: Number__ | F1: Code__ | G1: CreditValuePace | H1: PassThreshold__ | I1: Active | J1: Remark
A2: 1 | B2: 1 | C2: 1 | D2: =VLOOKUP(C2,Course!$A$1:$C$229, 2, FALSE) -> 0 | E2: 2 | F2: MA02RR03PT | G2: 1 | H2: 0.8 | I2: 1
A3: 2 | B3: 2 | C3: 1 | D3: =VLOOKUP(C3,Course!$A$1:$C$229, 2, FALSE) -> 0 | E3: 3 | F3: MA03RR03PT | G3: 1 | H3: 0.8 | I3: 1
A4: 3 | B4: 3 | C4: 1 | D4: =VLOOKUP(C4,Course!$A$1:$C$229, 2, FALSE) -> 0 | E4: 4 | F4: MA04RR03PT | G4: 1 | H4: 0.8 | I4: 1
A5: 4 | B5: 4 | C5: 1 | D5: =VLOOKUP(C5,Course!$A$1:$C$229, 2, FALSE) -> 0 | E5: 5 | F5: MA05RR03PT | G5: 1 | H5: 0.8 | I5: 1
A6: 5 | B6: 5 | C6: 1 | D6: =VLOOKUP(C6,Course!$A$1:$C$229, 2, FALSE) -> 0 | E6: 6 | F6: MA06RR03PT | G6: 1 | H6: 0.8 | I6: 1
A7: 6 | B7: 6 | C7: 1 | D7: =VLOOKUP(C7,Course!$A$1:$C$229, 2, FALSE) -> 0 | E7: 7 | F7: MA07RR03PT | G7: 1 | H7: 0.8 | I7: 1
A8: 7 | B8: 7 | C8: 1 | D8: =VLOOKUP(C8,Course!$A$1:$C$229, 2, FALSE) -> 0 | E8: 8 | F8: MA08RR03PT | G8: 1 | H8: 0.8 | I8: 1
A9: 8 | B9: 8 | C9: 1 | D9: =VLOOKUP(C9,Course!$A$1:$C$229, 2, FALSE) -> 0 | E9: 9 | F9: MA09RR03PT | G9: 1 | H9: 0.8 | I9: 1
A10: 9 | B10: 9 | C10: 1 | D10: =VLOOKUP(C10,Course!$A$1:$C$229, 2, FALSE) -> 0 | E10: 10 | F10: MA10RR03PT | G10: 1 | H10: 0.8 | I10: 1
A11: 10 | B11: 10 | C11: 1 | D11: =VLOOKUP(C11,Course!$A$1:$C$229, 2, FALSE) -> 0 | E11: 11 | F11: MA11RR03PT | G11: 1 | H11: 0.8 | I11: 1
A12: 11 | B12: 11 | C12: 1 | D12: =VLOOKUP(C12,Course!$A$1:$C$229, 2, FALSE) -> 0 | E12: 12 | F12: MA12RR03PT | G12: 1 | H12: 0.8 | I12: 1
A13: 12 | B13: 12 | C13: 2 | D13: =VLOOKUP(C13,Course!$A$1:$C$229, 2, FALSE) -> 0 | E13: 1 | F13: MA01MA03PT | G13: 1 | H13: 0.8 | I13: 1
... A564: 563 | B564: 563 | C564: 47 | D564: =VLOOKUP(C564,Course!$A$1:$C$229, 2, FALSE) -> 0 | E564: 84 | F564: WB84WB03PT | G564: 1 | H564: 0.9 | I564: 1
A565: 564 | B565: 564 | C565: 48 | D565: =VLOOKUP(C565,Course!$A$1:$C$229, 2, FALSE) -> 0 | E565: 74 | F565: LI74LC03PT | G565: =1/6/2 -> 0.083333333 | H565: 0.8 | I565: 1
A566: 566 | B566: 566 | C566: 48 | D566: =VLOOKUP(C566,Course!$A$1:$C$229, 2, FALSE) -> 0 | E566: 76 | F566: LI76LC03PT | G566: =1/6/2 -> 0.083333333 | H566: 0.8 | I566: 1
A567: 568 | B567: 568 | C567: 48 | D567: =VLOOKUP(C567,Course!$A$1:$C$229, 2, FALSE) -> 0 | E567: 78 | F567: LI78LC03PT | G567: =1/6/2 -> 0.083333333 | H567: 0.8 | I567: 1
A568: 570 | B568: 570 | C568: 48 | D568: =VLOOKUP(C568,Course!$A$1:$C$229, 2, FALSE) -> 0 | E568: 80 | F568: LI80LC03PT | G568: =1/6/2 -> 0.083333333 | H568: 0.8 | I568: 1
A569: 572 | B569: 572 | C569: 48 | D569: =VLOOKUP(C569,Course!$A$1:$C$229, 2, FALSE) -> 0 | E569: 82 | F569: LI82LC03PT | G569: =1/6/2 -> 0.083333333 | H569: 0.8 | I569: 1
A570: 574 | B570: 574 | C570: 48 | D570: =VLOOKUP(C570,Course!$A$1:$C$229, 2, FALSE) -> 0 | E570: 84 | F570: LI84LC03PT | G570: =1/6/2 -> 0.083333333 | H570: 0.8 | I570: 1
A571: 575 | B571: 575 | C571: 49 | D571: =VLOOKUP(C571,Course!$A$1:$C$229, 2, FALSE) -> 0 | E571: 73 | F571: SC73SC03PT | G571: 1 | H571: 0.8 | I571: 1
A572: 576 | B572: 576 | C572: 49 | D572: =VLOOKUP(C572,Course!$A$1:$C$229, 2, FALSE) -> 0 | E572: 74 | F572: SC74SC03PT | G572: 1 | H572: 0.8 | I572: 1
A573: 577 | B573: 577 | C573: 49 | D573: =VLOOKUP(C573,Course!$A$1:$C$229, 2, FALSE) -> 0 | E573: 75 | F573: SC75SC03PT | G573: 1 | H573: 0.8 | I573: 1
A574: 578 | B574: 578 | C574: 49 | D574: =VLOOKUP(C574,Course!$A$1:$C$229, 2, FALSE) -> 0 | E574: 76 | F574: SC76SC03PT | G574: 1 | H574: 0.8 | I574: 1
A575: 579 | B575: 579 | C575: 49 | D575: =VLOOKUP(C575,Course!$A$1:$C$229, 2, FALSE) -> 0 | E575: 77 | F575: SC77SC03PT | G575: 1 | H575: 0.8 | I575: 1
A576: 580 | B576: 580 | C576: 49 | D576: =VLOOKUP(C576,Course!$A$1:$C$229, 2, FALSE) -> 0 | E576: 78 | F576: SC78SC03PT | G576: 1 | H576: 0.8 | I576: 1
A577: 581 | B577: 581 | C577: 49 | D577: =VLOOKUP(C577,Course!$A$1:$C$229, 2, FALSE) -> 0 | E577: 79 | F577: SC79SC03PT | G577: 1 | H577: 0.8 | I577: 1
A578: 582 | B578: 582 | C578: 49 | D578: =VLOOKUP(C578,Course!$A$1:$C$229, 2, FALSE) -> 0 | E578: 80 | F578: SC80SC03PT | G578: 1 | H578: 0.8 | I578: 1
A579: 583 | B579: 583 | C579: 49 | D579: =VLOOKUP(C579,Course!$A$1:$C$229, 2, FALSE) -> 0 | E579: 81 | F579: SC81SC03PT | G579: 1 | H579: 0.8 | I579: 1
A580: 584 | B580: 584 | C580: 49 | D580: =VLOOKUP(C580,Course!$A$1:$C$229, 2, FALSE) -> 0 | E580: 82 | F580: SC82SC03PT | G580: 1 | H580: 0.8 | I580: 1
A581: 585 | B581: 585 | C581: 49 | D581: =VLOOKUP(C581,Course!$A$1:$C$229, 2, FALSE) -> 0 | E581: 83 | F581: SC83SC03PT | G581: 1 | H581: 0.8 | I581: 1
A582: 586 | B582: 586 | C582: 49 | D582: =VLOOKUP(C582,Course!$A$1:$C$229, 2, FALSE) -> 0 | E582: 84 | F582: SC84SC03PT | G582: 1 | H582: 0.8 | I582: 1
