Workbook

Sheet TODO
A1: ID | B1: Requirement | C1: Opmerking | D1: Status
A2: 1 | B2: Automatisch rijen verbergen die niet nodig zijn. | D2: Not Done
A3: 2 | B3: In "PACEs" de PACE-nummers valideren, voorwaardelijk aan de Course. | D3: Not Done
A4: 3 | B4: Wat zijn de requirements v.w.b. de kleur van de ster? | D4: Done
A5: 4 | B5: In "SPC" Scores automatisch invullen a.d.h.v. PACEs-tab | D5: Done
B6: In "PACEs" term automatisch invullen a.d.h.v. datum. | D6: Done
A7: 5 | B7: Nieuwe datumtabel aanmaken | D7: Done
A8: 6 | B8: Mogelijkheid om te filteren op schooljaar en term | D8: Not Done
A9: 7 | B9: Dynamisch maken voor elke student | D9: Not Done
A10: 8 | B10: Meerdere enrolments (van meerdere termen) mogelijk maken? | D10: Not Done
A11: 9 | B11: Term Report automatiseren
A12: 10 | B12: Namen van ICCE overal in verwerken | C12: Naam van Algebra I is "Mathematics-IA"? Is fout denk ik.

Sheet 2025-2026
K1: Term Report | AE1: 2025 - 2026
K3: ICS De Ceder - Boskoop | AE3: Term 1
A5: Student: | G5: Nathan Yong | V5: Report date: | AB5: 29 October 2025
A6: Group: | G6: Seniors | V6: Supervisor: | AB6: Mr S. Bezemer
K8: Term 1 | P8: Term 2 | U8: Term 3 | Z8: Term 4 | AE8: Term 5 | AJ8: Year to date
A9: Academic Studies
A10: New Testament Survey | K10: 0.99 | O10: 1 | AJ10: =((K10*O10)+(P10*T10)+(U10*Y10)+(Z10*AD10)+(AE10*AI10))/AN10 -> 0.99 | AN10: =SUM(O10,T10,Y10,AD10,AI10) -> 1
A12: General Mathematics | K12: 0.975 | O12: 1 | AJ12: =((K12*O12)+(P12*T12)+(U12*Y12)+(Z12*AD12)+(AE12*AI12))/AN12 -> 0.975 | AN12: =SUM(O12,T12,Y12,AD12,AI12) -> 1
A13: General English | K13: 1 | O13: 2 | AJ13: =((K13*O13)+(P13*T13)+(U13*Y13)+(Z13*AD13)+(AE13*AI13))/AN13 -> 1 | AN13: =SUM(O13,T13,Y13,AD13,AI13) -> 2
A14: Word Building 8 | K14: 0.9975 | O14: 2 | AJ14: =((K14*O14)+(P14*T14)+(U14*Y14)+(Z14*AD14)+(AE14*AI14))/AN14 -> 0.9975 | AN14: =SUM(O14,T14,Y14,AD14,AI14) -> 2
A15: Literature 8
A16: Earth Science | K16: 0.975 | O16: 1 | AJ16: =((K16*O16)+(P16*T16)+(U16*Y16)+(Z16*AD16)+(AE16*AI16))/AN16 -> 0.975 | AN16: =SUM(O16,T16,Y16,AD16,AI16) -> 1
A17: Biology | K17: 1 | O17: 1 | AJ17: =((K17*O17)+(P17*T17)+(U17*Y17)+(Z17*AD17)+(AE17*AI17))/AN17 -> 1 | AN17: =SUM(O17,T17,Y17,AD17,AI17) -> 1
A18: Physical Science | K18: 1 | O18: 2 | AJ18: =((K18*O18)+(P18*T18)+(U18*Y18)+(Z18*AD18)+(AE18*AI18))/AN18 -> 1 | AN18: =SUM(O18,T18,Y18,AD18,AI18) -> 2
A19: American History | K19: 1 | O19: 1 | AJ19: =((K19*O19)+(P19*T19)+(U19*Y19)+(Z19*AD19)+(AE19*AI19))/AN19 -> 1 | AN19: =SUM(O19,T19,Y19,AD19,AI19) -> 1
A20: World Geography | K20: 0.98 | O20: 1 | AJ20: =((K20*O20)+(P20*T20)+(U20*Y20)+(Z20*AD20)+(AE20*AI20))/AN20 -> 0.98 | AN20: =SUM(O20,T20,Y20,AD20,AI20) -> 1
A21: CS Digital Savvy | K21: 1 | O21: 1 | AJ21: =((K21*O21)+(P21*T21)+(U21*Y21)+(Z21*AD21)+(AE21*AI21))/AN21 -> 1 | AN21: =SUM(O21,T21,Y21,AD21,AI21) -> 1
A23: average / total | K23: =((K10*O10)+(K12*O12)+(K13*O13)+(K14*O14)+(K15*O15)+(K16*O16)+(K17*O17)+(K18*O18)+(K19*O19)+(K20*O20)+(K21*O21))/SUM(O10:O21) -> 0.99346154 | O23: =SUM(O10:O21) -> 13 | AJ23: =((AJ10*AN10)+(AJ12*AN12)+(AJ13*AN13)+(AJ14*AN14)+(AJ15*AN15)+(AJ16*AN16)+(AJ17*AN17)+(AJ18*AN18)+(AJ19*AN19)+(AJ20*AN20)+(AJ21*AN21))/SUM(AN10:AN21) -> 0.99346154 | AN23: =SUM(AN10:AN21) -> 13
A25: Nederlands
A26: Taal | AJ26: =SUM(K26:AI26)/COUNT(K26:AI26) -> #DIV/0!
A28: Supplementary activities
A29: Music | K29: G | AJ29: G
A30: Gardening | K30: G | AJ30: G
A31: Physical Education | K31: G | AJ31: G
A33: Attendance
A34: Score | K34: 0.82 | AJ34: =SUM(K34:AI34)/COUNT(K34:AI34) -> 0.82
A36: In relation to work | J36: T1 | L36: T2 | N36: T3 | P36: T4 | R36: T5 | V36: In relation to others | AE36: T1 | AG36: T2 | AI36: T3 | AK36: T4 | AM36: T5
A37: Is committed | J37: E | V37: Is cooperative | AE37: E
A38: Ability to establish own goals | J38: E | V38: Follows directions | AE38: G
A39: Works independently | J39: E | V39: Is courteous and respectful | AE39: G
A40: Completes work required | J40: E | V40: Responds well to correction | AE40: G
A41: Does work neatly | J41: G | V41: Exhibits self-control | AE41: G
A42: Does not disturb others | J42: G | V42: Gets along well with others | AE42: G
A43: Takes care of materials | J43: G | V43: Willing to serve | AE43: G
A45: principal: | O45: supervisor: | AC45: parent / guardian:

Sheet CourseContents
B1: CourseName | C1: Position | D1: PACEcode
B2: ICCE Physical Science | C2: 1 | D2: USMA09867
B3: USMA09 | C3: 1 | D3: USMA0986
B4: USMA09 | C4: 1 | D4: USMA09868

Sheet Enrolment
A1: ID | B1: CourseName_ACE | C1: 1 | D1: 2 | E1: 3 | F1: 4 | G1: 5 | H1: 6 | I1: 7 | J1: 8 | K1: 9 | L1: 10 | M1: 11 | N1: 12
A2: 1 | B2: General Maths | C2: 85 | D2: 86 | E2: 87 | F2: 88 | G2: 89 | H2: 90 | I2: 91 | J2: 92 | K2: 93 | L2: 94 | M2: 95 | N2: 96
A3: 2 | B3: General English | C3: 85 | D3: 86 | E3: 87 | F3: 88 | G3: 89 | H3: 90 | I3: 91 | J3: 92 | K3: 93 | L3: 94 | M3: 95 | N3: 96
A4: 3 | B4: Word Building Level 8 | C4: 85 | D4: 86 | E4: 87 | F4: 88 | G4: 89 | H4: 90 | I4: 91 | J4: 92 | K4: 93 | L4: 94 | M4: 95 | N4: 96
A5: 4 | B5: Earth Science | C5: 85 | D5: 86 | E5: 87 | F5: 88 | G5: 89 | H5: 90 | I5: 91 | J5: 92 | K5: 93 | L5: 94 | M5: 95 | N5: 96
A6: 5 | B6: ICCE Physical Science | C6: 85 | D6: 86 | E6: 86 | F6: 87 | G6: 88 | H6: 88 | I6: 97 | J6: 98 | K6: 98 | L6: 99 | M6: 100 | N6: 100
A7: 6 | B7: American History | C7: 85 | D7: 86 | E7: 87 | F7: 88 | G7: 89 | H7: 90 | I7: 91 | J7: 92 | K7: 93 | L7: 94 | M7: 95 | N7: 96
A8: 7 | B8: New Testament Survey | C8: 97 | D8: 98 | E8: 99 | F8: 100 | G8: 101 | H8: 102 | I8: 103 | J8: 104 | K8: 105 | L8: 106 | M8: 107 | N8: 108
A9: 8 | B9: Algebra I | C9: 97 | D9: 98 | E9: 99 | F9: 100 | G9: 101 | H9: 102 | I9: 103 | J9: 104 | K9: 105 | L9: 106 | M9: 107 | N9: 108
A10: 9 | B10: English I | C10: 97 | D10: 98 | E10: 99 | F10: 100 | G10: 101 | H10: 102 | I10: 103 | J10: 104 | K10: 105 | L10: 106 | M10: 107 | N10: 108
A11: 10 | B11: Word Building / Etymology | C11: 97 | D11: 98 | E11: 99 | F11: 100 | G11: 101 | H11: 102 | I11: 103 | J11: 104 | K11: 105 | L11: 106 | M11: 107 | N11: 108
A12: 11 | B12: Biology / Science Level 9 | C12: 97 | D12: 98 | E12: 99 | F12: 100 | G12: 101 | H12: 102 | I12: 103 | J12: 104 | K12: 105 | L12: 106 | M12: 107 | N12: 108
A13: 12 | B13: World Geography | C13: 97 | D13: 98 | E13: 99 | F13: 100 | G13: 101 | H13: 102 | I13: 103 | J13: 104 | K13: 105 | L13: 106 | M13: 107 | N13: 108
A14: 13 | B14: Music | C14: 1 | D14: 2 | E14: 3 | F14: 4 | G14: 5 | H14: 6
A15: 14 | B15: Astronomy | C15: 1 | D15: 2 | E15: 3 | F15: 4 | G15: 5 | H15: 5
A16: 15 | B16: Digital Savvy | C16: 15–17 | D16: 18–19

Sheet SPC
A1: CourseName_ACE | B1: 1 | C1: 2 | D1: 3 | E1: 4 | F1: 5 | G1: 6 | H1: 7 | I1: 8 | J1: 9 | K1: 10 | L1: 11 | M1: 12
A2: General Maths | B2: =IF(VLOOKUP($A2,Course!$B$2:$C$165, 2, FALSE)=0, VLOOKUP($A2,Course!$B$2:$C$165, 1, FALSE), VLOOKUP($A2,Course!$B$2:$C$165, 2, FALSE)) -> General Maths | G2: =A2 -> General Maths | L2: =IF(VLOOKUP($A2, Course!$B$2:$E$165, 3, FALSE)=0, "", VLOOKUP($A2, Course!$B$2:$E$165, 3, FALSE)) -> General Maths | O2: Grade | Q2: Date | R2: 45925
B3: =VLOOKUP($A2,Enrolment!$B$2:$N$15, B$1+1, FALSE) -> 85 | C3: =VLOOKUP($A2,Enrolment!$B$2:$N$15, C$1+1, FALSE) -> 86 | D3: =VLOOKUP($A2,Enrolment!$B$2:$N$15, D$1+1, FALSE) -> 87 | E3: =VLOOKUP($A2,Enrolment!$B$2:$N$15, E$1+1, FALSE) -> 88 | F3: =VLOOKUP($A2,Enrolment!$B$2:$N$15, F$1+1, FALSE) -> 89 | G3: =VLOOKUP($A2,Enrolment!$B$2:$N$15, G$1+1, FALSE) -> 90 | H3: =VLOOKUP($A2,Enrolment!$B$2:$N$15, H$1+1, FALSE) -> 91 | I3: =VLOOKUP($A2,Enrolment!$B$2:$N$15, I$1+1, FALSE) -> 92 | ... M3: =VLOOKUP($A2,Enrolment!$B$2:$N$15, M$1+1, FALSE) -> 96
B4: « | C4: « | D4: « | E4: « | F4: « | G4: « | H4: « | I4: « | J4: « | K4: « | L4: « | M4: «
B5: {=IFERROR(_xlfn.XLOOKUP(1, (PACEs!$C$2:$C$1000=$A2) * (PACEs!$D$2:$D$1000=B3), PACEs!$E$2:$E$1000), "")} | C5: {=IFERROR(_xlfn.XLOOKUP(1, (PACEs!$C$2:$C$1000=$A2) * (PACEs!$D$2:$D$1000=C3), PACEs!$E$2:$E$1000), "")} | D5: {=IFERROR(_xlfn.XLOOKUP(1, (PACEs!$C$2:$C$1000=$A2) * (PACEs!$D$2:$D$1000=D3), PACEs!$E$2:$E$1000), "")} | E5: {=IFERROR(_xlfn.XLOOKUP(1, (PACEs!$C$2:$C$1000=$A2) * (PACEs!$D$2:$D$1000=E3), PACEs!$E$2:$E$1000), "")} | F5: {=IFERROR(_xlfn.XLOOKUP(1, (PACEs!$C$2:$C$1000=$A2) * (PACEs!$D$2:$D$1000=F3), PACEs!$E$2:$E$1000), "")} | G5: {=IFERROR(_xlfn.XLOOKUP(1, (PACEs!$C$2:$C$1000=$A2) * (PACEs!$D$2:$D$1000=G3), PACEs!$E$2:$E$1000), "")} | H5: {=IFERROR(_xlfn.XLOOKUP(1, (PACEs!$C$2:$C$1000=$A2) * (PACEs!$D$2:$D$1000=H3), PACEs!$E$2:$E$1000), "")} | I5: {=IFERROR(_xlfn.XLOOKUP(1, (PACEs!$C$2:$C$1000=$A2) * (PACEs!$D$2:$D$1000=I3), PACEs!$E$2:$E$1000), "")} | ... M5: {=IFERROR(_xlfn.XLOOKUP(1, (PACEs!$C$2:$C$1000=$A2) * (PACEs!$D$2:$D$1000=M3), PACEs!$E$2:$E$1000), "")} -> 0.975 | O5: =AVERAGE(B5:M5) -> 0.975
B6: {=IF(ISERROR(_xlfn.XLOOKUP(1,(PACEs!$C$2:$C$1000=$A2)*(PACEs!$D$2:$D$1000=B3),PACEs!$F$2:$F$1000)),"",VLOOKUP(_xlfn.XLOOKUP(1,(PACEs!$C$2:$C$1000=$A2)*(PACEs!$D$2:$D$1000=B3),PACEs!$F$2:$F$1000),Date!$B$2:$K$1623,10,FALSE)&".T"&VLOOKUP(_xlfn.XLOOKUP(1,(PACEs!$C$2:$C$1000=$A2)*(PACEs!$D$2:$D$1000=B3),PACEs!$F$2:$F$1000),Date!$B$2:$K$1623,7,FALSE))} | C6: {=IF(ISERROR(_xlfn.XLOOKUP(1,(PACEs!$C$2:$C$1000=$A2)*(PACEs!$D$2:$D$1000=C3),PACEs!$F$2:$F$1000)),"",VLOOKUP(_xlfn.XLOOKUP(1,(PACEs!$C$2:$C$1000=$A2)*(PACEs!$D$2:$D$1000=C3),PACEs!$F$2:$F$1000),Date!$B$2:$K$1623,10,FALSE)&".T"&VLOOKUP(_xlfn.XLOOKUP(1,(PACEs!$C$2:$C$1000=$A2)*(PACEs!$D$2:$D$1000=C3),PACEs!$F$2:$F$1000),Date!$B$2:$K$1623,7,FALSE))} | D6: {=IF(ISERROR(_xlfn.XLOOKUP(1,(PACEs!$C$2:$C$1000=$A2)*(PACEs!$D$2:$D$1000=D3),PACEs!$F$2:$F$1000)),"",VLOOKUP(_xlfn.XLOOKUP(1,(PACEs!$C$2:$C$1000=$A2)*(PACEs!$D$2:$D$1000=D3),PACEs!$F$2:$F$1000),Date!$B$2:$K$1623,10,FALSE)&".T"&VLOOKUP(_xlfn.XLOOKUP(1,(PACEs!$C$2:$C$1000=$A2)*(PACEs!$D$2:$D$1000=D3),PACEs!$F$2:$F$1000),Date!$B$2:$K$1623,7,FALSE))} | E6: {=IF(ISERROR(_xlfn.XLOOKUP(1,(PACEs!$C$2:$C$1000=$A2)*(PACEs!$D$2:$D$1000=E3),PACEs!$F$2:$F$1000)),"",VLOOKUP(_xlfn.XLOOKUP(1,(PACEs!$C$2:$C$1000=$A2)*(PACEs!$D$2:$D$1000=E3),PACEs!$F$2:$F$1000),Date!$B$2:$K$1623,10,FALSE)&".T"&VLOOKUP(_xlfn.XLOOKUP(1,(PACEs!$C$2:$C$1000=$A2)*(PACEs!$D$2:$D$1000=E3),PACEs!$F$2:$F$1000),Date!$B$2:$K$1623,7,FALSE))} | F6: {=IF(ISERROR(_xlfn.XLOOKUP(1,(PACEs!$C$2:$C$1000=$A2)*(PACEs!$D$2:$D$1000=F3),PACEs!$F$2:$F$1000)),"",VLOOKUP(_xlfn.XLOOKUP(1,(PACEs!$C$2:$C$1000=$A2)*(PACEs!$D$2:$D$1000=F3),PACEs!$F$2:$F$1000),Date!$B$2:$K$1623,10,FALSE)&".T"&VLOOKUP(_xlfn.XLOOKUP(1,(PACEs!$C$2:$C$1000=$A2)*(PACEs!$D$2:$D$1000=F3),PACEs!$F$2:$F$1000),Date!$B$2:$K$1623,7,FALSE))} | G6: {=IF(ISERROR(_xlfn.XLOOKUP(1,(PACEs!$C$2:$C$1000=$A2)*(PACEs!$D$2:$D$1000=G3),PACEs!$F$2:$F$1000)),"",VLOOKUP(_xlfn.XLOOKUP(1,(PACEs!$C$2:$C$1000=$A2)*(PACEs!$D$2:$D$1000=G3),PACEs!$F$2:$F$1000),Date!$B$2:$K$1623,10,FALSE)&".T"&VLOOKUP(_xlfn.XLOOKUP(1,(PACEs!$C$2:$C$1000=$A2)*(PACEs!$D$2:$D$1000=G3),PACEs!$F$2:$F$1000),Date!$B$2:$K$1623,7,FALSE))} | H6: {=IF(ISERROR(_xlfn.XLOOKUP(1,(PACEs!$C$2:$C$1000=$A2)*(PACEs!$D$2:$D$1000=H3),PACEs!$F$2:$F$1000)),"",VLOOKUP(_xlfn.XLOOKUP(1,(PACEs!$C$2:$C$1000=$A2)*(PACEs!$D$2:$D$1000=H3),PACEs!$F$2:$F$1000),Date!$B$2:$K$1623,10,FALSE)&".T"&VLOOKUP(_xlfn.XLOOKUP(1,(PACEs!$C$2:$C$1000=$A2)*(PACEs!$D$2:$D$1000=H3),PACEs!$F$2:$F$1000),Date!$B$2:$K$1623,7,FALSE))} | I6: {=IF(ISERROR(_xlfn.XLOOKUP(1,(PACEs!$C$2:$C$1000=$A2)*(PACEs!$D$2:$D$1000=I3),PACEs!$F$2:$F$1000)),"",VLOOKUP(_xlfn.XLOOKUP(1,(PACEs!$C$2:$C$1000=$A2)*(PACEs!$D$2:$D$1000=I3),PACEs!$F$2:$F$1000),Date!$B$2:$K$1623,10,FALSE)&".T"&VLOOKUP(_xlfn.XLOOKUP(1,(PACEs!$C$2:$C$1000=$A2)*(PACEs!$D$2:$D$1000=I3),PACEs!$F$2:$F$1000),Date!$B$2:$K$1623,7,FALSE))} | ... M6: {=IF(ISERROR(_xlfn.XLOOKUP(1,(PACEs!$C$2:$C$1000=$A2)*(PACEs!$D$2:$D$1000=M3),PACEs!$F$2:$F$1000)),"",VLOOKUP(_xlfn.XLOOKUP(1,(PACEs!$C$2:$C$1000=$A2)*(PACEs!$D$2:$D$1000=M3),PACEs!$F$2:$F$1000),Date!$B$2:$K$1623,10,FALSE)&".T"&VLOOKUP(_xlfn.XLOOKUP(1,(PACEs!$C$2:$C$1000=$A2)*(PACEs!$D$2:$D$1000=M3),PACEs!$F$2:$F$1000),Date!$B$2:$K$1623,7,FALSE))} -> 25–26.T1 | Q6: StudentID
A7: General English | B7: =IF(VLOOKUP($A7,Course!$B$2:$C$165, 2, FALSE)=0, VLOOKUP($A7,Course!$B$2:$C$165, 1, FALSE), VLOOKUP($A7,Course!$B$2:$C$165, 2, FALSE)) -> General English | G7: =A7 -> General English | L7: =IF(VLOOKUP($A7, Course!$B$2:$E$165, 3, FALSE)=0, "", VLOOKUP($A7, Course!$B$2:$E$165, 3, FALSE)) -> General English | Q7: USMA09 | R7: 1 | S7: 2 | T7: 3 | U7: 4 | V7: 5 | W7: 6 | X7: 7 | Y7: 8 | Z7: 9 | AA7: 10 | AB7: 11 | AC7: 12
B8: =VLOOKUP($A7,Enrolment!$B$2:$N$15, B$1+1, FALSE) -> 85 | C8: =VLOOKUP($A7,Enrolment!$B$2:$N$15, C$1+1, FALSE) -> 86 | D8: =VLOOKUP($A7,Enrolment!$B$2:$N$15, D$1+1, FALSE) -> 87 | E8: =VLOOKUP($A7,Enrolment!$B$2:$N$15, E$1+1, FALSE) -> 88 | F8: =VLOOKUP($A7,Enrolment!$B$2:$N$15, F$1+1, FALSE) -> 89 | G8: =VLOOKUP($A7,Enrolment!$B$2:$N$15, G$1+1, FALSE) -> 90 | H8: =VLOOKUP($A7,Enrolment!$B$2:$N$15, H$1+1, FALSE) -> 91 | I8: =VLOOKUP($A7,Enrolment!$B$2:$N$15, I$1+1, FALSE) -> 92 | ... M8: =VLOOKUP($A7,Enrolment!$B$2:$N$15, M$1+1, FALSE) -> 96 | R8: New Testament Church History
B9: « | C9: « | D9: « | E9: « | F9: « | G9: « | H9: « | I9: « | J9: « | K9: « | L9: « | M9: « | Q9: PACE | R9: =VLOOKUP($Q7, Enrolment!$B$2:$N$11, R7 + 1, FALSE) -> #N/A | S9: =VLOOKUP($Q7, Enrolment!$B$2:$N$11, S7 + 1, FALSE) -> #N/A
B10: {=IFERROR(_xlfn.XLOOKUP(1, (PACEs!$C$2:$C$1000=$A7) * (PACEs!$D$2:$D$1000=B8), PACEs!$E$2:$E$1000), "")} | C10: {=IFERROR(_xlfn.XLOOKUP(1, (PACEs!$C$2:$C$1000=$A7) * (PACEs!$D$2:$D$1000=C8), PACEs!$E$2:$E$1000), "")} | D10: {=IFERROR(_xlfn.XLOOKUP(1, (PACEs!$C$2:$C$1000=$A7) * (PACEs!$D$2:$D$1000=D8), PACEs!$E$2:$E$1000), "")} | E10: {=IFERROR(_xlfn.XLOOKUP(1, (PACEs!$C$2:$C$1000=$A7) * (PACEs!$D$2:$D$1000=E8), PACEs!$E$2:$E$1000), "")} | F10: {=IFERROR(_xlfn.XLOOKUP(1, (PACEs!$C$2:$C$1000=$A7) * (PACEs!$D$2:$D$1000=F8), PACEs!$E$2:$E$1000), "")} | G10: {=IFERROR(_xlfn.XLOOKUP(1, (PACEs!$C$2:$C$1000=$A7) * (PACEs!$D$2:$D$1000=G8), PACEs!$E$2:$E$1000), "")} | H10: {=IFERROR(_xlfn.XLOOKUP(1, (PACEs!$C$2:$C$1000=$A7) * (PACEs!$D$2:$D$1000=H8), PACEs!$E$2:$E$1000), "")} | I10: {=IFERROR(_xlfn.XLOOKUP(1, (PACEs!$C$2:$C$1000=$A7) * (PACEs!$D$2:$D$1000=I8), PACEs!$E$2:$E$1000), "")} | ... M10: {=IFERROR(_xlfn.XLOOKUP(1, (PACEs!$C$2:$C$1000=$A7) * (PACEs!$D$2:$D$1000=M8), PACEs!$E$2:$E$1000), "")} -> 1 | O10: =AVERAGE(B10:M10) -> 1 | Q10: Stars | R10: 1 | S10: 2
B11: {=IF(ISERROR(_xlfn.XLOOKUP(1,(PACEs!$C$2:$C$1000=$A7)*(PACEs!$D$2:$D$1000=B8),PACEs!$F$2:$F$1000)),"",VLOOKUP(_xlfn.XLOOKUP(1,(PACEs!$C$2:$C$1000=$A7)*(PACEs!$D$2:$D$1000=B8),PACEs!$F$2:$F$1000),Date!$B$2:$K$1623,10,FALSE)&".T"&VLOOKUP(_xlfn.XLOOKUP(1,(PACEs!$C$2:$C$1000=$A7)*(PACEs!$D$2:$D$1000=B8),PACEs!$F$2:$F$1000),Date!$B$2:$K$1623,7,FALSE))} | C11: {=IF(ISERROR(_xlfn.XLOOKUP(1,(PACEs!$C$2:$C$1000=$A7)*(PACEs!$D$2:$D$1000=C8),PACEs!$F$2:$F$1000)),"",VLOOKUP(_xlfn.XLOOKUP(1,(PACEs!$C$2:$C$1000=$A7)*(PACEs!$D$2:$D$1000=C8),PACEs!$F$2:$F$1000),Date!$B$2:$K$1623,10,FALSE)&".T"&VLOOKUP(_xlfn.XLOOKUP(1,(PACEs!$C$2:$C$1000=$A7)*(PACEs!$D$2:$D$1000=C8),PACEs!$F$2:$F$1000),Date!$B$2:$K$1623,7,FALSE))} | D11: {=IF(ISERROR(_xlfn.XLOOKUP(1,(PACEs!$C$2:$C$1000=$A7)*(PACEs!$D$2:$D$1000=D8),PACEs!$F$2:$F$1000)),"",VLOOKUP(_xlfn.XLOOKUP(1,(PACEs!$C$2:$C$1000=$A7)*(PACEs!$D$2:$D$1000=D8),PACEs!$F$2:$F$1000),Date!$B$2:$K$1623,10,FALSE)&".T"&VLOOKUP(_xlfn.XLOOKUP(1,(PACEs!$C$2:$C$1000=$A7)*(PACEs!$D$2:$D$1000=D8),PACEs!$F$2:$F$1000),Date!$B$2:$K$1623,7,FALSE))} | E11: {=IF(ISERROR(_xlfn.XLOOKUP(1,(PACEs!$C$2:$C$1000=$A7)*(PACEs!$D$2:$D$1000=E8),PACEs!$F$2:$F$1000)),"",VLOOKUP(_xlfn.XLOOKUP(1,(PACEs!$C$2:$C$1000=$A7)*(PACEs!$D$2:$D$1000=E8),PACEs!$F$2:$F$1000),Date!$B$2:$K$1623,10,FALSE)&".T"&VLOOKUP(_xlfn.XLOOKUP(1,(PACEs!$C$2:$C$1000=$A7)*(PACEs!$D$2:$D$1000=E8),PACEs!$F$2:$F$1000),Date!$B$2:$K$1623,7,FALSE))} | F11: {=IF(ISERROR(_xlfn.XLOOKUP(1,(PACEs!$C$2:$C$1000=$A7)*(PACEs!$D$2:$D$1000=F8),PACEs!$F$2:$F$1000)),"",VLOOKUP(_xlfn.XLOOKUP(1,(PACEs!$C$2:$C$1000=$A7)*(PACEs!$D$2:$D$1000=F8),PACEs!$F$2:$F$1000),Date!$B$2:$K$1623,10,FALSE)&".T"&VLOOKUP(_xlfn.XLOOKUP(1,(PACEs!$C$2:$C$1000=$A7)*(PACEs!$D$2:$D$1000=F8),PACEs!$F$2:$F$1000),Date!$B$2:$K$1623,7,FALSE))} | G11: {=IF(ISERROR(_xlfn.XLOOKUP(1,(PACEs!$C$2:$C$1000=$A7)*(PACEs!$D$2:$D$1000=G8),PACEs!$F$2:$F$1000)),"",VLOOKUP(_xlfn.XLOOKUP(1,(PACEs!$C$2:$C$1000=$A7)*(PACEs!$D$2:$D$1000=G8),PACEs!$F$2:$F$1000),Date!$B$2:$K$1623,10,FALSE)&".T"&VLOOKUP(_xlfn.XLOOKUP(1,(PACEs!$C$2:$C$1000=$A7)*(PACEs!$D$2:$D$1000=G8),PACEs!$F$2:$F$1000),Date!$B$2:$K$1623,7,FALSE))} | H11: {=IF(ISERROR(_xlfn.XLOOKUP(1,(PACEs!$C$2:$C$1000=$A7)*(PACEs!$D$2:$D$1000=H8),PACEs!$F$2:$F$1000)),"",VLOOKUP(_xlfn.XLOOKUP(1,(PACEs!$C$2:$C$1000=$A7)*(PACEs!$D$2:$D$1000=H8),PACEs!$F$2:$F$1000),Date!$B$2:$K$1623,10,FALSE)&".T"&VLOOKUP(_xlfn.XLOOKUP(1,(PACEs!$C$2:$C$1000=$A7)*(PACEs!$D$2:$D$1000=H8),PACEs!$F$2:$F$1000),Date!$B$2:$K$1623,7,FALSE))} | I11: {=IF(ISERROR(_xlfn.XLOOKUP(1,(PACEs!$C$2:$C$1000=$A7)*(PACEs!$D$2:$D$1000=I8),PACEs!$F$2:$F$1000)),"",VLOOKUP(_xlfn.XLOOKUP(1,(PACEs!$C$2:$C$1000=$A7)*(PACEs!$D$2:$D$1000=I8),PACEs!$F$2:$F$1000),Date!$B$2:$K$1623,10,FALSE)&".T"&VLOOKUP(_xlfn.XLOOKUP(1,(PACEs!$C$2:$C$1000=$A7)*(PACEs!$D$2:$D$1000=I8),PACEs!$F$2:$F$1000),Date!$B$2:$K$1623,7,FALSE))} | ... M11: {=IF(ISERROR(_xlfn.XLOOKUP(1,(PACEs!$C$2:$C$1000=$A7)*(PACEs!$D$2:$D$1000=M8),PACEs!$F$2:$F$1000)),"",VLOOKUP(_xlfn.XLOOKUP(1,(PACEs!$C$2:$C$1000=$A7)*(PACEs!$D$2:$D$1000=M8),PACEs!$F$2:$F$1000),Date!$B$2:$K$1623,10,FALSE)&".T"&VLOOKUP(_xlfn.XLOOKUP(1,(PACEs!$C$2:$C$1000=$A7)*(PACEs!$D$2:$D$1000=M8),PACEs!$F$2:$F$1000),Date!$B$2:$K$1623,7,FALSE))} -> 25–26.T1 | Q11: dd/mm/yy
A12: Word Building Level 8 | B12: =IF(VLOOKUP($A12,Course!$B$2:$C$165, 2, FALSE)=0, VLOOKUP($A12,Course!$B$2:$C$165, 1, FALSE), VLOOKUP($A12,Course!$B$2:$C$165, 2, FALSE)) -> Word Building Level 8 | G12: =A12 -> Word Building Level 8 | L12: =IF(VLOOKUP($A12, Course!$B$2:$E$165, 3, FALSE)=0, "", VLOOKUP($A12, Course!$B$2:$E$165, 3, FALSE)) | Q12: score
B13: =VLOOKUP($A12,Enrolment!$B$2:$N$15, B$1+1, FALSE) -> 85 | C13: =VLOOKUP($A12,Enrolment!$B$2:$N$15, C$1+1, FALSE) -> 86 | D13: =VLOOKUP($A12,Enrolment!$B$2:$N$15, D$1+1, FALSE) -> 87 | E13: =VLOOKUP($A12,Enrolment!$B$2:$N$15, E$1+1, FALSE) -> 88 | F13: =VLOOKUP($A12,Enrolment!$B$2:$N$15, F$1+1, FALSE) -> 89 | G13: =VLOOKUP($A12,Enrolment!$B$2:$N$15, G$1+1, FALSE) -> 90 | H13: =VLOOKUP($A12,Enrolment!$B$2:$N$15, H$1+1, FALSE) -> 91 | I13: =VLOOKUP($A12,Enrolment!$B$2:$N$15, I$1+1, FALSE) -> 92 | ... M13: =VLOOKUP($A12,Enrolment!$B$2:$N$15, M$1+1, FALSE) -> 96
B14: « | C14: « | D14: « | E14: « | F14: « | G14: « | H14: « | I14: « | J14: « | K14: « | L14: « | M14: « | Q14: =COUNTIFS(PACEs!$C$2:$C$28,A2, PACEs!$D$2:$D$28,M3) -> 1
B15: {=IFERROR(_xlfn.XLOOKUP(1, (PACEs!$C$2:$C$1000=$A12) * (PACEs!$D$2:$D$1000=B13), PACEs!$E$2:$E$1000), "")} | C15: {=IFERROR(_xlfn.XLOOKUP(1, (PACEs!$C$2:$C$1000=$A12) * (PACEs!$D$2:$D$1000=C13), PACEs!$E$2:$E$1000), "")} | D15: {=IFERROR(_xlfn.XLOOKUP(1, (PACEs!$C$2:$C$1000=$A12) * (PACEs!$D$2:$D$1000=D13), PACEs!$E$2:$E$1000), "")} | E15: {=IFERROR(_xlfn.XLOOKUP(1, (PACEs!$C$2:$C$1000=$A12) * (PACEs!$D$2:$D$1000=E13), PACEs!$E$2:$E$1000), "")} | F15: {=IFERROR(_xlfn.XLOOKUP(1, (PACEs!$C$2:$C$1000=$A12) * (PACEs!$D$2:$D$1000=F13), PACEs!$E$2:$E$1000), "")} | G15: {=IFERROR(_xlfn.XLOOKUP(1, (PACEs!$C$2:$C$1000=$A12) * (PACEs!$D$2:$D$1000=G13), PACEs!$E$2:$E$1000), "")} | H15: {=IFERROR(_xlfn.XLOOKUP(1, (PACEs!$C$2:$C$1000=$A12) * (PACEs!$D$2:$D$1000=H13), PACEs!$E$2:$E$1000), "")} | I15: {=IFERROR(_xlfn.XLOOKUP(1, (PACEs!$C$2:$C$1000=$A12) * (PACEs!$D$2:$D$1000=I13), PACEs!$E$2:$E$1000), "")} | ... M15: {=IFERROR(_xlfn.XLOOKUP(1, (PACEs!$C$2:$C$1000=$A12) * (PACEs!$D$2:$D$1000=M13), PACEs!$E$2:$E$1000), "")} -> 1
B16: {=IF(ISERROR(_xlfn.XLOOKUP(1,(PACEs!$C$2:$C$1000=$A12)*(PACEs!$D$2:$D$1000=B13),PACEs!$F$2:$F$1000)),"",VLOOKUP(_xlfn.XLOOKUP(1,(PACEs!$C$2:$C$1000=$A12)*(PACEs!$D$2:$D$1000=B13),PACEs!$F$2:$F$1000),Date!$B$2:$K$1623,10,FALSE)&".T"&VLOOKUP(_xlfn.XLOOKUP(1,(PACEs!$C$2:$C$1000=$A12)*(PACEs!$D$2:$D$1000=B13),PACEs!$F$2:$F$1000),Date!$B$2:$K$1623,7,FALSE))} | C16: {=IF(ISERROR(_xlfn.XLOOKUP(1,(PACEs!$C$2:$C$1000=$A12)*(PACEs!$D$2:$D$1000=C13),PACEs!$F$2:$F$1000)),"",VLOOKUP(_xlfn.XLOOKUP(1,(PACEs!$C$2:$C$1000=$A12)*(PACEs!$D$2:$D$1000=C13),PACEs!$F$2:$F$1000),Date!$B$2:$K$1623,10,FALSE)&".T"&VLOOKUP(_xlfn.XLOOKUP(1,(PACEs!$C$2:$C$1000=$A12)*(PACEs!$D$2:$D$1000=C13),PACEs!$F$2:$F$1000),Date!$B$2:$K$1623,7,FALSE))} | D16: {=IF(ISERROR(_xlfn.XLOOKUP(1,(PACEs!$C$2:$C$1000=$A12)*(PACEs!$D$2:$D$1000=D13),PACEs!$F$2:$F$1000)),"",VLOOKUP(_xlfn.XLOOKUP(1,(PACEs!$C$2:$C$1000=$A12)*(PACEs!$D$2:$D$1000=D13),PACEs!$F$2:$F$1000),Date!$B$2:$K$1623,10,FALSE)&".T"&VLOOKUP(_xlfn.XLOOKUP(1,(PACEs!$C$2:$C$1000=$A12)*(PACEs!$D$2:$D$1000=D13),PACEs!$F$2:$F$1000),Date!$B$2:$K$1623,7,FALSE))} | E16: {=IF(ISERROR(_xlfn.XLOOKUP(1,(PACEs!$C$2:$C$1000=$A12)*(PACEs!$D$2:$D$1000=E13),PACEs!$F$2:$F$1000)),"",VLOOKUP(_xlfn.XLOOKUP(1,(PACEs!$C$2:$C$1000=$A12)*(PACEs!$D$2:$D$1000=E13),PACEs!$F$2:$F$1000),Date!$B$2:$K$1623,10,FALSE)&".T"&VLOOKUP(_xlfn.XLOOKUP(1,(PACEs!$C$2:$C$1000=$A12)*(PACEs!$D$2:$D$1000=E13),PACEs!$F$2:$F$1000),Date!$B$2:$K$1623,7,FALSE))} | F16: {=IF(ISERROR(_xlfn.XLOOKUP(1,(PACEs!$C$2:$C$1000=$A12)*(PACEs!$D$2:$D$1000=F13),PACEs!$F$2:$F$1000)),"",VLOOKUP(_xlfn.XLOOKUP(1,(PACEs!$C$2:$C$1000=$A12)*(PACEs!$D$2:$D$1000=F13),PACEs!$F$2:$F$1000),Date!$B$2:$K$1623,10,FALSE)&".T"&VLOOKUP(_xlfn.XLOOKUP(1,(PACEs!$C$2:$C$1000=$A12)*(PACEs!$D$2:$D$1000=F13),PACEs!$F$2:$F$1000),Date!$B$2:$K$1623,7,FALSE))} | G16: {=IF(ISERROR(_xlfn.XLOOKUP(1,(PACEs!$C$2:$C$1000=$A12)*(PACEs!$D$2:$D$1000=G13),PACEs!$F$2:$F$1000)),"",VLOOKUP(_xlfn.XLOOKUP(1,(PACEs!$C$2:$C$1000=$A12)*(PACEs!$D$2:$D$1000=G13),PACEs!$F$2:$F$1000),Date!$B$2:$K$1623,10,FALSE)&".T"&VLOOKUP(_xlfn.XLOOKUP(1,(PACEs!$C$2:$C$1000=$A12)*(PACEs!$D$2:$D$1000=G13),PACEs!$F$2:$F$1000),Date!$B$2:$K$1623,7,FALSE))} | H16: {=IF(ISERROR(_xlfn.XLOOKUP(1,(PACEs!$C$2:$C$1000=$A12)*(PACEs!$D$2:$D$1000=H13),PACEs!$F$2:$F$1000)),"",VLOOKUP(_xlfn.XLOOKUP(1,(PACEs!$C$2:$C$1000=$A12)*(PACEs!$D$2:$D$1000=H13),PACEs!$F$2:$F$1000),Date!$B$2:$K$1623,10,FALSE)&".T"&VLOOKUP(_xlfn.XLOOKUP(1,(PACEs!$C$2:$C$1000=$A12)*(PACEs!$D$2:$D$1000=H13),PACEs!$F$2:$F$1000),Date!$B$2:$K$1623,7,FALSE))} | I16: {=IF(ISERROR(_xlfn.XLOOKUP(1,(PACEs!$C$2:$C$1000=$A12)*(PACEs!$D$2:$D$1000=I13),PACEs!$F$2:$F$1000)),"",VLOOKUP(_xlfn.XLOOKUP(1,(PACEs!$C$2:$C$1000=$A12)*(PACEs!$D$2:$D$1000=I13),PACEs!$F$2:$F$1000),Date!$B$2:$K$1623,10,FALSE)&".T"&VLOOKUP(_xlfn.XLOOKUP(1,(PACEs!$C$2:$C$1000=$A12)*(PACEs!$D$2:$D$1000=I13),PACEs!$F$2:$F$1000),Date!$B$2:$K$1623,7,FALSE))} | ... M16: {=IF(ISERROR(_xlfn.XLOOKUP(1,(PACEs!$C$2:$C$1000=$A12)*(PACEs!$D$2:$D$1000=M13),PACEs!$F$2:$F$1000)),"",VLOOKUP(_xlfn.XLOOKUP(1,(PACEs!$C$2:$C$1000=$A12)*(PACEs!$D$2:$D$1000=M13),PACEs!$F$2:$F$1000),Date!$B$2:$K$1623,10,FALSE)&".T"&VLOOKUP(_xlfn.XLOOKUP(1,(PACEs!$C$2:$C$1000=$A12)*(PACEs!$D$2:$D$1000=M13),PACEs!$F$2:$F$1000),Date!$B$2:$K$1623,7,FALSE))} -> 25–26.T1
A17: Earth Science | B17: =IF(VLOOKUP($A17,Course!$B$2:$C$165, 2, FALSE)=0, VLOOKUP($A17,Course!$B$2:$C$165, 1, FALSE), VLOOKUP($A17,Course!$B$2:$C$165, 2, FALSE)) -> Earth Science | G17: =A17 -> Earth Science | L17: =IF(VLOOKUP($A17, Course!$B$2:$E$165, 3, FALSE)=0, "", VLOOKUP($A17, Course!$B$2:$E$165, 3, FALSE)) -> Earth Science
B18: =VLOOKUP($A17,Enrolment!$B$2:$N$15, B$1+1, FALSE) -> 85 | C18: =VLOOKUP($A17,Enrolment!$B$2:$N$15, C$1+1, FALSE) -> 86 | D18: =VLOOKUP($A17,Enrolment!$B$2:$N$15, D$1+1, FALSE) -> 87 | E18: =VLOOKUP($A17,Enrolment!$B$2:$N$15, E$1+1, FALSE) -> 88 | F18: =VLOOKUP($A17,Enrolment!$B$2:$N$15, F$1+1, FALSE) -> 89 | G18: =VLOOKUP($A17,Enrolment!$B$2:$N$15, G$1+1, FALSE) -> 90 | H18: =VLOOKUP($A17,Enrolment!$B$2:$N$15, H$1+1, FALSE) -> 91 | I18: =VLOOKUP($A17,Enrolment!$B$2:$N$15, I$1+1, FALSE) -> 92 | ... M18: =VLOOKUP($A17,Enrolment!$B$2:$N$15, M$1+1, FALSE) -> 96
B19: « | C19: « | D19: « | E19: « | F19: « | G19: « | H19: « | I19: « | J19: « | K19: « | L19: « | M19: «
B20: {=IFERROR(_xlfn.XLOOKUP(1, (PACEs!$C$2:$C$1000=$A17) * (PACEs!$D$2:$D$1000=B18), PACEs!$E$2:$E$1000), "")} | C20: {=IFERROR(_xlfn.XLOOKUP(1, (PACEs!$C$2:$C$1000=$A17) * (PACEs!$D$2:$D$1000=C18), PACEs!$E$2:$E$1000), "")} | D20: {=IFERROR(_xlfn.XLOOKUP(1, (PACEs!$C$2:$C$1000=$A17) * (PACEs!$D$2:$D$1000=D18), PACEs!$E$2:$E$1000), "")} | E20: {=IFERROR(_xlfn.XLOOKUP(1, (PACEs!$C$2:$C$1000=$A17) * (PACEs!$D$2:$D$1000=E18), PACEs!$E$2:$E$1000), "")} | F20: {=IFERROR(_xlfn.XLOOKUP(1, (PACEs!$C$2:$C$1000=$A17) * (PACEs!$D$2:$D$1000=F18), PACEs!$E$2:$E$1000), "")} | G20: {=IFERROR(_xlfn.XLOOKUP(1, (PACEs!$C$2:$C$1000=$A17) * (PACEs!$D$2:$D$1000=G18), PACEs!$E$2:$E$1000), "")} | H20: {=IFERROR(_xlfn.XLOOKUP(1, (PACEs!$C$2:$C$1000=$A17) * (PACEs!$D$2:$D$1000=H18), PACEs!$E$2:$E$1000), "")} | I20: {=IFERROR(_xlfn.XLOOKUP(1, (PACEs!$C$2:$C$1000=$A17) * (PACEs!$D$2:$D$1000=I18), PACEs!$E$2:$E$1000), "")} | ... M20: {=IFERROR(_xlfn.XLOOKUP(1, (PACEs!$C$2:$C$1000=$A17) * (PACEs!$D$2:$D$1000=M18), PACEs!$E$2:$E$1000), "")} -> 0.975
B21: {=IF(ISERROR(_xlfn.XLOOKUP(1,(PACEs!$C$2:$C$1000=$A17)*(PACEs!$D$2:$D$1000=B18),PACEs!$F$2:$F$1000)),"",VLOOKUP(_xlfn.XLOOKUP(1,(PACEs!$C$2:$C$1000=$A17)*(PACEs!$D$2:$D$1000=B18),PACEs!$F$2:$F$1000),Date!$B$2:$K$1623,10,FALSE)&".T"&VLOOKUP(_xlfn.XLOOKUP(1,(PACEs!$C$2:$C$1000=$A17)*(PACEs!$D$2:$D$1000=B18),PACEs!$F$2:$F$1000),Date!$B$2:$K$1623,7,FALSE))} | C21: {=IF(ISERROR(_xlfn.XLOOKUP(1,(PACEs!$C$2:$C$1000=$A17)*(PACEs!$D$2:$D$1000=C18),PACEs!$F$2:$F$1000)),"",VLOOKUP(_xlfn.XLOOKUP(1,(PACEs!$C$2:$C$1000=$A17)*(PACEs!$D$2:$D$1000=C18),PACEs!$F$2:$F$1000),Date!$B$2:$K$1623,10,FALSE)&".T"&VLOOKUP(_xlfn.XLOOKUP(1,(PACEs!$C$2:$C$1000=$A17)*(PACEs!$D$2:$D$1000=C18),PACEs!$F$2:$F$1000),Date!$B$2:$K$1623,7,FALSE))} | D21: {=IF(ISERROR(_xlfn.XLOOKUP(1,(PACEs!$C$2:$C$1000=$A17)*(PACEs!$D$2:$D$1000=D18),PACEs!$F$2:$F$1000)),"",VLOOKUP(_xlfn.XLOOKUP(1,(PACEs!$C$2:$C$1000=$A17)*(PACEs!$D$2:$D$1000=D18),PACEs!$F$2:$F$1000),Date!$B$2:$K$1623,10,FALSE)&".T"&VLOOKUP(_xlfn.XLOOKUP(1,(PACEs!$C$2:$C$1000=$A17)*(PACEs!$D$2:$D$1000=D18),PACEs!$F$2:$F$1000),Date!$B$2:$K$1623,7,FALSE))} | E21: {=IF(ISERROR(_xlfn.XLOOKUP(1,(PACEs!$C$2:$C$1000=$A17)*(PACEs!$D$2:$D$1000=E18),PACEs!$F$2:$F$1000)),"",VLOOKUP(_xlfn.XLOOKUP(1,(PACEs!$C$2:$C$1000=$A17)*(PACEs!$D$2:$D$1000=E18),PACEs!$F$2:$F$1000),Date!$B$2:$K$1623,10,FALSE)&".T"&VLOOKUP(_xlfn.XLOOKUP(1,(PACEs!$C$2:$C$1000=$A17)*(PACEs!$D$2:$D$1000=E18),PACEs!$F$2:$F$1000),Date!$B$2:$K$1623,7,FALSE))} | F21: {=IF(ISERROR(_xlfn.XLOOKUP(1,(PACEs!$C$2:$C$1000=$A17)*(PACEs!$D$2:$D$1000=F18),PACEs!$F$2:$F$1000)),"",VLOOKUP(_xlfn.XLOOKUP(1,(PACEs!$C$2:$C$1000=$A17)*(PACEs!$D$2:$D$1000=F18),PACEs!$F$2:$F$1000),Date!$B$2:$K$1623,10,FALSE)&".T"&VLOOKUP(_xlfn.XLOOKUP(1,(PACEs!$C$2:$C$1000=$A17)*(PACEs!$D$2:$D$1000=F18),PACEs!$F$2:$F$1000),Date!$B$2:$K$1623,7,FALSE))} | G21: {=IF(ISERROR(_xlfn.XLOOKUP(1,(PACEs!$C$2:$C$1000=$A17)*(PACEs!$D$2:$D$1000=G18),PACEs!$F$2:$F$1000)),"",VLOOKUP(_xlfn.XLOOKUP(1,(PACEs!$C$2:$C$1000=$A17)*(PACEs!$D$2:$D$1000=G18),PACEs!$F$2:$F$1000),Date!$B$2:$K$1623,10,FALSE)&".T"&VLOOKUP(_xlfn.XLOOKUP(1,(PACEs!$C$2:$C$1000=$A17)*(PACEs!$D$2:$D$1000=G18),PACEs!$F$2:$F$1000),Date!$B$2:$K$1623,7,FALSE))} | H21: {=IF(ISERROR(_xlfn.XLOOKUP(1,(PACEs!$C$2:$C$1000=$A17)*(PACEs!$D$2:$D$1000=H18),PACEs!$F$2:$F$1000)),"",VLOOKUP(_xlfn.XLOOKUP(1,(PACEs!$C$2:$C$1000=$A17)*(PACEs!$D$2:$D$1000=H18),PACEs!$F$2:$F$1000),Date!$B$2:$K$1623,10,FALSE)&".T"&VLOOKUP(_xlfn.XLOOKUP(1,(PACEs!$C$2:$C$1000=$A17)*(PACEs!$D$2:$D$1000=H18),PACEs!$F$2:$F$1000),Date!$B$2:$K$1623,7,FALSE))} | I21: {=IF(ISERROR(_xlfn.XLOOKUP(1,(PACEs!$C$2:$C$1000=$A17)*(PACEs!$D$2:$D$1000=I18),PACEs!$F$2:$F$1000)),"",VLOOKUP(_xlfn.XLOOKUP(1,(PACEs!$C$2:$C$1000=$A17)*(PACEs!$D$2:$D$1000=I18),PACEs!$F$2:$F$1000),Date!$B$2:$K$1623,10,FALSE)&".T"&VLOOKUP(_xlfn.XLOOKUP(1,(PACEs!$C$2:$C$1000=$A17)*(PACEs!$D$2:$D$1000=I18),PACEs!$F$2:$F$1000),Date!$B$2:$K$1623,7,FALSE))} | ... M21: {=IF(ISERROR(_xlfn.XLOOKUP(1,(PACEs!$C$2:$C$1000=$A17)*(PACEs!$D$2:$D$1000=M18),PACEs!$F$2:$F$1000)),"",VLOOKUP(_xlfn.XLOOKUP(1,(PACEs!$C$2:$C$1000=$A17)*(PACEs!$D$2:$D$1000=M18),PACEs!$F$2:$F$1000),Date!$B$2:$K$1623,10,FALSE)&".T"&VLOOKUP(_xlfn.XLOOKUP(1,(PACEs!$C$2:$C$1000=$A17)*(PACEs!$D$2:$D$1000=M18),PACEs!$F$2:$F$1000),Date!$B$2:$K$1623,7,FALSE))} -> 25–26.T1
A22: ICCE Physical Science | B22: =IF(VLOOKUP($A22,Course!$B$2:$C$165, 2, FALSE)=0, VLOOKUP($A22,Course!$B$2:$C$165, 1, FALSE), VLOOKUP($A22,Course!$B$2:$C$165, 2, FALSE)) -> CEE Physical Science I-B | G22: =A22 -> ICCE Physical Science | L22: =IF(VLOOKUP($A22, Course!$B$2:$E$165, 3, FALSE)=0, "", VLOOKUP($A22, Course!$B$2:$E$165, 3, FALSE)) -> Physical Science I
B23: =VLOOKUP($A22,Enrolment!$B$2:$N$15, B$1+1, FALSE) -> 85 | C23: =VLOOKUP($A22,Enrolment!$B$2:$N$15, C$1+1, FALSE) -> 86 | D23: =VLOOKUP($A22,Enrolment!$B$2:$N$15, D$1+1, FALSE) -> 86 | E23: =VLOOKUP($A22,Enrolment!$B$2:$N$15, E$1+1, FALSE) -> 87 | F23: =VLOOKUP($A22,Enrolment!$B$2:$N$15, F$1+1, FALSE) -> 88 | G23: =VLOOKUP($A22,Enrolment!$B$2:$N$15, G$1+1, FALSE) -> 88 | H23: =VLOOKUP($A22,Enrolment!$B$2:$N$15, H$1+1, FALSE) -> 97 | I23: =VLOOKUP($A22,Enrolment!$B$2:$N$15, I$1+1, FALSE) -> 98 | ... M23: =VLOOKUP($A22,Enrolment!$B$2:$N$15, M$1+1, FALSE) -> 100
B24: « | C24: « | D24: « | E24: « | F24: « | G24: « | H24: « | I24: « | J24: « | K24: « | L24: « | M24: «
B25: {=IFERROR(_xlfn.XLOOKUP(1, (PACEs!$C$2:$C$1000=$A22) * (PACEs!$D$2:$D$1000=B23), PACEs!$E$2:$E$1000), "")} | C25: {=IFERROR(_xlfn.XLOOKUP(1, (PACEs!$C$2:$C$1000=$A22) * (PACEs!$D$2:$D$1000=C23), PACEs!$E$2:$E$1000), "")} | D25: {=IFERROR(_xlfn.XLOOKUP(1, (PACEs!$C$2:$C$1000=$A22) * (PACEs!$D$2:$D$1000=D23), PACEs!$E$2:$E$1000), "")} | E25: {=IFERROR(_xlfn.XLOOKUP(1, (PACEs!$C$2:$C$1000=$A22) * (PACEs!$D$2:$D$1000=E23), PACEs!$E$2:$E$1000), "")} | F25: {=IFERROR(_xlfn.XLOOKUP(1, (PACEs!$C$2:$C$1000=$A22) * (PACEs!$D$2:$D$1000=F23), PACEs!$E$2:$E$1000), "")} | G25: {=IFERROR(_xlfn.XLOOKUP(1, (PACEs!$C$2:$C$1000=$A22) * (PACEs!$D$2:$D$1000=G23), PACEs!$E$2:$E$1000), "")} | H25: {=IFERROR(_xlfn.XLOOKUP(1, (PACEs!$C$2:$C$1000=$A22) * (PACEs!$D$2:$D$1000=H23), PACEs!$E$2:$E$1000), "")} | I25: {=IFERROR(_xlfn.XLOOKUP(1, (PACEs!$C$2:$C$1000=$A22) * (PACEs!$D$2:$D$1000=I23), PACEs!$E$2:$E$1000), "")} -> 1 | ... M25: {=IFERROR(_xlfn.XLOOKUP(1, (PACEs!$C$2:$C$1000=$A22) * (PACEs!$D$2:$D$1000=M23), PACEs!$E$2:$E$1000), "")}
B26: {=IF(ISERROR(_xlfn.XLOOKUP(1,(PACEs!$C$2:$C$1000=$A22)*(PACEs!$D$2:$D$1000=B23),PACEs!$F$2:$F$1000)),"",VLOOKUP(_xlfn.XLOOKUP(1,(PACEs!$C$2:$C$1000=$A22)*(PACEs!$D$2:$D$1000=B23),PACEs!$F$2:$F$1000),Date!$B$2:$K$1623,10,FALSE)&".T"&VLOOKUP(_xlfn.XLOOKUP(1,(PACEs!$C$2:$C$1000=$A22)*(PACEs!$D$2:$D$1000=B23),PACEs!$F$2:$F$1000),Date!$B$2:$K$1623,7,FALSE))} | C26: {=IF(ISERROR(_xlfn.XLOOKUP(1,(PACEs!$C$2:$C$1000=$A22)*(PACEs!$D$2:$D$1000=C23),PACEs!$F$2:$F$1000)),"",VLOOKUP(_xlfn.XLOOKUP(1,(PACEs!$C$2:$C$1000=$A22)*(PACEs!$D$2:$D$1000=C23),PACEs!$F$2:$F$1000),Date!$B$2:$K$1623,10,FALSE)&".T"&VLOOKUP(_xlfn.XLOOKUP(1,(PACEs!$C$2:$C$1000=$A22)*(PACEs!$D$2:$D$1000=C23),PACEs!$F$2:$F$1000),Date!$B$2:$K$1623,7,FALSE))} | D26: {=IF(ISERROR(_xlfn.XLOOKUP(1,(PACEs!$C$2:$C$1000=$A22)*(PACEs!$D$2:$D$1000=D23),PACEs!$F$2:$F$1000)),"",VLOOKUP(_xlfn.XLOOKUP(1,(PACEs!$C$2:$C$1000=$A22)*(PACEs!$D$2:$D$1000=D23),PACEs!$F$2:$F$1000),Date!$B$2:$K$1623,10,FALSE)&".T"&VLOOKUP(_xlfn.XLOOKUP(1,(PACEs!$C$2:$C$1000=$A22)*(PACEs!$D$2:$D$1000=D23),PACEs!$F$2:$F$1000),Date!$B$2:$K$1623,7,FALSE))} | E26: {=IF(ISERROR(_xlfn.XLOOKUP(1,(PACEs!$C$2:$C$1000=$A22)*(PACEs!$D$2:$D$1000=E23),PACEs!$F$2:$F$1000)),"",VLOOKUP(_xlfn.XLOOKUP(1,(PACEs!$C$2:$C$1000=$A22)*(PACEs!$D$2:$D$1000=E23),PACEs!$F$2:$F$1000),Date!$B$2:$K$1623,10,FALSE)&".T"&VLOOKUP(_xlfn.XLOOKUP(1,(PACEs!$C$2:$C$1000=$A22)*(PACEs!$D$2:$D$1000=E23),PACEs!$F$2:$F$1000),Date!$B$2:$K$1623,7,FALSE))} | F26: {=IF(ISERROR(_xlfn.XLOOKUP(1,(PACEs!$C$2:$C$1000=$A22)*(PACEs!$D$2:$D$1000=F23),PACEs!$F$2:$F$1000)),"",VLOOKUP(_xlfn.XLOOKUP(1,(PACEs!$C$2:$C$1000=$A22)*(PACEs!$D$2:$D$1000=F23),PACEs!$F$2:$F$1000),Date!$B$2:$K$1623,10,FALSE)&".T"&VLOOKUP(_xlfn.XLOOKUP(1,(PACEs!$C$2:$C$1000=$A22)*(PACEs!$D$2:$D$1000=F23),PACEs!$F$2:$F$1000),Date!$B$2:$K$1623,7,FALSE))} | G26: {=IF(ISERROR(_xlfn.XLOOKUP(1,(PACEs!$C$2:$C$1000=$A22)*(PACEs!$D$2:$D$1000=G23),PACEs!$F$2:$F$1000)),"",VLOOKUP(_xlfn.XLOOKUP(1,(PACEs!$C$2:$C$1000=$A22)*(PACEs!$D$2:$D$1000=G23),PACEs!$F$2:$F$1000),Date!$B$2:$K$1623,10,FALSE)&".T"&VLOOKUP(_xlfn.XLOOKUP(1,(PACEs!$C$2:$C$1000=$A22)*(PACEs!$D$2:$D$1000=G23),PACEs!$F$2:$F$1000),Date!$B$2:$K$1623,7,FALSE))} | H26: {=IF(ISERROR(_xlfn.XLOOKUP(1,(PACEs!$C$2:$C$1000=$A22)*(PACEs!$D$2:$D$1000=H23),PACEs!$F$2:$F$1000)),"",VLOOKUP(_xlfn.XLOOKUP(1,(PACEs!$C$2:$C$1000=$A22)*(PACEs!$D$2:$D$1000=H23),PACEs!$F$2:$F$1000),Date!$B$2:$K$1623,10,FALSE)&".T"&VLOOKUP(_xlfn.XLOOKUP(1,(PACEs!$C$2:$C$1000=$A22)*(PACEs!$D$2:$D$1000=H23),PACEs!$F$2:$F$1000),Date!$B$2:$K$1623,7,FALSE))} | I26: {=IF(ISERROR(_xlfn.XLOOKUP(1,(PACEs!$C$2:$C$1000=$A22)*(PACEs!$D$2:$D$1000=I23),PACEs!$F$2:$F$1000)),"",VLOOKUP(_xlfn.XLOOKUP(1,(PACEs!$C$2:$C$1000=$A22)*(PACEs!$D$2:$D$1000=I23),PACEs!$F$2:$F$1000),Date!$B$2:$K$1623,10,FALSE)&".T"&VLOOKUP(_xlfn.XLOOKUP(1,(PACEs!$C$2:$C$1000=$A22)*(PACEs!$D$2:$D$1000=I23),PACEs!$F$2:$F$1000),Date!$B$2:$K$1623,7,FALSE))} -> 25–26.T1 | ... M26: {=IF(ISERROR(_xlfn.XLOOKUP(1,(PACEs!$C$2:$C$1000=$A22)*(PACEs!$D$2:$D$1000=M23),PACEs!$F$2:$F$1000)),"",VLOOKUP(_xlfn.XLOOKUP(1,(PACEs!$C$2:$C$1000=$A22)*(PACEs!$D$2:$D$1000=M23),PACEs!$F$2:$F$1000),Date!$B$2:$K$1623,10,FALSE)&".T"&VLOOKUP(_xlfn.XLOOKUP(1,(PACEs!$C$2:$C$1000=$A22)*(PACEs!$D$2:$D$1000=M23),PACEs!$F$2:$F$1000),Date!$B$2:$K$1623,7,FALSE))}
A27: World Geography | B27: =IF(VLOOKUP($A27,Course!$B$2:$C$165, 2, FALSE)=0, VLOOKUP($A27,Course!$B$2:$C$165, 1, FALSE), VLOOKUP($A27,Course!$B$2:$C$165, 2, FALSE)) -> Social Studies I-C | G27: =A27 -> World Geography | L27: =IF(VLOOKUP($A27, Course!$B$2:$E$165, 3, FALSE)=0, "", VLOOKUP($A27, Course!$B$2:$E$165, 3, FALSE)) -> World Geography
B28: =VLOOKUP($A27,Enrolment!$B$2:$N$15, B$1+1, FALSE) -> 97 | C28: =VLOOKUP($A27,Enrolment!$B$2:$N$15, C$1+1, FALSE) -> 98 | D28: =VLOOKUP($A27,Enrolment!$B$2:$N$15, D$1+1, FALSE) -> 99 | E28: =VLOOKUP($A27,Enrolment!$B$2:$N$15, E$1+1, FALSE) -> 100 | F28: =VLOOKUP($A27,Enrolment!$B$2:$N$15, F$1+1, FALSE) -> 101 | G28: =VLOOKUP($A27,Enrolment!$B$2:$N$15, G$1+1, FALSE) -> 102 | H28: =VLOOKUP($A27,Enrolment!$B$2:$N$15, H$1+1, FALSE) -> 103 | I28: =VLOOKUP($A27,Enrolment!$B$2:$N$15, I$1+1, FALSE) -> 104 | ... M28: =VLOOKUP($A27,Enrolment!$B$2:$N$15, M$1+1, FALSE) -> 108
B29: « | C29: « | D29: « | E29: « | F29: « | G29: « | H29: « | I29: « | J29: « | K29: « | L29: « | M29: «
B30: {=IFERROR(_xlfn.XLOOKUP(1, (PACEs!$C$2:$C$1000=$A27) * (PACEs!$D$2:$D$1000=B28), PACEs!$E$2:$E$1000), "")} -> 0.98 | C30: {=IFERROR(_xlfn.XLOOKUP(1, (PACEs!$C$2:$C$1000=$A27) * (PACEs!$D$2:$D$1000=C28), PACEs!$E$2:$E$1000), "")} | D30: {=IFERROR(_xlfn.XLOOKUP(1, (PACEs!$C$2:$C$1000=$A27) * (PACEs!$D$2:$D$1000=D28), PACEs!$E$2:$E$1000), "")} -> 0.975 | E30: {=IFERROR(_xlfn.XLOOKUP(1, (PACEs!$C$2:$C$1000=$A27) * (PACEs!$D$2:$D$1000=E28), PACEs!$E$2:$E$1000), "")} -> 1 | F30: {=IFERROR(_xlfn.XLOOKUP(1, (PACEs!$C$2:$C$1000=$A27) * (PACEs!$D$2:$D$1000=F28), PACEs!$E$2:$E$1000), "")} | G30: {=IFERROR(_xlfn.XLOOKUP(1, (PACEs!$C$2:$C$1000=$A27) * (PACEs!$D$2:$D$1000=G28), PACEs!$E$2:$E$1000), "")} | H30: {=IFERROR(_xlfn.XLOOKUP(1, (PACEs!$C$2:$C$1000=$A27) * (PACEs!$D$2:$D$1000=H28), PACEs!$E$2:$E$1000), "")} | I30: {=IFERROR(_xlfn.XLOOKUP(1, (PACEs!$C$2:$C$1000=$A27) * (PACEs!$D$2:$D$1000=I28), PACEs!$E$2:$E$1000), "")} | ... M30: {=IFERROR(_xlfn.XLOOKUP(1, (PACEs!$C$2:$C$1000=$A27) * (PACEs!$D$2:$D$1000=M28), PACEs!$E$2:$E$1000), "")}
B31: {=IF(ISERROR(_xlfn.XLOOKUP(1,(PACEs!$C$2:$C$1000=$A27)*(PACEs!$D$2:$D$1000=B28),PACEs!$F$2:$F$1000)),"",VLOOKUP(_xlfn.XLOOKUP(1,(PACEs!$C$2:$C$1000=$A27)*(PACEs!$D$2:$D$1000=B28),PACEs!$F$2:$F$1000),Date!$B$2:$K$1623,10,FALSE)&".T"&VLOOKUP(_xlfn.XLOOKUP(1,(PACEs!$C$2:$C$1000=$A27)*(PACEs!$D$2:$D$1000=B28),PACEs!$F$2:$F$1000),Date!$B$2:$K$1623,7,FALSE))} -> 25–26.T1 | C31: {=IF(ISERROR(_xlfn.XLOOKUP(1,(PACEs!$C$2:$C$1000=$A27)*(PACEs!$D$2:$D$1000=C28),PACEs!$F$2:$F$1000)),"",VLOOKUP(_xlfn.XLOOKUP(1,(PACEs!$C$2:$C$1000=$A27)*(PACEs!$D$2:$D$1000=C28),PACEs!$F$2:$F$1000),Date!$B$2:$K$1623,10,FALSE)&".T"&VLOOKUP(_xlfn.XLOOKUP(1,(PACEs!$C$2:$C$1000=$A27)*(PACEs!$D$2:$D$1000=C28),PACEs!$F$2:$F$1000),Date!$B$2:$K$1623,7,FALSE))} | D31: {=IF(ISERROR(_xlfn.XLOOKUP(1,(PACEs!$C$2:$C$1000=$A27)*(PACEs!$D$2:$D$1000=D28),PACEs!$F$2:$F$1000)),"",VLOOKUP(_xlfn.XLOOKUP(1,(PACEs!$C$2:$C$1000=$A27)*(PACEs!$D$2:$D$1000=D28),PACEs!$F$2:$F$1000),Date!$B$2:$K$1623,10,FALSE)&".T"&VLOOKUP(_xlfn.XLOOKUP(1,(PACEs!$C$2:$C$1000=$A27)*(PACEs!$D$2:$D$1000=D28),PACEs!$F$2:$F$1000),Date!$B$2:$K$1623,7,FALSE))} -> 25–26.T3 | E31: {=IF(ISERROR(_xlfn.XLOOKUP(1,(PACEs!$C$2:$C$1000=$A27)*(PACEs!$D$2:$D$1000=E28),PACEs!$F$2:$F$1000)),"",VLOOKUP(_xlfn.XLOOKUP(1,(PACEs!$C$2:$C$1000=$A27)*(PACEs!$D$2:$D$1000=E28),PACEs!$F$2:$F$1000),Date!$B$2:$K$1623,10,FALSE)&".T"&VLOOKUP(_xlfn.XLOOKUP(1,(PACEs!$C$2:$C$1000=$A27)*(PACEs!$D$2:$D$1000=E28),PACEs!$F$2:$F$1000),Date!$B$2:$K$1623,7,FALSE))} -> 25–26.T3 | F31: {=IF(ISERROR(_xlfn.XLOOKUP(1,(PACEs!$C$2:$C$1000=$A27)*(PACEs!$D$2:$D$1000=F28),PACEs!$F$2:$F$1000)),"",VLOOKUP(_xlfn.XLOOKUP(1,(PACEs!$C$2:$C$1000=$A27)*(PACEs!$D$2:$D$1000=F28),PACEs!$F$2:$F$1000),Date!$B$2:$K$1623,10,FALSE)&".T"&VLOOKUP(_xlfn.XLOOKUP(1,(PACEs!$C$2:$C$1000=$A27)*(PACEs!$D$2:$D$1000=F28),PACEs!$F$2:$F$1000),Date!$B$2:$K$1623,7,FALSE))} | G31: {=IF(ISERROR(_xlfn.XLOOKUP(1,(PACEs!$C$2:$C$1000=$A27)*(PACEs!$D$2:$D$1000=G28),PACEs!$F$2:$F$1000)),"",VLOOKUP(_xlfn.XLOOKUP(1,(PACEs!$C$2:$C$1000=$A27)*(PACEs!$D$2:$D$1000=G28),PACEs!$F$2:$F$1000),Date!$B$2:$K$1623,10,FALSE)&".T"&VLOOKUP(_xlfn.XLOOKUP(1,(PACEs!$C$2:$C$1000=$A27)*(PACEs!$D$2:$D$1000=G28),PACEs!$F$2:$F$1000),Date!$B$2:$K$1623,7,FALSE))} | H31: {=IF(ISERROR(_xlfn.XLOOKUP(1,(PACEs!$C$2:$C$1000=$A27)*(PACEs!$D$2:$D$1000=H28),PACEs!$F$2:$F$1000)),"",VLOOKUP(_xlfn.XLOOKUP(1,(PACEs!$C$2:$C$1000=$A27)*(PACEs!$D$2:$D$1000=H28),PACEs!$F$2:$F$1000),Date!$B$2:$K$1623,10,FALSE)&".T"&VLOOKUP(_xlfn.XLOOKUP(1,(PACEs!$C$2:$C$1000=$A27)*(PACEs!$D$2:$D$1000=H28),PACEs!$F$2:$F$1000),Date!$B$2:$K$1623,7,FALSE))} | I31: {=IF(ISERROR(_xlfn.XLOOKUP(1,(PACEs!$C$2:$C$1000=$A27)*(PACEs!$D$2:$D$1000=I28),PACEs!$F$2:$F$1000)),"",VLOOKUP(_xlfn.XLOOKUP(1,(PACEs!$C$2:$C$1000=$A27)*(PACEs!$D$2:$D$1000=I28),PACEs!$F$2:$F$1000),Date!$B$2:$K$1623,10,FALSE)&".T"&VLOOKUP(_xlfn.XLOOKUP(1,(PACEs!$C$2:$C$1000=$A27)*(PACEs!$D$2:$D$1000=I28),PACEs!$F$2:$F$1000),Date!$B$2:$K$1623,7,FALSE))} | ... M31: {=IF(ISERROR(_xlfn.XLOOKUP(1,(PACEs!$C$2:$C$1000=$A27)*(PACEs!$D$2:$D$1000=M28),PACEs!$F$2:$F$1000)),"",VLOOKUP(_xlfn.XLOOKUP(1,(PACEs!$C$2:$C$1000=$A27)*(PACEs!$D$2:$D$1000=M28),PACEs!$F$2:$F$1000),Date!$B$2:$K$1623,10,FALSE)&".T"&VLOOKUP(_xlfn.XLOOKUP(1,(PACEs!$C$2:$C$1000=$A27)*(PACEs!$D$2:$D$1000=M28),PACEs!$F$2:$F$1000),Date!$B$2:$K$1623,7,FALSE))}
A32: New Testament Survey | B32: =IF(VLOOKUP($A32,Course!$B$2:$C$165, 2, FALSE)=0, VLOOKUP($A32,Course!$B$2:$C$165, 1, FALSE), VLOOKUP($A32,Course!$B$2:$C$165, 2, FALSE)) -> Biblical Studies I: New Testament Survey | G32: =A32 -> New Testament Survey | L32: =IF(VLOOKUP($A32, Course!$B$2:$E$165, 3, FALSE)=0, "", VLOOKUP($A32, Course!$B$2:$E$165, 3, FALSE)) -> New Testament Survey
B33: =VLOOKUP($A32,Enrolment!$B$2:$N$15, B$1+1, FALSE) -> 97 | C33: =VLOOKUP($A32,Enrolment!$B$2:$N$15, C$1+1, FALSE) -> 98 | D33: =VLOOKUP($A32,Enrolment!$B$2:$N$15, D$1+1, FALSE) -> 99 | E33: =VLOOKUP($A32,Enrolment!$B$2:$N$15, E$1+1, FALSE) -> 100 | F33: =VLOOKUP($A32,Enrolment!$B$2:$N$15, F$1+1, FALSE) -> 101 | G33: =VLOOKUP($A32,Enrolment!$B$2:$N$15, G$1+1, FALSE) -> 102 | H33: =VLOOKUP($A32,Enrolment!$B$2:$N$15, H$1+1, FALSE) -> 103 | I33: =VLOOKUP($A32,Enrolment!$B$2:$N$15, I$1+1, FALSE) -> 104 | ... M33: =VLOOKUP($A32,Enrolment!$B$2:$N$15, M$1+1, FALSE) -> 108
B34: « | C34: « | D34: « | E34: « | F34: « | G34: « | H34: « | I34: « | J34: « | K34: « | L34: « | M34: «
B35: {=IFERROR(_xlfn.XLOOKUP(1, (PACEs!$C$2:$C$1000=$A32) * (PACEs!$D$2:$D$1000=B33), PACEs!$E$2:$E$1000), "")} | C35: {=IFERROR(_xlfn.XLOOKUP(1, (PACEs!$C$2:$C$1000=$A32) * (PACEs!$D$2:$D$1000=C33), PACEs!$E$2:$E$1000), "")} | D35: {=IFERROR(_xlfn.XLOOKUP(1, (PACEs!$C$2:$C$1000=$A32) * (PACEs!$D$2:$D$1000=D33), PACEs!$E$2:$E$1000), "")} | E35: {=IFERROR(_xlfn.XLOOKUP(1, (PACEs!$C$2:$C$1000=$A32) * (PACEs!$D$2:$D$1000=E33), PACEs!$E$2:$E$1000), "")} | F35: {=IFERROR(_xlfn.XLOOKUP(1, (PACEs!$C$2:$C$1000=$A32) * (PACEs!$D$2:$D$1000=F33), PACEs!$E$2:$E$1000), "")} | G35: {=IFERROR(_xlfn.XLOOKUP(1, (PACEs!$C$2:$C$1000=$A32) * (PACEs!$D$2:$D$1000=G33), PACEs!$E$2:$E$1000), "")} | H35: {=IFERROR(_xlfn.XLOOKUP(1, (PACEs!$C$2:$C$1000=$A32) * (PACEs!$D$2:$D$1000=H33), PACEs!$E$2:$E$1000), "")} | I35: {=IFERROR(_xlfn.XLOOKUP(1, (PACEs!$C$2:$C$1000=$A32) * (PACEs!$D$2:$D$1000=I33), PACEs!$E$2:$E$1000), "")} | ... M35: {=IFERROR(_xlfn.XLOOKUP(1, (PACEs!$C$2:$C$1000=$A32) * (PACEs!$D$2:$D$1000=M33), PACEs!$E$2:$E$1000), "")} -> 0.99
B36: {=IF(ISERROR(_xlfn.XLOOKUP(1,(PACEs!$C$2:$C$1000=$A32)*(PACEs!$D$2:$D$1000=B33),PACEs!$F$2:$F$1000)),"",VLOOKUP(_xlfn.XLOOKUP(1,(PACEs!$C$2:$C$1000=$A32)*(PACEs!$D$2:$D$1000=B33),PACEs!$F$2:$F$1000),Date!$B$2:$K$1623,10,FALSE)&".T"&VLOOKUP(_xlfn.XLOOKUP(1,(PACEs!$C$2:$C$1000=$A32)*(PACEs!$D$2:$D$1000=B33),PACEs!$F$2:$F$1000),Date!$B$2:$K$1623,7,FALSE))} | C36: {=IF(ISERROR(_xlfn.XLOOKUP(1,(PACEs!$C$2:$C$1000=$A32)*(PACEs!$D$2:$D$1000=C33),PACEs!$F$2:$F$1000)),"",VLOOKUP(_xlfn.XLOOKUP(1,(PACEs!$C$2:$C$1000=$A32)*(PACEs!$D$2:$D$1000=C33),PACEs!$F$2:$F$1000),Date!$B$2:$K$1623,10,FALSE)&".T"&VLOOKUP(_xlfn.XLOOKUP(1,(PACEs!$C$2:$C$1000=$A32)*(PACEs!$D$2:$D$1000=C33),PACEs!$F$2:$F$1000),Date!$B$2:$K$1623,7,FALSE))} | D36: {=IF(ISERROR(_xlfn.XLOOKUP(1,(PACEs!$C$2:$C$1000=$A32)*(PACEs!$D$2:$D$1000=D33),PACEs!$F$2:$F$1000)),"",VLOOKUP(_xlfn.XLOOKUP(1,(PACEs!$C$2:$C$1000=$A32)*(PACEs!$D$2:$D$1000=D33),PACEs!$F$2:$F$1000),Date!$B$2:$K$1623,10,FALSE)&".T"&VLOOKUP(_xlfn.XLOOKUP(1,(PACEs!$C$2:$C$1000=$A32)*(PACEs!$D$2:$D$1000=D33),PACEs!$F$2:$F$1000),Date!$B$2:$K$1623,7,FALSE))} | E36: {=IF(ISERROR(_xlfn.XLOOKUP(1,(PACEs!$C$2:$C$1000=$A32)*(PACEs!$D$2:$D$1000=E33),PACEs!$F$2:$F$1000)),"",VLOOKUP(_xlfn.XLOOKUP(1,(PACEs!$C$2:$C$1000=$A32)*(PACEs!$D$2:$D$1000=E33),PACEs!$F$2:$F$1000),Date!$B$2:$K$1623,10,FALSE)&".T"&VLOOKUP(_xlfn.XLOOKUP(1,(PACEs!$C$2:$C$1000=$A32)*(PACEs!$D$2:$D$1000=E33),PACEs!$F$2:$F$1000),Date!$B$2:$K$1623,7,FALSE))} | F36: {=IF(ISERROR(_xlfn.XLOOKUP(1,(PACEs!$C$2:$C$1000=$A32)*(PACEs!$D$2:$D$1000=F33),PACEs!$F$2:$F$1000)),"",VLOOKUP(_xlfn.XLOOKUP(1,(PACEs!$C$2:$C$1000=$A32)*(PACEs!$D$2:$D$1000=F33),PACEs!$F$2:$F$1000),Date!$B$2:$K$1623,10,FALSE)&".T"&VLOOKUP(_xlfn.XLOOKUP(1,(PACEs!$C$2:$C$1000=$A32)*(PACEs!$D$2:$D$1000=F33),PACEs!$F$2:$F$1000),Date!$B$2:$K$1623,7,FALSE))} | G36: {=IF(ISERROR(_xlfn.XLOOKUP(1,(PACEs!$C$2:$C$1000=$A32)*(PACEs!$D$2:$D$1000=G33),PACEs!$F$2:$F$1000)),"",VLOOKUP(_xlfn.XLOOKUP(1,(PACEs!$C$2:$C$1000=$A32)*(PACEs!$D$2:$D$1000=G33),PACEs!$F$2:$F$1000),Date!$B$2:$K$1623,10,FALSE)&".T"&VLOOKUP(_xlfn.XLOOKUP(1,(PACEs!$C$2:$C$1000=$A32)*(PACEs!$D$2:$D$1000=G33),PACEs!$F$2:$F$1000),Date!$B$2:$K$1623,7,FALSE))} | H36: {=IF(ISERROR(_xlfn.XLOOKUP(1,(PACEs!$C$2:$C$1000=$A32)*(PACEs!$D$2:$D$1000=H33),PACEs!$F$2:$F$1000)),"",VLOOKUP(_xlfn.XLOOKUP(1,(PACEs!$C$2:$C$1000=$A32)*(PACEs!$D$2:$D$1000=H33),PACEs!$F$2:$F$1000),Date!$B$2:$K$1623,10,FALSE)&".T"&VLOOKUP(_xlfn.XLOOKUP(1,(PACEs!$C$2:$C$1000=$A32)*(PACEs!$D$2:$D$1000=H33),PACEs!$F$2:$F$1000),Date!$B$2:$K$1623,7,FALSE))} | I36: {=IF(ISERROR(_xlfn.XLOOKUP(1,(PACEs!$C$2:$C$1000=$A32)*(PACEs!$D$2:$D$1000=I33),PACEs!$F$2:$F$1000)),"",VLOOKUP(_xlfn.XLOOKUP(1,(PACEs!$C$2:$C$1000=$A32)*(PACEs!$D$2:$D$1000=I33),PACEs!$F$2:$F$1000),Date!$B$2:$K$1623,10,FALSE)&".T"&VLOOKUP(_xlfn.XLOOKUP(1,(PACEs!$C$2:$C$1000=$A32)*(PACEs!$D$2:$D$1000=I33),PACEs!$F$2:$F$1000),Date!$B$2:$K$1623,7,FALSE))} | ... M36: {=IF(ISERROR(_xlfn.XLOOKUP(1,(PACEs!$C$2:$C$1000=$A32)*(PACEs!$D$2:$D$1000=M33),PACEs!$F$2:$F$1000)),"",VLOOKUP(_xlfn.XLOOKUP(1,(PACEs!$C$2:$C$1000=$A32)*(PACEs!$D$2:$D$1000=M33),PACEs!$F$2:$F$1000),Date!$B$2:$K$1623,10,FALSE)&".T"&VLOOKUP(_xlfn.XLOOKUP(1,(PACEs!$C$2:$C$1000=$A32)*(PACEs!$D$2:$D$1000=M33),PACEs!$F$2:$F$1000),Date!$B$2:$K$1623,7,FALSE))} -> 25–26.T1
A37: Astronomy | B37: =IF(VLOOKUP($A37,Course!$B$2:$C$165, 2, FALSE)=0, VLOOKUP($A37,Course!$B$2:$C$165, 1, FALSE), VLOOKUP($A37,Course!$B$2:$C$165, 2, FALSE)) -> Astronomy | G37: =A37 -> Astronomy | L37: =IF(VLOOKUP($A37, Course!$B$2:$E$165, 3, FALSE)=0, "", VLOOKUP($A37, Course!$B$2:$E$165, 3, FALSE)) -> Astronomy
B38: =IF(VLOOKUP($A37,Enrolment!$B$2:$N$15, B$1+1, FALSE)=0, "", VLOOKUP($A37,Enrolment!$B$2:$N$15, B$1+1, FALSE)) -> 1 | C38: =IF(VLOOKUP($A37,Enrolment!$B$2:$N$15, C$1+1, FALSE)=0, "", VLOOKUP($A37,Enrolment!$B$2:$N$15, C$1+1, FALSE)) -> 2 | D38: =IF(VLOOKUP($A37,Enrolment!$B$2:$N$15, D$1+1, FALSE)=0, "", VLOOKUP($A37,Enrolment!$B$2:$N$15, D$1+1, FALSE)) -> 3 | E38: =IF(VLOOKUP($A37,Enrolment!$B$2:$N$15, E$1+1, FALSE)=0, "", VLOOKUP($A37,Enrolment!$B$2:$N$15, E$1+1, FALSE)) -> 4 | F38: =IF(VLOOKUP($A37,Enrolment!$B$2:$N$15, F$1+1, FALSE)=0, "", VLOOKUP($A37,Enrolment!$B$2:$N$15, F$1+1, FALSE)) -> 5 | G38: =IF(VLOOKUP($A37,Enrolment!$B$2:$N$15, G$1+1, FALSE)=0, "", VLOOKUP($A37,Enrolment!$B$2:$N$15, G$1+1, FALSE)) -> 5 | H38: =IF(VLOOKUP($A37,Enrolment!$B$2:$N$15, H$1+1, FALSE)=0, "", VLOOKUP($A37,Enrolment!$B$2:$N$15, H$1+1, FALSE)) | I38: =IF(VLOOKUP($A37,Enrolment!$B$2:$N$15, I$1+1, FALSE)=0, "", VLOOKUP($A37,Enrolment!$B$2:$N$15, I$1+1, FALSE)) | ... M38: =IF(VLOOKUP($A37,Enrolment!$B$2:$N$15, M$1+1, FALSE)=0, "", VLOOKUP($A37,Enrolment!$B$2:$N$15, M$1+1, FALSE))
B39: « | C39: « | D39: « | E39: « | F39: « | G39: « | H39: « | I39: « | J39: « | K39: « | L39: « | M39: «
B40: {=IFERROR(_xlfn.XLOOKUP(1, (PACEs!$C$2:$C$1000=$A37) * (PACEs!$D$2:$D$1000=B38), PACEs!$E$2:$E$1000), "")} | C40: {=IFERROR(_xlfn.XLOOKUP(1, (PACEs!$C$2:$C$1000=$A37) * (PACEs!$D$2:$D$1000=C38), PACEs!$E$2:$E$1000), "")} | D40: {=IFERROR(_xlfn.XLOOKUP(1, (PACEs!$C$2:$C$1000=$A37) * (PACEs!$D$2:$D$1000=D38), PACEs!$E$2:$E$1000), "")} | E40: {=IFERROR(_xlfn.XLOOKUP(1, (PACEs!$C$2:$C$1000=$A37) * (PACEs!$D$2:$D$1000=E38), PACEs!$E$2:$E$1000), "")} -> 0.92 | F40: {=IFERROR(_xlfn.XLOOKUP(1, (PACEs!$C$2:$C$1000=$A37) * (PACEs!$D$2:$D$1000=F38), PACEs!$E$2:$E$1000), "")} | G40: {=IFERROR(_xlfn.XLOOKUP(1, (PACEs!$C$2:$C$1000=$A37) * (PACEs!$D$2:$D$1000=G38), PACEs!$E$2:$E$1000), "")} | H40: {=IFERROR(_xlfn.XLOOKUP(1, (PACEs!$C$2:$C$1000=$A37) * (PACEs!$D$2:$D$1000=H38), PACEs!$E$2:$E$1000), "")} | I40: {=IFERROR(_xlfn.XLOOKUP(1, (PACEs!$C$2:$C$1000=$A37) * (PACEs!$D$2:$D$1000=I38), PACEs!$E$2:$E$1000), "")} | ... M40: {=IFERROR(_xlfn.XLOOKUP(1, (PACEs!$C$2:$C$1000=$A37) * (PACEs!$D$2:$D$1000=M38), PACEs!$E$2:$E$1000), "")}
...

Sheet Subject
A1: ID | B1: Subject | C1: ColorID | D1: Color | E1: Remarks
A2: 1 | B2: Maths | C2: 4 | D2: yellow
A3: 2 | B3: Language | C3: 2 | D3: red
A4: 3 | B4: Word Building | C4: 9 | D4: purple
A5: 4 | B5: Literature | C5: 3 | D5: dark red
A6: 5 | B6: Science | C6: 5 | D6: blue
A7: 6 | B7: Social Studies | C7: 6 | D7: green
A8: 7 | B8: Biblical Studies | C8: 1 | D8: sandy orange
A9: 11 | B9: Art Electives | C9: 9 | D9: purple
A10: 12 | B10: Technology Electives | C10: 8 | D10: dark grey | E10: changed to "dark grey" instead of "grey", because "grey" is the default.
A11: 10 | B11: Supplementary | C11: 10 | D11: white
A12: 8 | B12: Electives | C12: 7 | D12: grey | E12: This one has been replaced by ID=11,12

Sheet Course
A1: ID | B1: ACE_Alias | C1: ICCE_Alias (Course Name) | D1: Certificate Name | E1: ICCEID (Course ID) | F1: Level | G1: PaceNrStart | H1: PaceNrEnd | I1: PaceCount__ | J1: StarValue | K1: SubjectID | L1: Subject_temp | M1: SubjectAbb | N1: Remarks | O1: Specification | P1: SubjectGroupID | Q1: SubjectGroup__ | R1: CourseType | S1: Course | T1: PassThreshold | U1: Status
A2: 1 | B2: Maths Reading Readiness | F2: 0 | G2: 1 | H2: 12 | I2: =H2-G2+1 -> 12 | J2: 12 | K2: 1 | L2: =VLOOKUP(K2,Subject!$A$2:$B$12, 2, FALSE) -> Maths | M2: =VLOOKUP(K2, [1]Subject!$A$2:$E$11, 5, FALSE) -> MA | O2: RR | P2: 2 | Q2: =VLOOKUP(P2, [1]SubjectGroup!$A$2:$B$8, 2, FALSE) -> Core Academic Studies | R2: Core | S2: =B2 -> Maths Reading Readiness | T2: 0.8
A3: 2 | B3: Maths Level 1 | F3: 1 | G3: 1 | H3: 12 | I3: =H3-G3+1 -> 12 | J3: 12 | K3: 1 | L3: =VLOOKUP(K3,Subject!$A$2:$B$12, 2, FALSE) -> Maths | M3: =VLOOKUP(K3, [1]Subject!$A$2:$E$11, 5, FALSE) -> MA | O3: MA | P3: 2 | Q3: =VLOOKUP(P3, [1]SubjectGroup!$A$2:$B$8, 2, FALSE) -> Core Academic Studies | R3: Core | S3: =B3 -> Maths Level 1 | T3: 0.8
A4: 3 | B4: English Level 1 | F4: 1 | G4: 1 | H4: 12 | I4: =H4-G4+1 -> 12 | J4: 12 | K4: 2 | L4: =VLOOKUP(K4,Subject!$A$2:$B$12, 2, FALSE) -> Language | M4: =VLOOKUP(K4, [1]Subject!$A$2:$E$11, 5, FALSE) -> LA | O4: EN | P4: 2 | Q4: =VLOOKUP(P4, [1]SubjectGroup!$A$2:$B$8, 2, FALSE) -> Core Academic Studies | R4: Core | S4: =B4 -> English Level 1 | T4: 0.8
A5: 4 | B5: Word Building Level 1 | F5: 1 | G5: 1 | H5: 12 | I5: =H5-G5+1 -> 12 | J5: 12 | K5: 3 | L5: =VLOOKUP(K5,Subject!$A$2:$B$12, 2, FALSE) -> Word Building | M5: =VLOOKUP(K5, [1]Subject!$A$2:$E$11, 5, FALSE) -> WB | O5: WB | P5: 2 | Q5: =VLOOKUP(P5, [1]SubjectGroup!$A$2:$B$8, 2, FALSE) -> Core Academic Studies | R5: Core | S5: =B5 -> Word Building Level 1 | T5: 0.9
A6: 5 | B6: Literature and Creative Writing Level 1 | F6: 1 | G6: 1 | H6: 12 | I6: =H6-G6+1 -> 12 | J6: 12 | K6: 4 | L6: =VLOOKUP(K6,Subject!$A$2:$B$12, 2, FALSE) -> Literature | M6: =VLOOKUP(K6, [1]Subject!$A$2:$E$11, 5, FALSE) -> LI | O6: LC | P6: 2 | Q6: =VLOOKUP(P6, [1]SubjectGroup!$A$2:$B$8, 2, FALSE) -> Core Academic Studies | R6: Core | S6: =B6 -> Literature and Creative Writing Level 1 | T6: 0.8
A7: 6 | B7: Science Level 1 | E7: Science 1 | F7: 1 | G7: 1 | H7: 12 | I7: =H7-G7+1 -> 12 | J7: 12 | K7: 5 | L7: =VLOOKUP(K7,Subject!$A$2:$B$12, 2, FALSE) -> Science | M7: =VLOOKUP(K7, [1]Subject!$A$2:$E$11, 5, FALSE) -> SC | O7: SC | P7: 2 | Q7: =VLOOKUP(P7, [1]SubjectGroup!$A$2:$B$8, 2, FALSE) -> Core Academic Studies | R7: Core | S7: =B7 -> Science Level 1 | T7: 0.8
A8: 7 | B8: Social Studies Level 1 | F8: 1 | G8: 1 | H8: 12 | I8: =H8-G8+1 -> 12 | J8: 12 | K8: 6 | L8: =VLOOKUP(K8,Subject!$A$2:$B$12, 2, FALSE) -> Social Studies | M8: =VLOOKUP(K8, [1]Subject!$A$2:$E$11, 5, FALSE) -> SS | O8: SS | P8: 2 | Q8: =VLOOKUP(P8, [1]SubjectGroup!$A$2:$B$8, 2, FALSE) -> Core Academic Studies | R8: Core | S8: =B8 -> Social Studies Level 1 | T8: 0.8
A9: 8 | B9: Bible Reading Level 1 | F9: 1 | G9: 1 | H9: 12 | I9: =H9-G9+1 -> 12 | J9: 12 | K9: 7 | L9: =VLOOKUP(K9,Subject!$A$2:$B$12, 2, FALSE) -> Biblical Studies | M9: =VLOOKUP(K9, [1]Subject!$A$2:$E$11, 5, FALSE) -> BS | O9: BR | P9: 1 | Q9: =VLOOKUP(P9, [1]SubjectGroup!$A$2:$B$8, 2, FALSE) -> Christian Studies | R9: Core | S9: =B9 -> Bible Reading Level 1 | T9: 0.8
A10: 9 | B10: Maths Level 2 | F10: 2 | G10: 13 | H10: 24 | I10: =H10-G10+1 -> 12 | J10: 12 | K10: 1 | L10: =VLOOKUP(K10,Subject!$A$2:$B$12, 2, FALSE) -> Maths | M10: =VLOOKUP(K10, [1]Subject!$A$2:$E$11, 5, FALSE) -> MA | O10: MA | P10: 2 | Q10: =VLOOKUP(P10, [1]SubjectGroup!$A$2:$B$8, 2, FALSE) -> Core Academic Studies | R10: Core | S10: =B10 -> Maths Level 2 | T10: 0.8
A11: 10 | B11: English Level 2 | F11: 2 | G11: 13 | H11: 24 | I11: =H11-G11+1 -> 12 | J11: 12 | K11: 2 | L11: =VLOOKUP(K11,Subject!$A$2:$B$12, 2, FALSE) -> Language | M11: =VLOOKUP(K11, [1]Subject!$A$2:$E$11, 5, FALSE) -> LA | O11: EN | P11: 2 | Q11: =VLOOKUP(P11, [1]SubjectGroup!$A$2:$B$8, 2, FALSE) -> Core Academic Studies | R11: Core | S11: =B11 -> English Level 2 | T11: 0.8
A12: 11 | B12: Word Building Level 2 | F12: 2 | G12: 13 | H12: 24 | I12: =H12-G12+1 -> 12 | J12: 12 | K12: 3 | L12: =VLOOKUP(K12,Subject!$A$2:$B$12, 2, FALSE) -> Word Building | M12: =VLOOKUP(K12, [1]Subject!$A$2:$E$11, 5, FALSE) -> WB | O12: WB | P12: 2 | Q12: =VLOOKUP(P12, [1]SubjectGroup!$A$2:$B$8, 2, FALSE) -> Core Academic Studies | R12: Core | S12: =B12 -> Word Building Level 2 | T12: 0.9
A13: 12 | B13: Literature and Creative Writing Level 2 | F13: 2 | G13: 13 | H13: 24 | I13: =H13-G13+1 -> 12 | J13: 12 | K13: 4 | L13: =VLOOKUP(K13,Subject!$A$2:$B$12, 2, FALSE) -> Literature | M13: =VLOOKUP(K13, [1]Subject!$A$2:$E$11, 5, FALSE) -> LI | O13: LC | P13: 2 | Q13: =VLOOKUP(P13, [1]SubjectGroup!$A$2:$B$8, 2, FALSE) -> Core Academic Studies | R13: Core | S13: =B13 -> Literature and Creative Writing Level 2 | T13: 0.8
A14: 13 | B14: Science Level 2 | E14: Science 2 | F14: 2 | G14: 13 | H14: 24 | I14: =H14-G14+1 -> 12 | J14: 12 | K14: 5 | L14: =VLOOKUP(K14,Subject!$A$2:$B$12, 2, FALSE) -> Science | M14: =VLOOKUP(K14, [1]Subject!$A$2:$E$11, 5, FALSE) -> SC | O14: SC | P14: 2 | Q14: =VLOOKUP(P14, [1]SubjectGroup!$A$2:$B$8, 2, FALSE) -> Core Academic Studies | R14: Core | S14: =B14 -> Science Level 2 | T14: 0.8
A15: 14 | B15: Social Studies Level 2 | F15: 2 | G15: 13 | H15: 24 | I15: =H15-G15+1 -> 12 | J15: 12 | K15: 6 | L15: =VLOOKUP(K15,Subject!$A$2:$B$12, 2, FALSE) -> Social Studies | M15: =VLOOKUP(K15, [1]Subject!$A$2:$E$11, 5, FALSE) -> SS | O15: SS | P15: 2 | Q15: =VLOOKUP(P15, [1]SubjectGroup!$A$2:$B$8, 2, FALSE) -> Core Academic Studies | R15: Core | S15: =B15 -> Social Studies Level 2 | T15: 0.8
A16: 15 | B16: Bible Reading Level 2 | F16: 2 | G16: 13 | H16: 24 | I16: =H16-G16+1 -> 12 | J16: 12 | K16: 7 | L16: =VLOOKUP(K16,Subject!$A$2:$B$12, 2, FALSE) -> Biblical Studies | M16: =VLOOKUP(K16, [1]Subject!$A$2:$E$11, 5, FALSE) -> BS | O16: BR | P16: 1 | Q16: =VLOOKUP(P16, [1]SubjectGroup!$A$2:$B$8, 2, FALSE) -> Christian Studies | R16: Core | S16: =B16 -> Bible Reading Level 2 | T16: 0.8
A17: 16 | B17: Maths Level 3 | F17: 3 | G17: 25 | H17: 36 | I17: =H17-G17+1 -> 12 | J17: 12 | K17: 1 | L17: =VLOOKUP(K17,Subject!$A$2:$B$12, 2, FALSE) -> Maths | M17: =VLOOKUP(K17, [1]Subject!$A$2:$E$11, 5, FALSE) -> MA | O17: MA | P17: 2 | Q17: =VLOOKUP(P17, [1]SubjectGroup!$A$2:$B$8, 2, FALSE) -> Core Academic Studies | R17: Core | S17: =B17 -> Maths Level 3 | T17: 0.8
A18: 17 | B18: English Level 3 | F18: 3 | G18: 25 | H18: 36 | I18: =H18-G18+1 -> 12 | J18: 12 | K18: 2 | L18: =VLOOKUP(K18,Subject!$A$2:$B$12, 2, FALSE) -> Language | M18: =VLOOKUP(K18, [1]Subject!$A$2:$E$11, 5, FALSE) -> LA | O18: EN | P18: 2 | Q18: =VLOOKUP(P18, [1]SubjectGroup!$A$2:$B$8, 2, FALSE) -> Core Academic Studies | R18: Core | S18: =B18 -> English Level 3 | T18: 0.8
A19: 18 | B19: Word Building Level 3 | F19: 3 | G19: 25 | H19: 36 | I19: =H19-G19+1 -> 12 | J19: 12 | K19: 3 | L19: =VLOOKUP(K19,Subject!$A$2:$B$12, 2, FALSE) -> Word Building | M19: =VLOOKUP(K19, [1]Subject!$A$2:$E$11, 5, FALSE) -> WB | O19: WB | P19: 2 | Q19: =VLOOKUP(P19, [1]SubjectGroup!$A$2:$B$8, 2, FALSE) -> Core Academic Studies | R19: Core | S19: =B19 -> Word Building Level 3 | T19: 0.9
A20: 19 | B20: Literature and Creative Writing Level 3 | F20: 3 | G20: 25 | H20: 36 | I20: =H20-G20+1 -> 12 | J20: 12 | K20: 4 | L20: =VLOOKUP(K20,Subject!$A$2:$B$12, 2, FALSE) -> Literature | M20: =VLOOKUP(K20, [1]Subject!$A$2:$E$11, 5, FALSE) -> LI | O20: LC | P20: 2 | Q20: =VLOOKUP(P20, [1]SubjectGroup!$A$2:$B$8, 2, FALSE) -> Core Academic Studies | R20: Core | S20: =B20 -> Literature and Creative Writing Level 3 | T20: 0.8
A21: 20 | B21: Science Level 3 | E21: Science 3 | F21: 3 | G21: 25 | H21: 36 | I21: =H21-G21+1 -> 12 | J21: 12 | K21: 5 | L21: =VLOOKUP(K21,Subject!$A$2:$B$12, 2, FALSE) -> Science | M21: =VLOOKUP(K21, [1]Subject!$A$2:$E$11, 5, FALSE) -> SC | O21: SC | P21: 2 | Q21: =VLOOKUP(P21, [1]SubjectGroup!$A$2:$B$8, 2, FALSE) -> Core Academic Studies | R21: Core | S21: =B21 -> Science Level 3 | T21: 0.8
A22: 21 | B22: Social Studies Level 3 | F22: 3 | G22: 25 | H22: 36 | I22: =H22-G22+1 -> 12 | J22: 12 | K22: 6 | L22: =VLOOKUP(K22,Subject!$A$2:$B$12, 2, FALSE) -> Social Studies | M22: =VLOOKUP(K22, [1]Subject!$A$2:$E$11, 5, FALSE) -> SS | O22: SS | P22: 2 | Q22: =VLOOKUP(P22, [1]SubjectGroup!$A$2:$B$8, 2, FALSE) -> Core Academic Studies | R22: Core | S22: =B22 -> Social Studies Level 3 | T22: 0.8
A23: 22 | B23: Bible Reading Level 3 | F23: 3 | G23: 25 | H23: 36 | I23: =H23-G23+1 -> 12 | J23: 12 | K23: 7 | L23: =VLOOKUP(K23,Subject!$A$2:$B$12, 2, FALSE) -> Biblical Studies | M23: =VLOOKUP(K23, [1]Subject!$A$2:$E$11, 5, FALSE) -> BS | O23: BR | P23: 1 | Q23: =VLOOKUP(P23, [1]SubjectGroup!$A$2:$B$8, 2, FALSE) -> Christian Studies | R23: Core | S23: =B23 -> Bible Reading Level 3 | T23: 0.8
A24: 23 | B24: Maths Level 4 | F24: 4 | G24: 37 | H24: 48 | I24: =H24-G24+1 -> 12 | J24: 12 | K24: 1 | L24: =VLOOKUP(K24,Subject!$A$2:$B$12, 2, FALSE) -> Maths | M24: =VLOOKUP(K24, [1]Subject!$A$2:$E$11, 5, FALSE) -> MA | O24: MA | P24: 2 | Q24: =VLOOKUP(P24, [1]SubjectGroup!$A$2:$B$8, 2, FALSE) -> Core Academic Studies | R24: Core | S24: =B24 -> Maths Level 4 | T24: 0.8
A25: 24 | B25: English Level 4 | F25: 4 | G25: 37 | H25: 48 | I25: =H25-G25+1 -> 12 | J25: 12 | K25: 2 | L25: =VLOOKUP(K25,Subject!$A$2:$B$12, 2, FALSE) -> Language | M25: =VLOOKUP(K25, [1]Subject!$A$2:$E$11, 5, FALSE) -> LA | O25: EN | P25: 2 | Q25: =VLOOKUP(P25, [1]SubjectGroup!$A$2:$B$8, 2, FALSE) -> Core Academic Studies | R25: Core | S25: =B25 -> English Level 4 | T25: 0.8
A26: 25 | B26: Word Building Level 4 | F26: 4 | G26: 37 | H26: 48 | I26: =H26-G26+1 -> 12 | J26: 12 | K26: 3 | L26: =VLOOKUP(K26,Subject!$A$2:$B$12, 2, FALSE) -> Word Building | M26: =VLOOKUP(K26, [1]Subject!$A$2:$E$11, 5, FALSE) -> WB | O26: WB | P26: 2 | Q26: =VLOOKUP(P26, [1]SubjectGroup!$A$2:$B$8, 2, FALSE) -> Core Academic Studies | R26: Core | S26: =B26 -> Word Building Level 4 | T26: 0.9
A27: 26 | B27: Literature and Creative Writing Level 4 | F27: 4 | G27: 37 | H27: 48 | I27: =H27-G27+1 -> 12 | J27: 12 | K27: 4 | L27: =VLOOKUP(K27,Subject!$A$2:$B$12, 2, FALSE) -> Literature | M27: =VLOOKUP(K27, [1]Subject!$A$2:$E$11, 5, FALSE) -> LI | O27: LC | P27: 2 | Q27: =VLOOKUP(P27, [1]SubjectGroup!$A$2:$B$8, 2, FALSE) -> Core Academic Studies | R27: Core | S27: =B27 -> Literature and Creative Writing Level 4 | T27: 0.8
A28: 27 | B28: Science Level 4 | E28: Science 4 | F28: 4 | G28: 37 | H28: 48 | I28: =H28-G28+1 -> 12 | J28: 12 | K28: 5 | L28: =VLOOKUP(K28,Subject!$A$2:$B$12, 2, FALSE) -> Science | M28: =VLOOKUP(K28, [1]Subject!$A$2:$E$11, 5, FALSE) -> SC | O28: SC | P28: 2 | Q28: =VLOOKUP(P28, [1]SubjectGroup!$A$2:$B$8, 2, FALSE) -> Core Academic Studies | R28: Core | S28: =B28 -> Science Level 4 | T28: 0.8
A29: 28 | B29: Social Studies Level 4 | F29: 4 | G29: 37 | H29: 48 | I29: =H29-G29+1 -> 12 | J29: 12 | K29: 6 | L29: =VLOOKUP(K29,Subject!$A$2:$B$12, 2, FALSE) -> Social Studies | M29: =VLOOKUP(K29, [1]Subject!$A$2:$E$11, 5, FALSE) -> SS | O29: SS | P29: 2 | Q29: =VLOOKUP(P29, [1]SubjectGroup!$A$2:$B$8, 2, FALSE) -> Core Academic Studies | R29: Core | S29: =B29 -> Social Studies Level 4 | T29: 0.8
A30: 29 | B30: Bible Reading Level 4 | F30: 4 | G30: 37 | H30: 48 | I30: =H30-G30+1 -> 12 | J30: 12 | K30: 7 | L30: =VLOOKUP(K30,Subject!$A$2:$B$12, 2, FALSE) -> Biblical Studies | M30: =VLOOKUP(K30, [1]Subject!$A$2:$E$11, 5, FALSE) -> BS | O30: BR | P30: 1 | Q30: =VLOOKUP(P30, [1]SubjectGroup!$A$2:$B$8, 2, FALSE) -> Christian Studies | R30: Core | S30: =B30 -> Bible Reading Level 4 | T30: 0.8
A31: 30 | B31: Maths Level 5 | F31: 5 | G31: 49 | H31: 60 | I31: =H31-G31+1 -> 12 | J31: 12 | K31: 1 | L31: =VLOOKUP(K31,Subject!$A$2:$B$12, 2, FALSE) -> Maths | M31: =VLOOKUP(K31, [1]Subject!$A$2:$E$11, 5, FALSE) -> MA | O31: MA | P31: 2 | Q31: =VLOOKUP(P31, [1]SubjectGroup!$A$2:$B$8, 2, FALSE) -> Core Academic Studies | R31: Core | S31: =B31 -> Maths Level 5 | T31: 0.8
